2023-04-23 18:01:56,140 - app - ERROR - Exception on /add_plant [POST]
Traceback (most recent call last):
  File "/Users/wbabich/Documents/plantApp/plant_app/app.py", line 70, in add_plant
    plant_name = request.form['name']
                 ~~~~~~~~~~~~^^^^^^^^
  File "/Users/wbabich/Documents/plantApp/plant_app/venv/lib/python3.11/site-packages/werkzeug/datastructures.py", line 375, in __getitem__
    raise exceptions.BadRequestKeyError(key)
werkzeug.exceptions.BadRequestKeyError: 400 Bad Request: The browser (or proxy) sent a request that this server could not understand.

During handling of the above exception, another exception occurred:

Traceback (most recent call last):
  File "/Users/wbabich/Documents/plantApp/plant_app/venv/lib/python3.11/site-packages/flask/app.py", line 2528, in wsgi_app
    response = self.full_dispatch_request()
               ^^^^^^^^^^^^^^^^^^^^^^^^^^^^
  File "/Users/wbabich/Documents/plantApp/plant_app/venv/lib/python3.11/site-packages/flask/app.py", line 1825, in full_dispatch_request
    rv = self.handle_user_exception(e)
         ^^^^^^^^^^^^^^^^^^^^^^^^^^^^^
  File "/Users/wbabich/Documents/plantApp/plant_app/venv/lib/python3.11/site-packages/flask/app.py", line 1823, in full_dispatch_request
    rv = self.dispatch_request()
         ^^^^^^^^^^^^^^^^^^^^^^^
  File "/Users/wbabich/Documents/plantApp/plant_app/venv/lib/python3.11/site-packages/flask/app.py", line 1799, in dispatch_request
    return self.ensure_sync(self.view_functions[rule.endpoint])(**view_args)
           ^^^^^^^^^^^^^^^^^^^^^^^^^^^^^^^^^^^^^^^^^^^^^^^^^^^^^^^^^^^^^^^^^
  File "/Users/wbabich/Documents/plantApp/plant_app/app.py", line 94, in add_plant
    flash(f"Error adding plant {plant_name}: {str(e)}", "danger")
                                ^^^^^^^^^^
UnboundLocalError: cannot access local variable 'plant_name' where it is not associated with a value
2023-04-23 18:51:59,368 - app - ERROR - Exception on / [GET]
Traceback (most recent call last):
  File "/Users/wbabich/Documents/plantApp/plant_app/venv/lib/python3.11/site-packages/flask/app.py", line 2528, in wsgi_app
    response = self.full_dispatch_request()
               ^^^^^^^^^^^^^^^^^^^^^^^^^^^^
  File "/Users/wbabich/Documents/plantApp/plant_app/venv/lib/python3.11/site-packages/flask/app.py", line 1825, in full_dispatch_request
    rv = self.handle_user_exception(e)
         ^^^^^^^^^^^^^^^^^^^^^^^^^^^^^
  File "/Users/wbabich/Documents/plantApp/plant_app/venv/lib/python3.11/site-packages/flask/app.py", line 1823, in full_dispatch_request
    rv = self.dispatch_request()
         ^^^^^^^^^^^^^^^^^^^^^^^
  File "/Users/wbabich/Documents/plantApp/plant_app/venv/lib/python3.11/site-packages/flask/app.py", line 1799, in dispatch_request
    return self.ensure_sync(self.view_functions[rule.endpoint])(**view_args)
           ^^^^^^^^^^^^^^^^^^^^^^^^^^^^^^^^^^^^^^^^^^^^^^^^^^^^^^^^^^^^^^^^^
  File "/Users/wbabich/Documents/plantApp/plant_app/app.py", line 48, in home
    return render_template('home.html', plants=plants, random_plant=random_plant)
           ^^^^^^^^^^^^^^^^^^^^^^^^^^^^^^^^^^^^^^^^^^^^^^^^^^^^^^^^^^^^^^^^^^^^^^
  File "/Users/wbabich/Documents/plantApp/plant_app/venv/lib/python3.11/site-packages/flask/templating.py", line 147, in render_template
    return _render(app, template, context)
           ^^^^^^^^^^^^^^^^^^^^^^^^^^^^^^^
  File "/Users/wbabich/Documents/plantApp/plant_app/venv/lib/python3.11/site-packages/flask/templating.py", line 130, in _render
    rv = template.render(context)
         ^^^^^^^^^^^^^^^^^^^^^^^^
  File "/Users/wbabich/Documents/plantApp/plant_app/venv/lib/python3.11/site-packages/jinja2/environment.py", line 1301, in render
    self.environment.handle_exception()
  File "/Users/wbabich/Documents/plantApp/plant_app/venv/lib/python3.11/site-packages/jinja2/environment.py", line 936, in handle_exception
    raise rewrite_traceback_stack(source=source)
  File "/Users/wbabich/Documents/plantApp/plant_app/templates/home.html", line 1, in top-level template code
    {% extends 'base.html' %}
  File "/Users/wbabich/Documents/plantApp/plant_app/templates/base.html", line 15, in top-level template code
    <a class="navbar-brand" href="{{ url_for('index') }}">plants</a>
    ^^^^^^^^^^^^^^^^^^^^^^^^^
  File "/Users/wbabich/Documents/plantApp/plant_app/venv/lib/python3.11/site-packages/flask/app.py", line 2034, in url_for
    return self.handle_url_build_error(error, endpoint, values)
           ^^^^^^^^^^^^^^^^^^^^^^^^^^^^^^^^^^^^^^^^^^^^^^^^^^^^
  File "/Users/wbabich/Documents/plantApp/plant_app/venv/lib/python3.11/site-packages/flask/app.py", line 2023, in url_for
    rv = url_adapter.build(  # type: ignore[union-attr]
         ^^^^^^^^^^^^^^^^^^^^^^^^^^^^^^^^^^^^^^^^^^^^^^
  File "/Users/wbabich/Documents/plantApp/plant_app/venv/lib/python3.11/site-packages/werkzeug/routing/map.py", line 917, in build
    raise BuildError(endpoint, values, method, self)
werkzeug.routing.exceptions.BuildError: Could not build url for endpoint 'index'. Did you mean 'delete' instead?
2023-04-23 18:51:59,563 - app - ERROR - Exception on / [GET]
Traceback (most recent call last):
  File "/Users/wbabich/Documents/plantApp/plant_app/venv/lib/python3.11/site-packages/flask/app.py", line 2528, in wsgi_app
    response = self.full_dispatch_request()
               ^^^^^^^^^^^^^^^^^^^^^^^^^^^^
  File "/Users/wbabich/Documents/plantApp/plant_app/venv/lib/python3.11/site-packages/flask/app.py", line 1825, in full_dispatch_request
    rv = self.handle_user_exception(e)
         ^^^^^^^^^^^^^^^^^^^^^^^^^^^^^
  File "/Users/wbabich/Documents/plantApp/plant_app/venv/lib/python3.11/site-packages/flask/app.py", line 1823, in full_dispatch_request
    rv = self.dispatch_request()
         ^^^^^^^^^^^^^^^^^^^^^^^
  File "/Users/wbabich/Documents/plantApp/plant_app/venv/lib/python3.11/site-packages/flask/app.py", line 1799, in dispatch_request
    return self.ensure_sync(self.view_functions[rule.endpoint])(**view_args)
           ^^^^^^^^^^^^^^^^^^^^^^^^^^^^^^^^^^^^^^^^^^^^^^^^^^^^^^^^^^^^^^^^^
  File "/Users/wbabich/Documents/plantApp/plant_app/app.py", line 48, in home
    return render_template('home.html', plants=plants, random_plant=random_plant)
           ^^^^^^^^^^^^^^^^^^^^^^^^^^^^^^^^^^^^^^^^^^^^^^^^^^^^^^^^^^^^^^^^^^^^^^
  File "/Users/wbabich/Documents/plantApp/plant_app/venv/lib/python3.11/site-packages/flask/templating.py", line 147, in render_template
    return _render(app, template, context)
           ^^^^^^^^^^^^^^^^^^^^^^^^^^^^^^^
  File "/Users/wbabich/Documents/plantApp/plant_app/venv/lib/python3.11/site-packages/flask/templating.py", line 130, in _render
    rv = template.render(context)
         ^^^^^^^^^^^^^^^^^^^^^^^^
  File "/Users/wbabich/Documents/plantApp/plant_app/venv/lib/python3.11/site-packages/jinja2/environment.py", line 1301, in render
    self.environment.handle_exception()
  File "/Users/wbabich/Documents/plantApp/plant_app/venv/lib/python3.11/site-packages/jinja2/environment.py", line 936, in handle_exception
    raise rewrite_traceback_stack(source=source)
  File "/Users/wbabich/Documents/plantApp/plant_app/templates/home.html", line 1, in top-level template code
    {% extends 'base.html' %}
  File "/Users/wbabich/Documents/plantApp/plant_app/templates/base.html", line 15, in top-level template code
    <a class="navbar-brand" href="{{ url_for('index') }}">plants</a>
    ^^^^^^^^^^^^^^^^^^^^^^^^^
  File "/Users/wbabich/Documents/plantApp/plant_app/venv/lib/python3.11/site-packages/flask/app.py", line 2034, in url_for
    return self.handle_url_build_error(error, endpoint, values)
           ^^^^^^^^^^^^^^^^^^^^^^^^^^^^^^^^^^^^^^^^^^^^^^^^^^^^
  File "/Users/wbabich/Documents/plantApp/plant_app/venv/lib/python3.11/site-packages/flask/app.py", line 2023, in url_for
    rv = url_adapter.build(  # type: ignore[union-attr]
         ^^^^^^^^^^^^^^^^^^^^^^^^^^^^^^^^^^^^^^^^^^^^^^
  File "/Users/wbabich/Documents/plantApp/plant_app/venv/lib/python3.11/site-packages/werkzeug/routing/map.py", line 917, in build
    raise BuildError(endpoint, values, method, self)
werkzeug.routing.exceptions.BuildError: Could not build url for endpoint 'index'. Did you mean 'delete' instead?
2023-04-23 18:52:33,887 - app - ERROR - Exception on / [GET]
Traceback (most recent call last):
  File "/Users/wbabich/Documents/plantApp/plant_app/venv/lib/python3.11/site-packages/flask/app.py", line 2528, in wsgi_app
    response = self.full_dispatch_request()
               ^^^^^^^^^^^^^^^^^^^^^^^^^^^^
  File "/Users/wbabich/Documents/plantApp/plant_app/venv/lib/python3.11/site-packages/flask/app.py", line 1825, in full_dispatch_request
    rv = self.handle_user_exception(e)
         ^^^^^^^^^^^^^^^^^^^^^^^^^^^^^
  File "/Users/wbabich/Documents/plantApp/plant_app/venv/lib/python3.11/site-packages/flask/app.py", line 1823, in full_dispatch_request
    rv = self.dispatch_request()
         ^^^^^^^^^^^^^^^^^^^^^^^
  File "/Users/wbabich/Documents/plantApp/plant_app/venv/lib/python3.11/site-packages/flask/app.py", line 1799, in dispatch_request
    return self.ensure_sync(self.view_functions[rule.endpoint])(**view_args)
           ^^^^^^^^^^^^^^^^^^^^^^^^^^^^^^^^^^^^^^^^^^^^^^^^^^^^^^^^^^^^^^^^^
  File "/Users/wbabich/Documents/plantApp/plant_app/app.py", line 48, in home
    return render_template('home.html', plants=plants, random_plant=random_plant)
           ^^^^^^^^^^^^^^^^^^^^^^^^^^^^^^^^^^^^^^^^^^^^^^^^^^^^^^^^^^^^^^^^^^^^^^
  File "/Users/wbabich/Documents/plantApp/plant_app/venv/lib/python3.11/site-packages/flask/templating.py", line 147, in render_template
    return _render(app, template, context)
           ^^^^^^^^^^^^^^^^^^^^^^^^^^^^^^^
  File "/Users/wbabich/Documents/plantApp/plant_app/venv/lib/python3.11/site-packages/flask/templating.py", line 130, in _render
    rv = template.render(context)
         ^^^^^^^^^^^^^^^^^^^^^^^^
  File "/Users/wbabich/Documents/plantApp/plant_app/venv/lib/python3.11/site-packages/jinja2/environment.py", line 1301, in render
    self.environment.handle_exception()
  File "/Users/wbabich/Documents/plantApp/plant_app/venv/lib/python3.11/site-packages/jinja2/environment.py", line 936, in handle_exception
    raise rewrite_traceback_stack(source=source)
  File "/Users/wbabich/Documents/plantApp/plant_app/templates/home.html", line 1, in top-level template code
    {% extends 'base.html' %}
  File "/Users/wbabich/Documents/plantApp/plant_app/templates/base.html", line 15, in top-level template code
    <a class="navbar-brand" href="{{ url_for('index') }}">plants</a>
    ^^^^^^^^^^^^^^^^^^^^^^^^^
  File "/Users/wbabich/Documents/plantApp/plant_app/venv/lib/python3.11/site-packages/flask/app.py", line 2034, in url_for
    return self.handle_url_build_error(error, endpoint, values)
           ^^^^^^^^^^^^^^^^^^^^^^^^^^^^^^^^^^^^^^^^^^^^^^^^^^^^
  File "/Users/wbabich/Documents/plantApp/plant_app/venv/lib/python3.11/site-packages/flask/app.py", line 2023, in url_for
    rv = url_adapter.build(  # type: ignore[union-attr]
         ^^^^^^^^^^^^^^^^^^^^^^^^^^^^^^^^^^^^^^^^^^^^^^
  File "/Users/wbabich/Documents/plantApp/plant_app/venv/lib/python3.11/site-packages/werkzeug/routing/map.py", line 917, in build
    raise BuildError(endpoint, values, method, self)
werkzeug.routing.exceptions.BuildError: Could not build url for endpoint 'index'. Did you mean 'delete' instead?
2023-04-23 18:52:34,554 - app - ERROR - Exception on / [GET]
Traceback (most recent call last):
  File "/Users/wbabich/Documents/plantApp/plant_app/venv/lib/python3.11/site-packages/flask/app.py", line 2528, in wsgi_app
    response = self.full_dispatch_request()
               ^^^^^^^^^^^^^^^^^^^^^^^^^^^^
  File "/Users/wbabich/Documents/plantApp/plant_app/venv/lib/python3.11/site-packages/flask/app.py", line 1825, in full_dispatch_request
    rv = self.handle_user_exception(e)
         ^^^^^^^^^^^^^^^^^^^^^^^^^^^^^
  File "/Users/wbabich/Documents/plantApp/plant_app/venv/lib/python3.11/site-packages/flask/app.py", line 1823, in full_dispatch_request
    rv = self.dispatch_request()
         ^^^^^^^^^^^^^^^^^^^^^^^
  File "/Users/wbabich/Documents/plantApp/plant_app/venv/lib/python3.11/site-packages/flask/app.py", line 1799, in dispatch_request
    return self.ensure_sync(self.view_functions[rule.endpoint])(**view_args)
           ^^^^^^^^^^^^^^^^^^^^^^^^^^^^^^^^^^^^^^^^^^^^^^^^^^^^^^^^^^^^^^^^^
  File "/Users/wbabich/Documents/plantApp/plant_app/app.py", line 48, in home
    return render_template('home.html', plants=plants, random_plant=random_plant)
           ^^^^^^^^^^^^^^^^^^^^^^^^^^^^^^^^^^^^^^^^^^^^^^^^^^^^^^^^^^^^^^^^^^^^^^
  File "/Users/wbabich/Documents/plantApp/plant_app/venv/lib/python3.11/site-packages/flask/templating.py", line 147, in render_template
    return _render(app, template, context)
           ^^^^^^^^^^^^^^^^^^^^^^^^^^^^^^^
  File "/Users/wbabich/Documents/plantApp/plant_app/venv/lib/python3.11/site-packages/flask/templating.py", line 130, in _render
    rv = template.render(context)
         ^^^^^^^^^^^^^^^^^^^^^^^^
  File "/Users/wbabich/Documents/plantApp/plant_app/venv/lib/python3.11/site-packages/jinja2/environment.py", line 1301, in render
    self.environment.handle_exception()
  File "/Users/wbabich/Documents/plantApp/plant_app/venv/lib/python3.11/site-packages/jinja2/environment.py", line 936, in handle_exception
    raise rewrite_traceback_stack(source=source)
  File "/Users/wbabich/Documents/plantApp/plant_app/templates/home.html", line 1, in top-level template code
    {% extends 'base.html' %}
  File "/Users/wbabich/Documents/plantApp/plant_app/templates/base.html", line 15, in top-level template code
    <a class="navbar-brand" href="{{ url_for('index') }}">plants</a>
    ^^^^^^^^^^^^^^^^^^^^^^^^^
  File "/Users/wbabich/Documents/plantApp/plant_app/venv/lib/python3.11/site-packages/flask/app.py", line 2034, in url_for
    return self.handle_url_build_error(error, endpoint, values)
           ^^^^^^^^^^^^^^^^^^^^^^^^^^^^^^^^^^^^^^^^^^^^^^^^^^^^
  File "/Users/wbabich/Documents/plantApp/plant_app/venv/lib/python3.11/site-packages/flask/app.py", line 2023, in url_for
    rv = url_adapter.build(  # type: ignore[union-attr]
         ^^^^^^^^^^^^^^^^^^^^^^^^^^^^^^^^^^^^^^^^^^^^^^
  File "/Users/wbabich/Documents/plantApp/plant_app/venv/lib/python3.11/site-packages/werkzeug/routing/map.py", line 917, in build
    raise BuildError(endpoint, values, method, self)
werkzeug.routing.exceptions.BuildError: Could not build url for endpoint 'index'. Did you mean 'delete' instead?
2023-04-23 19:36:14,478 - app - ERROR - Exception on /add_plant [GET]
Traceback (most recent call last):
  File "/Users/wbabich/Documents/plantApp/plant_app/venv/lib/python3.11/site-packages/flask/app.py", line 2528, in wsgi_app
    response = self.full_dispatch_request()
               ^^^^^^^^^^^^^^^^^^^^^^^^^^^^
  File "/Users/wbabich/Documents/plantApp/plant_app/venv/lib/python3.11/site-packages/flask/app.py", line 1825, in full_dispatch_request
    rv = self.handle_user_exception(e)
         ^^^^^^^^^^^^^^^^^^^^^^^^^^^^^
  File "/Users/wbabich/Documents/plantApp/plant_app/venv/lib/python3.11/site-packages/flask/app.py", line 1823, in full_dispatch_request
    rv = self.dispatch_request()
         ^^^^^^^^^^^^^^^^^^^^^^^
  File "/Users/wbabich/Documents/plantApp/plant_app/venv/lib/python3.11/site-packages/flask/app.py", line 1799, in dispatch_request
    return self.ensure_sync(self.view_functions[rule.endpoint])(**view_args)
           ^^^^^^^^^^^^^^^^^^^^^^^^^^^^^^^^^^^^^^^^^^^^^^^^^^^^^^^^^^^^^^^^^
  File "/Users/wbabich/Documents/plantApp/plant_app/app.py", line 108, in add_plant
    return render_template('add_plant.html')
           ^^^^^^^^^^^^^^^^^^^^^^^^^^^^^^^^^
  File "/Users/wbabich/Documents/plantApp/plant_app/venv/lib/python3.11/site-packages/flask/templating.py", line 147, in render_template
    return _render(app, template, context)
           ^^^^^^^^^^^^^^^^^^^^^^^^^^^^^^^
  File "/Users/wbabich/Documents/plantApp/plant_app/venv/lib/python3.11/site-packages/flask/templating.py", line 130, in _render
    rv = template.render(context)
         ^^^^^^^^^^^^^^^^^^^^^^^^
  File "/Users/wbabich/Documents/plantApp/plant_app/venv/lib/python3.11/site-packages/jinja2/environment.py", line 1301, in render
    self.environment.handle_exception()
  File "/Users/wbabich/Documents/plantApp/plant_app/venv/lib/python3.11/site-packages/jinja2/environment.py", line 936, in handle_exception
    raise rewrite_traceback_stack(source=source)
  File "/Users/wbabich/Documents/plantApp/plant_app/templates/add_plant.html", line 1, in top-level template code
    {% extends 'base.html' %}
  File "/Users/wbabich/Documents/plantApp/plant_app/templates/base.html", line 45, in top-level template code
    {% block content %}
  File "/Users/wbabich/Documents/plantApp/plant_app/templates/add_plant.html", line 47, in block 'content'
    <a href="{{ url_for('modify_plant', id=plant.id) }}" class="btn btn-primary mr-3">Modify</a>
    ^^^^^^^^^^^^^^^^^^^^^^^^^
  File "/Users/wbabich/Documents/plantApp/plant_app/venv/lib/python3.11/site-packages/jinja2/environment.py", line 485, in getattr
    return getattr(obj, attribute)
           ^^^^^^^^^^^^^^^^^^^^^^^
jinja2.exceptions.UndefinedError: 'plant' is undefined
2023-04-23 19:39:36,202 - app - ERROR - Exception on /add_plant [GET]
Traceback (most recent call last):
  File "/Users/wbabich/Documents/plantApp/plant_app/venv/lib/python3.11/site-packages/flask/app.py", line 2528, in wsgi_app
    response = self.full_dispatch_request()
               ^^^^^^^^^^^^^^^^^^^^^^^^^^^^
  File "/Users/wbabich/Documents/plantApp/plant_app/venv/lib/python3.11/site-packages/flask/app.py", line 1825, in full_dispatch_request
    rv = self.handle_user_exception(e)
         ^^^^^^^^^^^^^^^^^^^^^^^^^^^^^
  File "/Users/wbabich/Documents/plantApp/plant_app/venv/lib/python3.11/site-packages/flask/app.py", line 1823, in full_dispatch_request
    rv = self.dispatch_request()
         ^^^^^^^^^^^^^^^^^^^^^^^
  File "/Users/wbabich/Documents/plantApp/plant_app/venv/lib/python3.11/site-packages/flask/app.py", line 1799, in dispatch_request
    return self.ensure_sync(self.view_functions[rule.endpoint])(**view_args)
           ^^^^^^^^^^^^^^^^^^^^^^^^^^^^^^^^^^^^^^^^^^^^^^^^^^^^^^^^^^^^^^^^^
  File "/Users/wbabich/Documents/plantApp/plant_app/app.py", line 111, in add_plant
    return render_template('add_plant.html', plant_info=plant_info)
           ^^^^^^^^^^^^^^^^^^^^^^^^^^^^^^^^^^^^^^^^^^^^^^^^^^^^^^^^
  File "/Users/wbabich/Documents/plantApp/plant_app/venv/lib/python3.11/site-packages/flask/templating.py", line 147, in render_template
    return _render(app, template, context)
           ^^^^^^^^^^^^^^^^^^^^^^^^^^^^^^^
  File "/Users/wbabich/Documents/plantApp/plant_app/venv/lib/python3.11/site-packages/flask/templating.py", line 130, in _render
    rv = template.render(context)
         ^^^^^^^^^^^^^^^^^^^^^^^^
  File "/Users/wbabich/Documents/plantApp/plant_app/venv/lib/python3.11/site-packages/jinja2/environment.py", line 1301, in render
    self.environment.handle_exception()
  File "/Users/wbabich/Documents/plantApp/plant_app/venv/lib/python3.11/site-packages/jinja2/environment.py", line 936, in handle_exception
    raise rewrite_traceback_stack(source=source)
  File "/Users/wbabich/Documents/plantApp/plant_app/templates/add_plant.html", line 1, in top-level template code
    {% extends 'base.html' %}
  File "/Users/wbabich/Documents/plantApp/plant_app/templates/base.html", line 45, in top-level template code
    {% block content %}
  File "/Users/wbabich/Documents/plantApp/plant_app/templates/add_plant.html", line 47, in block 'content'
    <a href="{{ url_for('modify_plant', id=plant.id) }}" class="btn btn-primary mr-3">Modify</a>
    ^^^^^^^^^^^^^^^^^^^^^^^^^
  File "/Users/wbabich/Documents/plantApp/plant_app/venv/lib/python3.11/site-packages/jinja2/environment.py", line 485, in getattr
    return getattr(obj, attribute)
           ^^^^^^^^^^^^^^^^^^^^^^^
jinja2.exceptions.UndefinedError: 'plant' is undefined
2023-04-23 19:41:44,667 - app - ERROR - Exception on /add_plant [GET]
Traceback (most recent call last):
  File "/Users/wbabich/Documents/plantApp/plant_app/venv/lib/python3.11/site-packages/flask/app.py", line 2528, in wsgi_app
    response = self.full_dispatch_request()
               ^^^^^^^^^^^^^^^^^^^^^^^^^^^^
  File "/Users/wbabich/Documents/plantApp/plant_app/venv/lib/python3.11/site-packages/flask/app.py", line 1825, in full_dispatch_request
    rv = self.handle_user_exception(e)
         ^^^^^^^^^^^^^^^^^^^^^^^^^^^^^
  File "/Users/wbabich/Documents/plantApp/plant_app/venv/lib/python3.11/site-packages/flask/app.py", line 1823, in full_dispatch_request
    rv = self.dispatch_request()
         ^^^^^^^^^^^^^^^^^^^^^^^
  File "/Users/wbabich/Documents/plantApp/plant_app/venv/lib/python3.11/site-packages/flask/app.py", line 1799, in dispatch_request
    return self.ensure_sync(self.view_functions[rule.endpoint])(**view_args)
           ^^^^^^^^^^^^^^^^^^^^^^^^^^^^^^^^^^^^^^^^^^^^^^^^^^^^^^^^^^^^^^^^^
  File "/Users/wbabich/Documents/plantApp/plant_app/app.py", line 108, in add_plant
    return render_template('add_plant.html')
           ^^^^^^^^^^^^^^^^^^^^^^^^^^^^^^^^^
  File "/Users/wbabich/Documents/plantApp/plant_app/venv/lib/python3.11/site-packages/flask/templating.py", line 147, in render_template
    return _render(app, template, context)
           ^^^^^^^^^^^^^^^^^^^^^^^^^^^^^^^
  File "/Users/wbabich/Documents/plantApp/plant_app/venv/lib/python3.11/site-packages/flask/templating.py", line 130, in _render
    rv = template.render(context)
         ^^^^^^^^^^^^^^^^^^^^^^^^
  File "/Users/wbabich/Documents/plantApp/plant_app/venv/lib/python3.11/site-packages/jinja2/environment.py", line 1301, in render
    self.environment.handle_exception()
  File "/Users/wbabich/Documents/plantApp/plant_app/venv/lib/python3.11/site-packages/jinja2/environment.py", line 936, in handle_exception
    raise rewrite_traceback_stack(source=source)
  File "/Users/wbabich/Documents/plantApp/plant_app/templates/add_plant.html", line 1, in top-level template code
    {% extends 'base.html' %}
  File "/Users/wbabich/Documents/plantApp/plant_app/templates/base.html", line 45, in top-level template code
    {% block content %}
  File "/Users/wbabich/Documents/plantApp/plant_app/templates/add_plant.html", line 47, in block 'content'
    <a href="{{ url_for('modify_plant', id=plant.id) }}" class="btn btn-primary mr-3">Modify</a>
    ^^^^^^^^^^^^^^^^^^^^^^^^^
  File "/Users/wbabich/Documents/plantApp/plant_app/venv/lib/python3.11/site-packages/jinja2/environment.py", line 485, in getattr
    return getattr(obj, attribute)
           ^^^^^^^^^^^^^^^^^^^^^^^
jinja2.exceptions.UndefinedError: 'plant' is undefined
2023-04-23 19:43:11,715 - app - ERROR - Exception on /add_plant [GET]
Traceback (most recent call last):
  File "/Users/wbabich/Documents/plantApp/plant_app/venv/lib/python3.11/site-packages/flask/app.py", line 2528, in wsgi_app
    response = self.full_dispatch_request()
               ^^^^^^^^^^^^^^^^^^^^^^^^^^^^
  File "/Users/wbabich/Documents/plantApp/plant_app/venv/lib/python3.11/site-packages/flask/app.py", line 1825, in full_dispatch_request
    rv = self.handle_user_exception(e)
         ^^^^^^^^^^^^^^^^^^^^^^^^^^^^^
  File "/Users/wbabich/Documents/plantApp/plant_app/venv/lib/python3.11/site-packages/flask/app.py", line 1823, in full_dispatch_request
    rv = self.dispatch_request()
         ^^^^^^^^^^^^^^^^^^^^^^^
  File "/Users/wbabich/Documents/plantApp/plant_app/venv/lib/python3.11/site-packages/flask/app.py", line 1799, in dispatch_request
    return self.ensure_sync(self.view_functions[rule.endpoint])(**view_args)
           ^^^^^^^^^^^^^^^^^^^^^^^^^^^^^^^^^^^^^^^^^^^^^^^^^^^^^^^^^^^^^^^^^
  File "/Users/wbabich/Documents/plantApp/plant_app/app.py", line 72, in add_plant
    plant = Plant()
            ^^^^^^^
TypeError: __init__() missing 2 required positional arguments: 'common_name' and 'scientific_name'
2023-04-23 19:44:29,588 - app - ERROR - Exception on /add_plant [GET]
Traceback (most recent call last):
  File "/Users/wbabich/Documents/plantApp/plant_app/venv/lib/python3.11/site-packages/flask/app.py", line 2528, in wsgi_app
    response = self.full_dispatch_request()
               ^^^^^^^^^^^^^^^^^^^^^^^^^^^^
  File "/Users/wbabich/Documents/plantApp/plant_app/venv/lib/python3.11/site-packages/flask/app.py", line 1825, in full_dispatch_request
    rv = self.handle_user_exception(e)
         ^^^^^^^^^^^^^^^^^^^^^^^^^^^^^
  File "/Users/wbabich/Documents/plantApp/plant_app/venv/lib/python3.11/site-packages/flask/app.py", line 1823, in full_dispatch_request
    rv = self.dispatch_request()
         ^^^^^^^^^^^^^^^^^^^^^^^
  File "/Users/wbabich/Documents/plantApp/plant_app/venv/lib/python3.11/site-packages/flask/app.py", line 1799, in dispatch_request
    return self.ensure_sync(self.view_functions[rule.endpoint])(**view_args)
           ^^^^^^^^^^^^^^^^^^^^^^^^^^^^^^^^^^^^^^^^^^^^^^^^^^^^^^^^^^^^^^^^^
  File "/Users/wbabich/Documents/plantApp/plant_app/app.py", line 114, in add_plant
    return render_template('add_plant.html', plant=plant)
           ^^^^^^^^^^^^^^^^^^^^^^^^^^^^^^^^^^^^^^^^^^^^^^
  File "/Users/wbabich/Documents/plantApp/plant_app/venv/lib/python3.11/site-packages/flask/templating.py", line 147, in render_template
    return _render(app, template, context)
           ^^^^^^^^^^^^^^^^^^^^^^^^^^^^^^^
  File "/Users/wbabich/Documents/plantApp/plant_app/venv/lib/python3.11/site-packages/flask/templating.py", line 130, in _render
    rv = template.render(context)
         ^^^^^^^^^^^^^^^^^^^^^^^^
  File "/Users/wbabich/Documents/plantApp/plant_app/venv/lib/python3.11/site-packages/jinja2/environment.py", line 1301, in render
    self.environment.handle_exception()
  File "/Users/wbabich/Documents/plantApp/plant_app/venv/lib/python3.11/site-packages/jinja2/environment.py", line 936, in handle_exception
    raise rewrite_traceback_stack(source=source)
  File "/Users/wbabich/Documents/plantApp/plant_app/templates/add_plant.html", line 1, in top-level template code
    {% extends 'base.html' %}
  File "/Users/wbabich/Documents/plantApp/plant_app/templates/base.html", line 45, in top-level template code
    {% block content %}
  File "/Users/wbabich/Documents/plantApp/plant_app/templates/add_plant.html", line 47, in block 'content'
    <a href="{{ url_for('modify_plant', id=plant.id) }}" class="btn btn-primary mr-3">Modify</a>
    ^^^^^^^^^^^^^^^^^^^^^^^^^
  File "/Users/wbabich/Documents/plantApp/plant_app/venv/lib/python3.11/site-packages/flask/app.py", line 2034, in url_for
    return self.handle_url_build_error(error, endpoint, values)
           ^^^^^^^^^^^^^^^^^^^^^^^^^^^^^^^^^^^^^^^^^^^^^^^^^^^^
  File "/Users/wbabich/Documents/plantApp/plant_app/venv/lib/python3.11/site-packages/flask/app.py", line 2023, in url_for
    rv = url_adapter.build(  # type: ignore[union-attr]
         ^^^^^^^^^^^^^^^^^^^^^^^^^^^^^^^^^^^^^^^^^^^^^^
  File "/Users/wbabich/Documents/plantApp/plant_app/venv/lib/python3.11/site-packages/werkzeug/routing/map.py", line 917, in build
    raise BuildError(endpoint, values, method, self)
werkzeug.routing.exceptions.BuildError: Could not build url for endpoint 'modify_plant'. Did you forget to specify values ['id']?
2023-04-23 19:49:11,023 - app - ERROR - Exception on /add_plant [GET]
Traceback (most recent call last):
  File "/Users/wbabich/Documents/plantApp/plant_app/venv/lib/python3.11/site-packages/flask/app.py", line 2528, in wsgi_app
    response = self.full_dispatch_request()
               ^^^^^^^^^^^^^^^^^^^^^^^^^^^^
  File "/Users/wbabich/Documents/plantApp/plant_app/venv/lib/python3.11/site-packages/flask/app.py", line 1825, in full_dispatch_request
    rv = self.handle_user_exception(e)
         ^^^^^^^^^^^^^^^^^^^^^^^^^^^^^
  File "/Users/wbabich/Documents/plantApp/plant_app/venv/lib/python3.11/site-packages/flask/app.py", line 1823, in full_dispatch_request
    rv = self.dispatch_request()
         ^^^^^^^^^^^^^^^^^^^^^^^
  File "/Users/wbabich/Documents/plantApp/plant_app/venv/lib/python3.11/site-packages/flask/app.py", line 1799, in dispatch_request
    return self.ensure_sync(self.view_functions[rule.endpoint])(**view_args)
           ^^^^^^^^^^^^^^^^^^^^^^^^^^^^^^^^^^^^^^^^^^^^^^^^^^^^^^^^^^^^^^^^^
  File "/Users/wbabich/Documents/plantApp/plant_app/app.py", line 114, in add_plant
    return render_template('add_plant.html', plant=plant)
           ^^^^^^^^^^^^^^^^^^^^^^^^^^^^^^^^^^^^^^^^^^^^^^
  File "/Users/wbabich/Documents/plantApp/plant_app/venv/lib/python3.11/site-packages/flask/templating.py", line 147, in render_template
    return _render(app, template, context)
           ^^^^^^^^^^^^^^^^^^^^^^^^^^^^^^^
  File "/Users/wbabich/Documents/plantApp/plant_app/venv/lib/python3.11/site-packages/flask/templating.py", line 130, in _render
    rv = template.render(context)
         ^^^^^^^^^^^^^^^^^^^^^^^^
  File "/Users/wbabich/Documents/plantApp/plant_app/venv/lib/python3.11/site-packages/jinja2/environment.py", line 1301, in render
    self.environment.handle_exception()
  File "/Users/wbabich/Documents/plantApp/plant_app/venv/lib/python3.11/site-packages/jinja2/environment.py", line 936, in handle_exception
    raise rewrite_traceback_stack(source=source)
  File "/Users/wbabich/Documents/plantApp/plant_app/templates/add_plant.html", line 1, in top-level template code
    {% extends 'base.html' %}
  File "/Users/wbabich/Documents/plantApp/plant_app/templates/base.html", line 45, in top-level template code
    {% block content %}
  File "/Users/wbabich/Documents/plantApp/plant_app/templates/add_plant.html", line 60, in block 'content'
    <a href="{{ url_for('modify_plant', id=plant.id) }}" class="btn btn-primary mr-3">Modify</a>
    ^^^^^^^^^^^^^^^^^^^^^^^^^
  File "/Users/wbabich/Documents/plantApp/plant_app/venv/lib/python3.11/site-packages/flask/app.py", line 2034, in url_for
    return self.handle_url_build_error(error, endpoint, values)
           ^^^^^^^^^^^^^^^^^^^^^^^^^^^^^^^^^^^^^^^^^^^^^^^^^^^^
  File "/Users/wbabich/Documents/plantApp/plant_app/venv/lib/python3.11/site-packages/flask/app.py", line 2023, in url_for
    rv = url_adapter.build(  # type: ignore[union-attr]
         ^^^^^^^^^^^^^^^^^^^^^^^^^^^^^^^^^^^^^^^^^^^^^^
  File "/Users/wbabich/Documents/plantApp/plant_app/venv/lib/python3.11/site-packages/werkzeug/routing/map.py", line 917, in build
    raise BuildError(endpoint, values, method, self)
werkzeug.routing.exceptions.BuildError: Could not build url for endpoint 'modify_plant'. Did you forget to specify values ['id']?
2023-04-23 19:54:34,574 - app - ERROR - Exception on /add_plant [GET]
Traceback (most recent call last):
  File "/Users/wbabich/Documents/plantApp/plant_app/venv/lib/python3.11/site-packages/flask/app.py", line 2528, in wsgi_app
    response = self.full_dispatch_request()
               ^^^^^^^^^^^^^^^^^^^^^^^^^^^^
  File "/Users/wbabich/Documents/plantApp/plant_app/venv/lib/python3.11/site-packages/flask/app.py", line 1825, in full_dispatch_request
    rv = self.handle_user_exception(e)
         ^^^^^^^^^^^^^^^^^^^^^^^^^^^^^
  File "/Users/wbabich/Documents/plantApp/plant_app/venv/lib/python3.11/site-packages/flask/app.py", line 1823, in full_dispatch_request
    rv = self.dispatch_request()
         ^^^^^^^^^^^^^^^^^^^^^^^
  File "/Users/wbabich/Documents/plantApp/plant_app/venv/lib/python3.11/site-packages/flask/app.py", line 1799, in dispatch_request
    return self.ensure_sync(self.view_functions[rule.endpoint])(**view_args)
           ^^^^^^^^^^^^^^^^^^^^^^^^^^^^^^^^^^^^^^^^^^^^^^^^^^^^^^^^^^^^^^^^^
  File "/Users/wbabich/Documents/plantApp/plant_app/app.py", line 114, in add_plant
    return render_template('add_plant.html', plant=plant)
           ^^^^^^^^^^^^^^^^^^^^^^^^^^^^^^^^^^^^^^^^^^^^^^
  File "/Users/wbabich/Documents/plantApp/plant_app/venv/lib/python3.11/site-packages/flask/templating.py", line 147, in render_template
    return _render(app, template, context)
           ^^^^^^^^^^^^^^^^^^^^^^^^^^^^^^^
  File "/Users/wbabich/Documents/plantApp/plant_app/venv/lib/python3.11/site-packages/flask/templating.py", line 130, in _render
    rv = template.render(context)
         ^^^^^^^^^^^^^^^^^^^^^^^^
  File "/Users/wbabich/Documents/plantApp/plant_app/venv/lib/python3.11/site-packages/jinja2/environment.py", line 1301, in render
    self.environment.handle_exception()
  File "/Users/wbabich/Documents/plantApp/plant_app/venv/lib/python3.11/site-packages/jinja2/environment.py", line 936, in handle_exception
    raise rewrite_traceback_stack(source=source)
  File "/Users/wbabich/Documents/plantApp/plant_app/templates/add_plant.html", line 1, in top-level template code
    {% extends 'base.html' %}
  File "/Users/wbabich/Documents/plantApp/plant_app/templates/base.html", line 45, in top-level template code
    {% block content %}
  File "/Users/wbabich/Documents/plantApp/plant_app/templates/add_plant.html", line 60, in block 'content'
    <a href="{{ url_for('modify_plant', id=plant.id) }}" class="btn btn-primary mr-3">Modify</a>
    ^^^^^^^^^^^^^^^^^^^^^^^^^
  File "/Users/wbabich/Documents/plantApp/plant_app/venv/lib/python3.11/site-packages/flask/app.py", line 2034, in url_for
    return self.handle_url_build_error(error, endpoint, values)
           ^^^^^^^^^^^^^^^^^^^^^^^^^^^^^^^^^^^^^^^^^^^^^^^^^^^^
  File "/Users/wbabich/Documents/plantApp/plant_app/venv/lib/python3.11/site-packages/flask/app.py", line 2023, in url_for
    rv = url_adapter.build(  # type: ignore[union-attr]
         ^^^^^^^^^^^^^^^^^^^^^^^^^^^^^^^^^^^^^^^^^^^^^^
  File "/Users/wbabich/Documents/plantApp/plant_app/venv/lib/python3.11/site-packages/werkzeug/routing/map.py", line 917, in build
    raise BuildError(endpoint, values, method, self)
werkzeug.routing.exceptions.BuildError: Could not build url for endpoint 'modify_plant'. Did you forget to specify values ['id']?
2023-04-23 19:55:56,459 - app - ERROR - Exception on /add_plant [GET]
Traceback (most recent call last):
  File "/Users/wbabich/Documents/plantApp/plant_app/venv/lib/python3.11/site-packages/flask/app.py", line 2528, in wsgi_app
    response = self.full_dispatch_request()
               ^^^^^^^^^^^^^^^^^^^^^^^^^^^^
  File "/Users/wbabich/Documents/plantApp/plant_app/venv/lib/python3.11/site-packages/flask/app.py", line 1825, in full_dispatch_request
    rv = self.handle_user_exception(e)
         ^^^^^^^^^^^^^^^^^^^^^^^^^^^^^
  File "/Users/wbabich/Documents/plantApp/plant_app/venv/lib/python3.11/site-packages/flask/app.py", line 1823, in full_dispatch_request
    rv = self.dispatch_request()
         ^^^^^^^^^^^^^^^^^^^^^^^
  File "/Users/wbabich/Documents/plantApp/plant_app/venv/lib/python3.11/site-packages/flask/app.py", line 1799, in dispatch_request
    return self.ensure_sync(self.view_functions[rule.endpoint])(**view_args)
           ^^^^^^^^^^^^^^^^^^^^^^^^^^^^^^^^^^^^^^^^^^^^^^^^^^^^^^^^^^^^^^^^^
  File "/Users/wbabich/Documents/plantApp/plant_app/app.py", line 114, in add_plant
    return render_template('add_plant.html', plant=plant)
           ^^^^^^^^^^^^^^^^^^^^^^^^^^^^^^^^^^^^^^^^^^^^^^
  File "/Users/wbabich/Documents/plantApp/plant_app/venv/lib/python3.11/site-packages/flask/templating.py", line 147, in render_template
    return _render(app, template, context)
           ^^^^^^^^^^^^^^^^^^^^^^^^^^^^^^^
  File "/Users/wbabich/Documents/plantApp/plant_app/venv/lib/python3.11/site-packages/flask/templating.py", line 130, in _render
    rv = template.render(context)
         ^^^^^^^^^^^^^^^^^^^^^^^^
  File "/Users/wbabich/Documents/plantApp/plant_app/venv/lib/python3.11/site-packages/jinja2/environment.py", line 1301, in render
    self.environment.handle_exception()
  File "/Users/wbabich/Documents/plantApp/plant_app/venv/lib/python3.11/site-packages/jinja2/environment.py", line 936, in handle_exception
    raise rewrite_traceback_stack(source=source)
  File "/Users/wbabich/Documents/plantApp/plant_app/templates/add_plant.html", line 1, in top-level template code
    {% extends 'base.html' %}
  File "/Users/wbabich/Documents/plantApp/plant_app/templates/base.html", line 45, in top-level template code
    {% block content %}
  File "/Users/wbabich/Documents/plantApp/plant_app/templates/add_plant.html", line 60, in block 'content'
    <a href="{{ url_for('modify_plant', id=plant.id) }}" class="btn btn-primary mr-3">Modify</a>
    ^^^^^^^^^^^^^^^^^^^^^^^^^
  File "/Users/wbabich/Documents/plantApp/plant_app/venv/lib/python3.11/site-packages/flask/app.py", line 2034, in url_for
    return self.handle_url_build_error(error, endpoint, values)
           ^^^^^^^^^^^^^^^^^^^^^^^^^^^^^^^^^^^^^^^^^^^^^^^^^^^^
  File "/Users/wbabich/Documents/plantApp/plant_app/venv/lib/python3.11/site-packages/flask/app.py", line 2023, in url_for
    rv = url_adapter.build(  # type: ignore[union-attr]
         ^^^^^^^^^^^^^^^^^^^^^^^^^^^^^^^^^^^^^^^^^^^^^^
  File "/Users/wbabich/Documents/plantApp/plant_app/venv/lib/python3.11/site-packages/werkzeug/routing/map.py", line 917, in build
    raise BuildError(endpoint, values, method, self)
werkzeug.routing.exceptions.BuildError: Could not build url for endpoint 'modify_plant'. Did you forget to specify values ['id']?
2023-04-23 19:58:22,640 - app - ERROR - Exception on /add_plant [GET]
Traceback (most recent call last):
  File "/Users/wbabich/Documents/plantApp/plant_app/venv/lib/python3.11/site-packages/flask/app.py", line 2528, in wsgi_app
    response = self.full_dispatch_request()
               ^^^^^^^^^^^^^^^^^^^^^^^^^^^^
  File "/Users/wbabich/Documents/plantApp/plant_app/venv/lib/python3.11/site-packages/flask/app.py", line 1825, in full_dispatch_request
    rv = self.handle_user_exception(e)
         ^^^^^^^^^^^^^^^^^^^^^^^^^^^^^
  File "/Users/wbabich/Documents/plantApp/plant_app/venv/lib/python3.11/site-packages/flask/app.py", line 1823, in full_dispatch_request
    rv = self.dispatch_request()
         ^^^^^^^^^^^^^^^^^^^^^^^
  File "/Users/wbabich/Documents/plantApp/plant_app/venv/lib/python3.11/site-packages/flask/app.py", line 1799, in dispatch_request
    return self.ensure_sync(self.view_functions[rule.endpoint])(**view_args)
           ^^^^^^^^^^^^^^^^^^^^^^^^^^^^^^^^^^^^^^^^^^^^^^^^^^^^^^^^^^^^^^^^^
  File "/Users/wbabich/Documents/plantApp/plant_app/app.py", line 114, in add_plant
    return render_template('add_plant.html', plant=plant)
           ^^^^^^^^^^^^^^^^^^^^^^^^^^^^^^^^^^^^^^^^^^^^^^
  File "/Users/wbabich/Documents/plantApp/plant_app/venv/lib/python3.11/site-packages/flask/templating.py", line 147, in render_template
    return _render(app, template, context)
           ^^^^^^^^^^^^^^^^^^^^^^^^^^^^^^^
  File "/Users/wbabich/Documents/plantApp/plant_app/venv/lib/python3.11/site-packages/flask/templating.py", line 130, in _render
    rv = template.render(context)
         ^^^^^^^^^^^^^^^^^^^^^^^^
  File "/Users/wbabich/Documents/plantApp/plant_app/venv/lib/python3.11/site-packages/jinja2/environment.py", line 1301, in render
    self.environment.handle_exception()
  File "/Users/wbabich/Documents/plantApp/plant_app/venv/lib/python3.11/site-packages/jinja2/environment.py", line 936, in handle_exception
    raise rewrite_traceback_stack(source=source)
  File "/Users/wbabich/Documents/plantApp/plant_app/templates/add_plant.html", line 1, in top-level template code
    {% extends 'base.html' %}
  File "/Users/wbabich/Documents/plantApp/plant_app/templates/base.html", line 45, in top-level template code
    {% block content %}
  File "/Users/wbabich/Documents/plantApp/plant_app/templates/add_plant.html", line 59, in block 'content'
    <a href="{{ url_for('modify_plant', id=plant.id) }}" class="btn btn-primary mr-3">Modify</a>
    ^^^^^^^^^^^^^^^^^^^^^^^^^
  File "/Users/wbabich/Documents/plantApp/plant_app/venv/lib/python3.11/site-packages/flask/app.py", line 2034, in url_for
    return self.handle_url_build_error(error, endpoint, values)
           ^^^^^^^^^^^^^^^^^^^^^^^^^^^^^^^^^^^^^^^^^^^^^^^^^^^^
  File "/Users/wbabich/Documents/plantApp/plant_app/venv/lib/python3.11/site-packages/flask/app.py", line 2023, in url_for
    rv = url_adapter.build(  # type: ignore[union-attr]
         ^^^^^^^^^^^^^^^^^^^^^^^^^^^^^^^^^^^^^^^^^^^^^^
  File "/Users/wbabich/Documents/plantApp/plant_app/venv/lib/python3.11/site-packages/werkzeug/routing/map.py", line 917, in build
    raise BuildError(endpoint, values, method, self)
werkzeug.routing.exceptions.BuildError: Could not build url for endpoint 'modify_plant'. Did you forget to specify values ['id']?
2023-04-23 20:00:52,102 - app - ERROR - Exception on /add_plant [GET]
Traceback (most recent call last):
  File "/Users/wbabich/Documents/plantApp/plant_app/venv/lib/python3.11/site-packages/flask/app.py", line 2528, in wsgi_app
    response = self.full_dispatch_request()
               ^^^^^^^^^^^^^^^^^^^^^^^^^^^^
  File "/Users/wbabich/Documents/plantApp/plant_app/venv/lib/python3.11/site-packages/flask/app.py", line 1825, in full_dispatch_request
    rv = self.handle_user_exception(e)
         ^^^^^^^^^^^^^^^^^^^^^^^^^^^^^
  File "/Users/wbabich/Documents/plantApp/plant_app/venv/lib/python3.11/site-packages/flask/app.py", line 1823, in full_dispatch_request
    rv = self.dispatch_request()
         ^^^^^^^^^^^^^^^^^^^^^^^
  File "/Users/wbabich/Documents/plantApp/plant_app/venv/lib/python3.11/site-packages/flask/app.py", line 1799, in dispatch_request
    return self.ensure_sync(self.view_functions[rule.endpoint])(**view_args)
           ^^^^^^^^^^^^^^^^^^^^^^^^^^^^^^^^^^^^^^^^^^^^^^^^^^^^^^^^^^^^^^^^^
  File "/Users/wbabich/Documents/plantApp/plant_app/app.py", line 138, in add_plant
    return render_template('add_plant.html', plant=plant)
           ^^^^^^^^^^^^^^^^^^^^^^^^^^^^^^^^^^^^^^^^^^^^^^
  File "/Users/wbabich/Documents/plantApp/plant_app/venv/lib/python3.11/site-packages/flask/templating.py", line 147, in render_template
    return _render(app, template, context)
           ^^^^^^^^^^^^^^^^^^^^^^^^^^^^^^^
  File "/Users/wbabich/Documents/plantApp/plant_app/venv/lib/python3.11/site-packages/flask/templating.py", line 130, in _render
    rv = template.render(context)
         ^^^^^^^^^^^^^^^^^^^^^^^^
  File "/Users/wbabich/Documents/plantApp/plant_app/venv/lib/python3.11/site-packages/jinja2/environment.py", line 1301, in render
    self.environment.handle_exception()
  File "/Users/wbabich/Documents/plantApp/plant_app/venv/lib/python3.11/site-packages/jinja2/environment.py", line 936, in handle_exception
    raise rewrite_traceback_stack(source=source)
  File "/Users/wbabich/Documents/plantApp/plant_app/templates/add_plant.html", line 1, in top-level template code
    {% extends 'base.html' %}
  File "/Users/wbabich/Documents/plantApp/plant_app/templates/base.html", line 45, in top-level template code
    {% block content %}
  File "/Users/wbabich/Documents/plantApp/plant_app/templates/add_plant.html", line 59, in block 'content'
    <a href="{{ url_for('modify_plant', id=plant.id) }}" class="btn btn-primary mr-3">Modify</a>
    ^^^^^^^^^^^^^^^^^^^^^^^^^
  File "/Users/wbabich/Documents/plantApp/plant_app/venv/lib/python3.11/site-packages/flask/app.py", line 2034, in url_for
    return self.handle_url_build_error(error, endpoint, values)
           ^^^^^^^^^^^^^^^^^^^^^^^^^^^^^^^^^^^^^^^^^^^^^^^^^^^^
  File "/Users/wbabich/Documents/plantApp/plant_app/venv/lib/python3.11/site-packages/flask/app.py", line 2023, in url_for
    rv = url_adapter.build(  # type: ignore[union-attr]
         ^^^^^^^^^^^^^^^^^^^^^^^^^^^^^^^^^^^^^^^^^^^^^^
  File "/Users/wbabich/Documents/plantApp/plant_app/venv/lib/python3.11/site-packages/werkzeug/routing/map.py", line 917, in build
    raise BuildError(endpoint, values, method, self)
werkzeug.routing.exceptions.BuildError: Could not build url for endpoint 'modify_plant'. Did you forget to specify values ['id']?
2023-04-23 21:52:49,346 - app - ERROR - Exception on / [GET]
Traceback (most recent call last):
  File "/Users/wbabich/Documents/plantApp/plant_app/venv/lib/python3.11/site-packages/flask/app.py", line 2528, in wsgi_app
    response = self.full_dispatch_request()
               ^^^^^^^^^^^^^^^^^^^^^^^^^^^^
  File "/Users/wbabich/Documents/plantApp/plant_app/venv/lib/python3.11/site-packages/flask/app.py", line 1825, in full_dispatch_request
    rv = self.handle_user_exception(e)
         ^^^^^^^^^^^^^^^^^^^^^^^^^^^^^
  File "/Users/wbabich/Documents/plantApp/plant_app/venv/lib/python3.11/site-packages/flask/app.py", line 1823, in full_dispatch_request
    rv = self.dispatch_request()
         ^^^^^^^^^^^^^^^^^^^^^^^
  File "/Users/wbabich/Documents/plantApp/plant_app/venv/lib/python3.11/site-packages/flask/app.py", line 1799, in dispatch_request
    return self.ensure_sync(self.view_functions[rule.endpoint])(**view_args)
           ^^^^^^^^^^^^^^^^^^^^^^^^^^^^^^^^^^^^^^^^^^^^^^^^^^^^^^^^^^^^^^^^^
  File "/Users/wbabich/Documents/plantApp/plant_app/app.py", line 48, in home
    return render_template('home.html', plants=plants, random_plant=random_plant)
           ^^^^^^^^^^^^^^^^^^^^^^^^^^^^^^^^^^^^^^^^^^^^^^^^^^^^^^^^^^^^^^^^^^^^^^
  File "/Users/wbabich/Documents/plantApp/plant_app/venv/lib/python3.11/site-packages/flask/templating.py", line 147, in render_template
    return _render(app, template, context)
           ^^^^^^^^^^^^^^^^^^^^^^^^^^^^^^^
  File "/Users/wbabich/Documents/plantApp/plant_app/venv/lib/python3.11/site-packages/flask/templating.py", line 130, in _render
    rv = template.render(context)
         ^^^^^^^^^^^^^^^^^^^^^^^^
  File "/Users/wbabich/Documents/plantApp/plant_app/venv/lib/python3.11/site-packages/jinja2/environment.py", line 1301, in render
    self.environment.handle_exception()
  File "/Users/wbabich/Documents/plantApp/plant_app/venv/lib/python3.11/site-packages/jinja2/environment.py", line 936, in handle_exception
    raise rewrite_traceback_stack(source=source)
  File "/Users/wbabich/Documents/plantApp/plant_app/templates/home.html", line 1, in top-level template code
    {% extends 'base.html' %}
  File "/Users/wbabich/Documents/plantApp/plant_app/templates/base.html", line 32, in top-level template code
    <form class="form-inline my-2 my-lg-0" action="{{ url_for('plant_search') }}">
    ^^^^^^^^^^^^^^^^^^^^^^^^^
  File "/Users/wbabich/Documents/plantApp/plant_app/venv/lib/python3.11/site-packages/flask/app.py", line 2034, in url_for
    return self.handle_url_build_error(error, endpoint, values)
           ^^^^^^^^^^^^^^^^^^^^^^^^^^^^^^^^^^^^^^^^^^^^^^^^^^^^
  File "/Users/wbabich/Documents/plantApp/plant_app/venv/lib/python3.11/site-packages/flask/app.py", line 2023, in url_for
    rv = url_adapter.build(  # type: ignore[union-attr]
         ^^^^^^^^^^^^^^^^^^^^^^^^^^^^^^^^^^^^^^^^^^^^^^
  File "/Users/wbabich/Documents/plantApp/plant_app/venv/lib/python3.11/site-packages/werkzeug/routing/map.py", line 917, in build
    raise BuildError(endpoint, values, method, self)
werkzeug.routing.exceptions.BuildError: Could not build url for endpoint 'plant_search'. Did you mean 'list_plants' instead?
2023-04-23 21:53:59,976 - app - ERROR - Exception on / [GET]
Traceback (most recent call last):
  File "/Users/wbabich/Documents/plantApp/plant_app/venv/lib/python3.11/site-packages/flask/app.py", line 2528, in wsgi_app
    response = self.full_dispatch_request()
               ^^^^^^^^^^^^^^^^^^^^^^^^^^^^
  File "/Users/wbabich/Documents/plantApp/plant_app/venv/lib/python3.11/site-packages/flask/app.py", line 1825, in full_dispatch_request
    rv = self.handle_user_exception(e)
         ^^^^^^^^^^^^^^^^^^^^^^^^^^^^^
  File "/Users/wbabich/Documents/plantApp/plant_app/venv/lib/python3.11/site-packages/flask/app.py", line 1823, in full_dispatch_request
    rv = self.dispatch_request()
         ^^^^^^^^^^^^^^^^^^^^^^^
  File "/Users/wbabich/Documents/plantApp/plant_app/venv/lib/python3.11/site-packages/flask/app.py", line 1799, in dispatch_request
    return self.ensure_sync(self.view_functions[rule.endpoint])(**view_args)
           ^^^^^^^^^^^^^^^^^^^^^^^^^^^^^^^^^^^^^^^^^^^^^^^^^^^^^^^^^^^^^^^^^
  File "/Users/wbabich/Documents/plantApp/plant_app/app.py", line 48, in home
    return render_template('home.html', plants=plants, random_plant=random_plant)
           ^^^^^^^^^^^^^^^^^^^^^^^^^^^^^^^^^^^^^^^^^^^^^^^^^^^^^^^^^^^^^^^^^^^^^^
  File "/Users/wbabich/Documents/plantApp/plant_app/venv/lib/python3.11/site-packages/flask/templating.py", line 147, in render_template
    return _render(app, template, context)
           ^^^^^^^^^^^^^^^^^^^^^^^^^^^^^^^
  File "/Users/wbabich/Documents/plantApp/plant_app/venv/lib/python3.11/site-packages/flask/templating.py", line 130, in _render
    rv = template.render(context)
         ^^^^^^^^^^^^^^^^^^^^^^^^
  File "/Users/wbabich/Documents/plantApp/plant_app/venv/lib/python3.11/site-packages/jinja2/environment.py", line 1301, in render
    self.environment.handle_exception()
  File "/Users/wbabich/Documents/plantApp/plant_app/venv/lib/python3.11/site-packages/jinja2/environment.py", line 936, in handle_exception
    raise rewrite_traceback_stack(source=source)
  File "/Users/wbabich/Documents/plantApp/plant_app/templates/home.html", line 1, in top-level template code
    {% extends 'base.html' %}
  File "/Users/wbabich/Documents/plantApp/plant_app/templates/base.html", line 32, in top-level template code
    <form class="form-inline my-2 my-lg-0" action="{{ url_for('plant_search') }}">
    ^^^^^^^^^^^^^^^^^^^^^^^^^
  File "/Users/wbabich/Documents/plantApp/plant_app/venv/lib/python3.11/site-packages/flask/app.py", line 2034, in url_for
    return self.handle_url_build_error(error, endpoint, values)
           ^^^^^^^^^^^^^^^^^^^^^^^^^^^^^^^^^^^^^^^^^^^^^^^^^^^^
  File "/Users/wbabich/Documents/plantApp/plant_app/venv/lib/python3.11/site-packages/flask/app.py", line 2023, in url_for
    rv = url_adapter.build(  # type: ignore[union-attr]
         ^^^^^^^^^^^^^^^^^^^^^^^^^^^^^^^^^^^^^^^^^^^^^^
  File "/Users/wbabich/Documents/plantApp/plant_app/venv/lib/python3.11/site-packages/werkzeug/routing/map.py", line 917, in build
    raise BuildError(endpoint, values, method, self)
werkzeug.routing.exceptions.BuildError: Could not build url for endpoint 'plant_search'. Did you mean 'list_plants' instead?
2023-04-23 21:57:05,400 - app - ERROR - Exception on / [GET]
Traceback (most recent call last):
  File "/Users/wbabich/Documents/plantApp/plant_app/venv/lib/python3.11/site-packages/flask/app.py", line 2528, in wsgi_app
    response = self.full_dispatch_request()
               ^^^^^^^^^^^^^^^^^^^^^^^^^^^^
  File "/Users/wbabich/Documents/plantApp/plant_app/venv/lib/python3.11/site-packages/flask/app.py", line 1825, in full_dispatch_request
    rv = self.handle_user_exception(e)
         ^^^^^^^^^^^^^^^^^^^^^^^^^^^^^
  File "/Users/wbabich/Documents/plantApp/plant_app/venv/lib/python3.11/site-packages/flask/app.py", line 1823, in full_dispatch_request
    rv = self.dispatch_request()
         ^^^^^^^^^^^^^^^^^^^^^^^
  File "/Users/wbabich/Documents/plantApp/plant_app/venv/lib/python3.11/site-packages/flask/app.py", line 1799, in dispatch_request
    return self.ensure_sync(self.view_functions[rule.endpoint])(**view_args)
           ^^^^^^^^^^^^^^^^^^^^^^^^^^^^^^^^^^^^^^^^^^^^^^^^^^^^^^^^^^^^^^^^^
  File "/Users/wbabich/Documents/plantApp/plant_app/app.py", line 48, in home
    return render_template('home.html', plants=plants, random_plant=random_plant)
           ^^^^^^^^^^^^^^^^^^^^^^^^^^^^^^^^^^^^^^^^^^^^^^^^^^^^^^^^^^^^^^^^^^^^^^
  File "/Users/wbabich/Documents/plantApp/plant_app/venv/lib/python3.11/site-packages/flask/templating.py", line 147, in render_template
    return _render(app, template, context)
           ^^^^^^^^^^^^^^^^^^^^^^^^^^^^^^^
  File "/Users/wbabich/Documents/plantApp/plant_app/venv/lib/python3.11/site-packages/flask/templating.py", line 130, in _render
    rv = template.render(context)
         ^^^^^^^^^^^^^^^^^^^^^^^^
  File "/Users/wbabich/Documents/plantApp/plant_app/venv/lib/python3.11/site-packages/jinja2/environment.py", line 1301, in render
    self.environment.handle_exception()
  File "/Users/wbabich/Documents/plantApp/plant_app/venv/lib/python3.11/site-packages/jinja2/environment.py", line 936, in handle_exception
    raise rewrite_traceback_stack(source=source)
  File "/Users/wbabich/Documents/plantApp/plant_app/templates/home.html", line 1, in top-level template code
    {% extends 'base.html' %}
  File "/Users/wbabich/Documents/plantApp/plant_app/templates/base.html", line 32, in top-level template code
    <form class="form-inline my-2 my-lg-0" action="{{ url_for('search_plants') }}">
    ^^^^^^^^^^^^^^^^^^^^^^^^^
  File "/Users/wbabich/Documents/plantApp/plant_app/venv/lib/python3.11/site-packages/flask/app.py", line 2034, in url_for
    return self.handle_url_build_error(error, endpoint, values)
           ^^^^^^^^^^^^^^^^^^^^^^^^^^^^^^^^^^^^^^^^^^^^^^^^^^^^
  File "/Users/wbabich/Documents/plantApp/plant_app/venv/lib/python3.11/site-packages/flask/app.py", line 2023, in url_for
    rv = url_adapter.build(  # type: ignore[union-attr]
         ^^^^^^^^^^^^^^^^^^^^^^^^^^^^^^^^^^^^^^^^^^^^^^
  File "/Users/wbabich/Documents/plantApp/plant_app/venv/lib/python3.11/site-packages/werkzeug/routing/map.py", line 917, in build
    raise BuildError(endpoint, values, method, self)
werkzeug.routing.exceptions.BuildError: Could not build url for endpoint 'search_plants'. Did you mean 'search_plant' instead?
2023-04-23 21:57:28,767 - app - ERROR - Exception on /add_plant [GET]
Traceback (most recent call last):
  File "/Users/wbabich/Documents/plantApp/plant_app/venv/lib/python3.11/site-packages/flask/app.py", line 2528, in wsgi_app
    response = self.full_dispatch_request()
               ^^^^^^^^^^^^^^^^^^^^^^^^^^^^
  File "/Users/wbabich/Documents/plantApp/plant_app/venv/lib/python3.11/site-packages/flask/app.py", line 1825, in full_dispatch_request
    rv = self.handle_user_exception(e)
         ^^^^^^^^^^^^^^^^^^^^^^^^^^^^^
  File "/Users/wbabich/Documents/plantApp/plant_app/venv/lib/python3.11/site-packages/flask/app.py", line 1823, in full_dispatch_request
    rv = self.dispatch_request()
         ^^^^^^^^^^^^^^^^^^^^^^^
  File "/Users/wbabich/Documents/plantApp/plant_app/venv/lib/python3.11/site-packages/flask/app.py", line 1799, in dispatch_request
    return self.ensure_sync(self.view_functions[rule.endpoint])(**view_args)
           ^^^^^^^^^^^^^^^^^^^^^^^^^^^^^^^^^^^^^^^^^^^^^^^^^^^^^^^^^^^^^^^^^
  File "/Users/wbabich/Documents/plantApp/plant_app/app.py", line 154, in add_plant
    return render_template('add_plant.html', plant=plant)
           ^^^^^^^^^^^^^^^^^^^^^^^^^^^^^^^^^^^^^^^^^^^^^^
  File "/Users/wbabich/Documents/plantApp/plant_app/venv/lib/python3.11/site-packages/flask/templating.py", line 147, in render_template
    return _render(app, template, context)
           ^^^^^^^^^^^^^^^^^^^^^^^^^^^^^^^
  File "/Users/wbabich/Documents/plantApp/plant_app/venv/lib/python3.11/site-packages/flask/templating.py", line 130, in _render
    rv = template.render(context)
         ^^^^^^^^^^^^^^^^^^^^^^^^
  File "/Users/wbabich/Documents/plantApp/plant_app/venv/lib/python3.11/site-packages/jinja2/environment.py", line 1301, in render
    self.environment.handle_exception()
  File "/Users/wbabich/Documents/plantApp/plant_app/venv/lib/python3.11/site-packages/jinja2/environment.py", line 936, in handle_exception
    raise rewrite_traceback_stack(source=source)
  File "/Users/wbabich/Documents/plantApp/plant_app/templates/add_plant.html", line 1, in top-level template code
    {% extends 'base.html' %}
  File "/Users/wbabich/Documents/plantApp/plant_app/templates/base.html", line 45, in top-level template code
    {% block content %}
  File "/Users/wbabich/Documents/plantApp/plant_app/templates/add_plant.html", line 47, in block 'content'
    <form id="submit-form" action="{{ url_for('add_to_database') }}" method="POST" onsubmit="return false;">
    ^^^^^^^^^^^^^^^^^^^^^^^^^
  File "/Users/wbabich/Documents/plantApp/plant_app/venv/lib/python3.11/site-packages/flask/app.py", line 2034, in url_for
    return self.handle_url_build_error(error, endpoint, values)
           ^^^^^^^^^^^^^^^^^^^^^^^^^^^^^^^^^^^^^^^^^^^^^^^^^^^^
  File "/Users/wbabich/Documents/plantApp/plant_app/venv/lib/python3.11/site-packages/flask/app.py", line 2023, in url_for
    rv = url_adapter.build(  # type: ignore[union-attr]
         ^^^^^^^^^^^^^^^^^^^^^^^^^^^^^^^^^^^^^^^^^^^^^^
  File "/Users/wbabich/Documents/plantApp/plant_app/venv/lib/python3.11/site-packages/werkzeug/routing/map.py", line 917, in build
    raise BuildError(endpoint, values, method, self)
werkzeug.routing.exceptions.BuildError: Could not build url for endpoint 'add_to_database'. Did you forget to specify values ['id']?
2023-04-23 21:59:00,706 - app - ERROR - Exception on /add_plant [GET]
Traceback (most recent call last):
  File "/Users/wbabich/Documents/plantApp/plant_app/venv/lib/python3.11/site-packages/flask/app.py", line 2528, in wsgi_app
    response = self.full_dispatch_request()
               ^^^^^^^^^^^^^^^^^^^^^^^^^^^^
  File "/Users/wbabich/Documents/plantApp/plant_app/venv/lib/python3.11/site-packages/flask/app.py", line 1825, in full_dispatch_request
    rv = self.handle_user_exception(e)
         ^^^^^^^^^^^^^^^^^^^^^^^^^^^^^
  File "/Users/wbabich/Documents/plantApp/plant_app/venv/lib/python3.11/site-packages/flask/app.py", line 1823, in full_dispatch_request
    rv = self.dispatch_request()
         ^^^^^^^^^^^^^^^^^^^^^^^
  File "/Users/wbabich/Documents/plantApp/plant_app/venv/lib/python3.11/site-packages/flask/app.py", line 1799, in dispatch_request
    return self.ensure_sync(self.view_functions[rule.endpoint])(**view_args)
           ^^^^^^^^^^^^^^^^^^^^^^^^^^^^^^^^^^^^^^^^^^^^^^^^^^^^^^^^^^^^^^^^^
  File "/Users/wbabich/Documents/plantApp/plant_app/app.py", line 154, in add_plant
    return render_template('add_plant.html', plant=plant)
           ^^^^^^^^^^^^^^^^^^^^^^^^^^^^^^^^^^^^^^^^^^^^^^
  File "/Users/wbabich/Documents/plantApp/plant_app/venv/lib/python3.11/site-packages/flask/templating.py", line 147, in render_template
    return _render(app, template, context)
           ^^^^^^^^^^^^^^^^^^^^^^^^^^^^^^^
  File "/Users/wbabich/Documents/plantApp/plant_app/venv/lib/python3.11/site-packages/flask/templating.py", line 130, in _render
    rv = template.render(context)
         ^^^^^^^^^^^^^^^^^^^^^^^^
  File "/Users/wbabich/Documents/plantApp/plant_app/venv/lib/python3.11/site-packages/jinja2/environment.py", line 1301, in render
    self.environment.handle_exception()
  File "/Users/wbabich/Documents/plantApp/plant_app/venv/lib/python3.11/site-packages/jinja2/environment.py", line 936, in handle_exception
    raise rewrite_traceback_stack(source=source)
  File "/Users/wbabich/Documents/plantApp/plant_app/templates/add_plant.html", line 1, in top-level template code
    {% extends 'base.html' %}
  File "/Users/wbabich/Documents/plantApp/plant_app/templates/base.html", line 45, in top-level template code
    {% block content %}
  File "/Users/wbabich/Documents/plantApp/plant_app/templates/add_plant.html", line 48, in block 'content'
    <form id="submit-form" action="{{ url_for('add_to_database') }}" method="POST" onsubmit="return false;">
    ^^^^^^^^^^^^^^^^^^^^^^^^^
  File "/Users/wbabich/Documents/plantApp/plant_app/venv/lib/python3.11/site-packages/flask/app.py", line 2034, in url_for
    return self.handle_url_build_error(error, endpoint, values)
           ^^^^^^^^^^^^^^^^^^^^^^^^^^^^^^^^^^^^^^^^^^^^^^^^^^^^
  File "/Users/wbabich/Documents/plantApp/plant_app/venv/lib/python3.11/site-packages/flask/app.py", line 2023, in url_for
    rv = url_adapter.build(  # type: ignore[union-attr]
         ^^^^^^^^^^^^^^^^^^^^^^^^^^^^^^^^^^^^^^^^^^^^^^
  File "/Users/wbabich/Documents/plantApp/plant_app/venv/lib/python3.11/site-packages/werkzeug/routing/map.py", line 917, in build
    raise BuildError(endpoint, values, method, self)
werkzeug.routing.exceptions.BuildError: Could not build url for endpoint 'add_to_database'. Did you forget to specify values ['id']?
2023-04-23 22:04:56,230 - app - ERROR - Exception on /add_plant [GET]
Traceback (most recent call last):
  File "/Users/wbabich/Documents/plantApp/plant_app/venv/lib/python3.11/site-packages/flask/app.py", line 2528, in wsgi_app
    response = self.full_dispatch_request()
               ^^^^^^^^^^^^^^^^^^^^^^^^^^^^
  File "/Users/wbabich/Documents/plantApp/plant_app/venv/lib/python3.11/site-packages/flask/app.py", line 1825, in full_dispatch_request
    rv = self.handle_user_exception(e)
         ^^^^^^^^^^^^^^^^^^^^^^^^^^^^^
  File "/Users/wbabich/Documents/plantApp/plant_app/venv/lib/python3.11/site-packages/flask/app.py", line 1823, in full_dispatch_request
    rv = self.dispatch_request()
         ^^^^^^^^^^^^^^^^^^^^^^^
  File "/Users/wbabich/Documents/plantApp/plant_app/venv/lib/python3.11/site-packages/flask/app.py", line 1799, in dispatch_request
    return self.ensure_sync(self.view_functions[rule.endpoint])(**view_args)
           ^^^^^^^^^^^^^^^^^^^^^^^^^^^^^^^^^^^^^^^^^^^^^^^^^^^^^^^^^^^^^^^^^
  File "/Users/wbabich/Documents/plantApp/plant_app/app.py", line 154, in add_plant
    return render_template('add_plant.html', plant=plant)
           ^^^^^^^^^^^^^^^^^^^^^^^^^^^^^^^^^^^^^^^^^^^^^^
  File "/Users/wbabich/Documents/plantApp/plant_app/venv/lib/python3.11/site-packages/flask/templating.py", line 147, in render_template
    return _render(app, template, context)
           ^^^^^^^^^^^^^^^^^^^^^^^^^^^^^^^
  File "/Users/wbabich/Documents/plantApp/plant_app/venv/lib/python3.11/site-packages/flask/templating.py", line 130, in _render
    rv = template.render(context)
         ^^^^^^^^^^^^^^^^^^^^^^^^
  File "/Users/wbabich/Documents/plantApp/plant_app/venv/lib/python3.11/site-packages/jinja2/environment.py", line 1301, in render
    self.environment.handle_exception()
  File "/Users/wbabich/Documents/plantApp/plant_app/venv/lib/python3.11/site-packages/jinja2/environment.py", line 936, in handle_exception
    raise rewrite_traceback_stack(source=source)
  File "/Users/wbabich/Documents/plantApp/plant_app/templates/add_plant.html", line 1, in top-level template code
    {% extends 'base.html' %}
  File "/Users/wbabich/Documents/plantApp/plant_app/templates/base.html", line 45, in top-level template code
    {% block content %}
  File "/Users/wbabich/Documents/plantApp/plant_app/templates/add_plant.html", line 48, in block 'content'
    <form id="submit-form" action="{{ url_for('add_to_database') }}" method="POST" onsubmit="return false;">
    ^^^^^^^^^^^^^^^^^^^^^^^^^
  File "/Users/wbabich/Documents/plantApp/plant_app/venv/lib/python3.11/site-packages/flask/app.py", line 2034, in url_for
    return self.handle_url_build_error(error, endpoint, values)
           ^^^^^^^^^^^^^^^^^^^^^^^^^^^^^^^^^^^^^^^^^^^^^^^^^^^^
  File "/Users/wbabich/Documents/plantApp/plant_app/venv/lib/python3.11/site-packages/flask/app.py", line 2023, in url_for
    rv = url_adapter.build(  # type: ignore[union-attr]
         ^^^^^^^^^^^^^^^^^^^^^^^^^^^^^^^^^^^^^^^^^^^^^^
  File "/Users/wbabich/Documents/plantApp/plant_app/venv/lib/python3.11/site-packages/werkzeug/routing/map.py", line 917, in build
    raise BuildError(endpoint, values, method, self)
werkzeug.routing.exceptions.BuildError: Could not build url for endpoint 'add_to_database'. Did you forget to specify values ['id']?
2023-04-23 22:20:04,879 - app - ERROR - Exception on /add_plant [GET]
Traceback (most recent call last):
  File "/Users/wbabich/Documents/plantApp/plant_app/venv/lib/python3.11/site-packages/flask/app.py", line 2528, in wsgi_app
    response = self.full_dispatch_request()
               ^^^^^^^^^^^^^^^^^^^^^^^^^^^^
  File "/Users/wbabich/Documents/plantApp/plant_app/venv/lib/python3.11/site-packages/flask/app.py", line 1825, in full_dispatch_request
    rv = self.handle_user_exception(e)
         ^^^^^^^^^^^^^^^^^^^^^^^^^^^^^
  File "/Users/wbabich/Documents/plantApp/plant_app/venv/lib/python3.11/site-packages/flask/app.py", line 1823, in full_dispatch_request
    rv = self.dispatch_request()
         ^^^^^^^^^^^^^^^^^^^^^^^
  File "/Users/wbabich/Documents/plantApp/plant_app/venv/lib/python3.11/site-packages/flask/app.py", line 1799, in dispatch_request
    return self.ensure_sync(self.view_functions[rule.endpoint])(**view_args)
           ^^^^^^^^^^^^^^^^^^^^^^^^^^^^^^^^^^^^^^^^^^^^^^^^^^^^^^^^^^^^^^^^^
  File "/Users/wbabich/Documents/plantApp/plant_app/app.py", line 154, in add_plant
    return render_template('add_plant.html', plant=plant)
           ^^^^^^^^^^^^^^^^^^^^^^^^^^^^^^^^^^^^^^^^^^^^^^
  File "/Users/wbabich/Documents/plantApp/plant_app/venv/lib/python3.11/site-packages/flask/templating.py", line 147, in render_template
    return _render(app, template, context)
           ^^^^^^^^^^^^^^^^^^^^^^^^^^^^^^^
  File "/Users/wbabich/Documents/plantApp/plant_app/venv/lib/python3.11/site-packages/flask/templating.py", line 130, in _render
    rv = template.render(context)
         ^^^^^^^^^^^^^^^^^^^^^^^^
  File "/Users/wbabich/Documents/plantApp/plant_app/venv/lib/python3.11/site-packages/jinja2/environment.py", line 1301, in render
    self.environment.handle_exception()
  File "/Users/wbabich/Documents/plantApp/plant_app/venv/lib/python3.11/site-packages/jinja2/environment.py", line 936, in handle_exception
    raise rewrite_traceback_stack(source=source)
  File "/Users/wbabich/Documents/plantApp/plant_app/templates/add_plant.html", line 1, in top-level template code
    {% extends 'base.html' %}
  File "/Users/wbabich/Documents/plantApp/plant_app/templates/base.html", line 45, in top-level template code
    {% block content %}
  File "/Users/wbabich/Documents/plantApp/plant_app/templates/add_plant.html", line 48, in block 'content'
    <form id="submit-form" action="{{ url_for('add_to_database') }}" method="POST" onsubmit="return false;">
    ^^^^^^^^^^^^^^^^^^^^^^^^^
  File "/Users/wbabich/Documents/plantApp/plant_app/venv/lib/python3.11/site-packages/flask/app.py", line 2034, in url_for
    return self.handle_url_build_error(error, endpoint, values)
           ^^^^^^^^^^^^^^^^^^^^^^^^^^^^^^^^^^^^^^^^^^^^^^^^^^^^
  File "/Users/wbabich/Documents/plantApp/plant_app/venv/lib/python3.11/site-packages/flask/app.py", line 2023, in url_for
    rv = url_adapter.build(  # type: ignore[union-attr]
         ^^^^^^^^^^^^^^^^^^^^^^^^^^^^^^^^^^^^^^^^^^^^^^
  File "/Users/wbabich/Documents/plantApp/plant_app/venv/lib/python3.11/site-packages/werkzeug/routing/map.py", line 917, in build
    raise BuildError(endpoint, values, method, self)
werkzeug.routing.exceptions.BuildError: Could not build url for endpoint 'add_to_database'. Did you mean 'add_plant' instead?
2023-04-23 22:20:46,422 - app - ERROR - Exception on /add_plant [GET]
Traceback (most recent call last):
  File "/Users/wbabich/Documents/plantApp/plant_app/venv/lib/python3.11/site-packages/flask/app.py", line 2528, in wsgi_app
    response = self.full_dispatch_request()
               ^^^^^^^^^^^^^^^^^^^^^^^^^^^^
  File "/Users/wbabich/Documents/plantApp/plant_app/venv/lib/python3.11/site-packages/flask/app.py", line 1825, in full_dispatch_request
    rv = self.handle_user_exception(e)
         ^^^^^^^^^^^^^^^^^^^^^^^^^^^^^
  File "/Users/wbabich/Documents/plantApp/plant_app/venv/lib/python3.11/site-packages/flask/app.py", line 1823, in full_dispatch_request
    rv = self.dispatch_request()
         ^^^^^^^^^^^^^^^^^^^^^^^
  File "/Users/wbabich/Documents/plantApp/plant_app/venv/lib/python3.11/site-packages/flask/app.py", line 1799, in dispatch_request
    return self.ensure_sync(self.view_functions[rule.endpoint])(**view_args)
           ^^^^^^^^^^^^^^^^^^^^^^^^^^^^^^^^^^^^^^^^^^^^^^^^^^^^^^^^^^^^^^^^^
  File "/Users/wbabich/Documents/plantApp/plant_app/app.py", line 154, in add_plant
    return render_template('add_plant.html', plant=plant)
           ^^^^^^^^^^^^^^^^^^^^^^^^^^^^^^^^^^^^^^^^^^^^^^
  File "/Users/wbabich/Documents/plantApp/plant_app/venv/lib/python3.11/site-packages/flask/templating.py", line 147, in render_template
    return _render(app, template, context)
           ^^^^^^^^^^^^^^^^^^^^^^^^^^^^^^^
  File "/Users/wbabich/Documents/plantApp/plant_app/venv/lib/python3.11/site-packages/flask/templating.py", line 130, in _render
    rv = template.render(context)
         ^^^^^^^^^^^^^^^^^^^^^^^^
  File "/Users/wbabich/Documents/plantApp/plant_app/venv/lib/python3.11/site-packages/jinja2/environment.py", line 1301, in render
    self.environment.handle_exception()
  File "/Users/wbabich/Documents/plantApp/plant_app/venv/lib/python3.11/site-packages/jinja2/environment.py", line 936, in handle_exception
    raise rewrite_traceback_stack(source=source)
  File "/Users/wbabich/Documents/plantApp/plant_app/templates/add_plant.html", line 1, in top-level template code
    {% extends 'base.html' %}
  File "/Users/wbabich/Documents/plantApp/plant_app/templates/base.html", line 45, in top-level template code
    {% block content %}
  File "/Users/wbabich/Documents/plantApp/plant_app/templates/add_plant.html", line 48, in block 'content'
    <form id="submit-form" action="{{ url_for('add_to_database') }}" method="POST" onsubmit="return false;">
    ^^^^^^^^^^^^^^^^^^^^^^^^^
  File "/Users/wbabich/Documents/plantApp/plant_app/venv/lib/python3.11/site-packages/flask/app.py", line 2034, in url_for
    return self.handle_url_build_error(error, endpoint, values)
           ^^^^^^^^^^^^^^^^^^^^^^^^^^^^^^^^^^^^^^^^^^^^^^^^^^^^
  File "/Users/wbabich/Documents/plantApp/plant_app/venv/lib/python3.11/site-packages/flask/app.py", line 2023, in url_for
    rv = url_adapter.build(  # type: ignore[union-attr]
         ^^^^^^^^^^^^^^^^^^^^^^^^^^^^^^^^^^^^^^^^^^^^^^
  File "/Users/wbabich/Documents/plantApp/plant_app/venv/lib/python3.11/site-packages/werkzeug/routing/map.py", line 917, in build
    raise BuildError(endpoint, values, method, self)
werkzeug.routing.exceptions.BuildError: Could not build url for endpoint 'add_to_database'. Did you forget to specify values ['id']?
2023-04-23 22:23:29,403 - app - ERROR - Exception on /add_plant [GET]
Traceback (most recent call last):
  File "/Users/wbabich/Documents/plantApp/plant_app/venv/lib/python3.11/site-packages/flask/app.py", line 2528, in wsgi_app
    response = self.full_dispatch_request()
               ^^^^^^^^^^^^^^^^^^^^^^^^^^^^
  File "/Users/wbabich/Documents/plantApp/plant_app/venv/lib/python3.11/site-packages/flask/app.py", line 1825, in full_dispatch_request
    rv = self.handle_user_exception(e)
         ^^^^^^^^^^^^^^^^^^^^^^^^^^^^^
  File "/Users/wbabich/Documents/plantApp/plant_app/venv/lib/python3.11/site-packages/flask/app.py", line 1823, in full_dispatch_request
    rv = self.dispatch_request()
         ^^^^^^^^^^^^^^^^^^^^^^^
  File "/Users/wbabich/Documents/plantApp/plant_app/venv/lib/python3.11/site-packages/flask/app.py", line 1799, in dispatch_request
    return self.ensure_sync(self.view_functions[rule.endpoint])(**view_args)
           ^^^^^^^^^^^^^^^^^^^^^^^^^^^^^^^^^^^^^^^^^^^^^^^^^^^^^^^^^^^^^^^^^
  File "/Users/wbabich/Documents/plantApp/plant_app/app.py", line 154, in add_plant
    return render_template('add_plant.html', plant=plant)
           ^^^^^^^^^^^^^^^^^^^^^^^^^^^^^^^^^^^^^^^^^^^^^^
  File "/Users/wbabich/Documents/plantApp/plant_app/venv/lib/python3.11/site-packages/flask/templating.py", line 147, in render_template
    return _render(app, template, context)
           ^^^^^^^^^^^^^^^^^^^^^^^^^^^^^^^
  File "/Users/wbabich/Documents/plantApp/plant_app/venv/lib/python3.11/site-packages/flask/templating.py", line 130, in _render
    rv = template.render(context)
         ^^^^^^^^^^^^^^^^^^^^^^^^
  File "/Users/wbabich/Documents/plantApp/plant_app/venv/lib/python3.11/site-packages/jinja2/environment.py", line 1301, in render
    self.environment.handle_exception()
  File "/Users/wbabich/Documents/plantApp/plant_app/venv/lib/python3.11/site-packages/jinja2/environment.py", line 936, in handle_exception
    raise rewrite_traceback_stack(source=source)
  File "/Users/wbabich/Documents/plantApp/plant_app/templates/add_plant.html", line 1, in top-level template code
    {% extends 'base.html' %}
  File "/Users/wbabich/Documents/plantApp/plant_app/templates/base.html", line 45, in top-level template code
    {% block content %}
  File "/Users/wbabich/Documents/plantApp/plant_app/templates/add_plant.html", line 48, in block 'content'
    <form id="submit-form" action="{{ url_for('add_to_database', id=next_id) }}" method="POST" onsubmit="return false;">
    ^^^^^^^^^^^^^^^^^^^^^^^^^
  File "/Users/wbabich/Documents/plantApp/plant_app/venv/lib/python3.11/site-packages/flask/app.py", line 2023, in url_for
    rv = url_adapter.build(  # type: ignore[union-attr]
         ^^^^^^^^^^^^^^^^^^^^^^^^^^^^^^^^^^^^^^^^^^^^^^
  File "/Users/wbabich/Documents/plantApp/plant_app/venv/lib/python3.11/site-packages/werkzeug/routing/map.py", line 915, in build
    rv = self._partial_build(endpoint, values, method, append_unknown)
         ^^^^^^^^^^^^^^^^^^^^^^^^^^^^^^^^^^^^^^^^^^^^^^^^^^^^^^^^^^^^^
  File "/Users/wbabich/Documents/plantApp/plant_app/venv/lib/python3.11/site-packages/werkzeug/routing/map.py", line 807, in _partial_build
    build_rv = rule.build(values, append_unknown)
               ^^^^^^^^^^^^^^^^^^^^^^^^^^^^^^^^^^
  File "/Users/wbabich/Documents/plantApp/plant_app/venv/lib/python3.11/site-packages/werkzeug/routing/rules.py", line 826, in build
    return self._build_unknown(**values)
           ^^^^^^^^^^^^^^^^^^^^^^^^^^^^^
  File "<werkzeug routing>", line 1, in <builder:'/add_to_database/<int:id>'>
  File "/Users/wbabich/Documents/plantApp/plant_app/venv/lib/python3.11/site-packages/werkzeug/routing/converters.py", line 156, in to_url
    value = str(self.num_convert(value))
                ^^^^^^^^^^^^^^^^^^^^^^^
jinja2.exceptions.UndefinedError: 'next_id' is undefined
2023-04-23 22:24:29,132 - app - ERROR - Exception on /add_plant [GET]
Traceback (most recent call last):
  File "/Users/wbabich/Documents/plantApp/plant_app/venv/lib/python3.11/site-packages/flask/app.py", line 2528, in wsgi_app
    response = self.full_dispatch_request()
               ^^^^^^^^^^^^^^^^^^^^^^^^^^^^
  File "/Users/wbabich/Documents/plantApp/plant_app/venv/lib/python3.11/site-packages/flask/app.py", line 1825, in full_dispatch_request
    rv = self.handle_user_exception(e)
         ^^^^^^^^^^^^^^^^^^^^^^^^^^^^^
  File "/Users/wbabich/Documents/plantApp/plant_app/venv/lib/python3.11/site-packages/flask/app.py", line 1823, in full_dispatch_request
    rv = self.dispatch_request()
         ^^^^^^^^^^^^^^^^^^^^^^^
  File "/Users/wbabich/Documents/plantApp/plant_app/venv/lib/python3.11/site-packages/flask/app.py", line 1799, in dispatch_request
    return self.ensure_sync(self.view_functions[rule.endpoint])(**view_args)
           ^^^^^^^^^^^^^^^^^^^^^^^^^^^^^^^^^^^^^^^^^^^^^^^^^^^^^^^^^^^^^^^^^
  File "/Users/wbabich/Documents/plantApp/plant_app/app.py", line 154, in add_plant
    return render_template('add_plant.html', plant=plant)
           ^^^^^^^^^^^^^^^^^^^^^^^^^^^^^^^^^^^^^^^^^^^^^^
  File "/Users/wbabich/Documents/plantApp/plant_app/venv/lib/python3.11/site-packages/flask/templating.py", line 147, in render_template
    return _render(app, template, context)
           ^^^^^^^^^^^^^^^^^^^^^^^^^^^^^^^
  File "/Users/wbabich/Documents/plantApp/plant_app/venv/lib/python3.11/site-packages/flask/templating.py", line 130, in _render
    rv = template.render(context)
         ^^^^^^^^^^^^^^^^^^^^^^^^
  File "/Users/wbabich/Documents/plantApp/plant_app/venv/lib/python3.11/site-packages/jinja2/environment.py", line 1301, in render
    self.environment.handle_exception()
  File "/Users/wbabich/Documents/plantApp/plant_app/venv/lib/python3.11/site-packages/jinja2/environment.py", line 936, in handle_exception
    raise rewrite_traceback_stack(source=source)
  File "/Users/wbabich/Documents/plantApp/plant_app/templates/add_plant.html", line 1, in top-level template code
    {% extends 'base.html' %}
  File "/Users/wbabich/Documents/plantApp/plant_app/templates/base.html", line 45, in top-level template code
    {% block content %}
  File "/Users/wbabich/Documents/plantApp/plant_app/templates/add_plant.html", line 48, in block 'content'
    <form id="submit-form" action="{{ url_for('add_to_database', id="{{ next_id }}") }}" method="POST" onsubmit="return false;">
    ^^^^^^^^^^^^^^^^^^^^^^^^^
  File "/Users/wbabich/Documents/plantApp/plant_app/venv/lib/python3.11/site-packages/flask/app.py", line 2023, in url_for
    rv = url_adapter.build(  # type: ignore[union-attr]
         ^^^^^^^^^^^^^^^^^^^^^^^^^^^^^^^^^^^^^^^^^^^^^^
  File "/Users/wbabich/Documents/plantApp/plant_app/venv/lib/python3.11/site-packages/werkzeug/routing/map.py", line 915, in build
    rv = self._partial_build(endpoint, values, method, append_unknown)
         ^^^^^^^^^^^^^^^^^^^^^^^^^^^^^^^^^^^^^^^^^^^^^^^^^^^^^^^^^^^^^
  File "/Users/wbabich/Documents/plantApp/plant_app/venv/lib/python3.11/site-packages/werkzeug/routing/map.py", line 807, in _partial_build
    build_rv = rule.build(values, append_unknown)
               ^^^^^^^^^^^^^^^^^^^^^^^^^^^^^^^^^^
  File "/Users/wbabich/Documents/plantApp/plant_app/venv/lib/python3.11/site-packages/werkzeug/routing/rules.py", line 826, in build
    return self._build_unknown(**values)
           ^^^^^^^^^^^^^^^^^^^^^^^^^^^^^
  File "<werkzeug routing>", line 1, in <builder:'/add_to_database/<int:id>'>
  File "/Users/wbabich/Documents/plantApp/plant_app/venv/lib/python3.11/site-packages/werkzeug/routing/converters.py", line 156, in to_url
    value = str(self.num_convert(value))
                ^^^^^^^^^^^^^^^^^^^^^^^
ValueError: invalid literal for int() with base 10: '{{ next_id }}'
2023-04-23 22:26:00,791 - app - ERROR - Exception on /add_plant [GET]
Traceback (most recent call last):
  File "/Users/wbabich/Documents/plantApp/plant_app/venv/lib/python3.11/site-packages/flask/app.py", line 2528, in wsgi_app
    response = self.full_dispatch_request()
               ^^^^^^^^^^^^^^^^^^^^^^^^^^^^
  File "/Users/wbabich/Documents/plantApp/plant_app/venv/lib/python3.11/site-packages/flask/app.py", line 1825, in full_dispatch_request
    rv = self.handle_user_exception(e)
         ^^^^^^^^^^^^^^^^^^^^^^^^^^^^^
  File "/Users/wbabich/Documents/plantApp/plant_app/venv/lib/python3.11/site-packages/flask/app.py", line 1823, in full_dispatch_request
    rv = self.dispatch_request()
         ^^^^^^^^^^^^^^^^^^^^^^^
  File "/Users/wbabich/Documents/plantApp/plant_app/venv/lib/python3.11/site-packages/flask/app.py", line 1799, in dispatch_request
    return self.ensure_sync(self.view_functions[rule.endpoint])(**view_args)
           ^^^^^^^^^^^^^^^^^^^^^^^^^^^^^^^^^^^^^^^^^^^^^^^^^^^^^^^^^^^^^^^^^
  File "/Users/wbabich/Documents/plantApp/plant_app/app.py", line 154, in add_plant
    return render_template('add_plant.html', plant=plant)
           ^^^^^^^^^^^^^^^^^^^^^^^^^^^^^^^^^^^^^^^^^^^^^^
  File "/Users/wbabich/Documents/plantApp/plant_app/venv/lib/python3.11/site-packages/flask/templating.py", line 147, in render_template
    return _render(app, template, context)
           ^^^^^^^^^^^^^^^^^^^^^^^^^^^^^^^
  File "/Users/wbabich/Documents/plantApp/plant_app/venv/lib/python3.11/site-packages/flask/templating.py", line 130, in _render
    rv = template.render(context)
         ^^^^^^^^^^^^^^^^^^^^^^^^
  File "/Users/wbabich/Documents/plantApp/plant_app/venv/lib/python3.11/site-packages/jinja2/environment.py", line 1301, in render
    self.environment.handle_exception()
  File "/Users/wbabich/Documents/plantApp/plant_app/venv/lib/python3.11/site-packages/jinja2/environment.py", line 936, in handle_exception
    raise rewrite_traceback_stack(source=source)
  File "/Users/wbabich/Documents/plantApp/plant_app/templates/add_plant.html", line 1, in top-level template code
    {% extends 'base.html' %}
  File "/Users/wbabich/Documents/plantApp/plant_app/templates/base.html", line 45, in top-level template code
    {% block content %}
  File "/Users/wbabich/Documents/plantApp/plant_app/templates/add_plant.html", line 48, in block 'content'
    <form id="submit-form" action="{{ url_for('add_to_database', id=next_id) }}" method="POST" onsubmit="return false;">
    ^^^^^^^^^^^^^^^^^^^^^^^^^
  File "/Users/wbabich/Documents/plantApp/plant_app/venv/lib/python3.11/site-packages/flask/app.py", line 2023, in url_for
    rv = url_adapter.build(  # type: ignore[union-attr]
         ^^^^^^^^^^^^^^^^^^^^^^^^^^^^^^^^^^^^^^^^^^^^^^
  File "/Users/wbabich/Documents/plantApp/plant_app/venv/lib/python3.11/site-packages/werkzeug/routing/map.py", line 915, in build
    rv = self._partial_build(endpoint, values, method, append_unknown)
         ^^^^^^^^^^^^^^^^^^^^^^^^^^^^^^^^^^^^^^^^^^^^^^^^^^^^^^^^^^^^^
  File "/Users/wbabich/Documents/plantApp/plant_app/venv/lib/python3.11/site-packages/werkzeug/routing/map.py", line 807, in _partial_build
    build_rv = rule.build(values, append_unknown)
               ^^^^^^^^^^^^^^^^^^^^^^^^^^^^^^^^^^
  File "/Users/wbabich/Documents/plantApp/plant_app/venv/lib/python3.11/site-packages/werkzeug/routing/rules.py", line 826, in build
    return self._build_unknown(**values)
           ^^^^^^^^^^^^^^^^^^^^^^^^^^^^^
  File "<werkzeug routing>", line 1, in <builder:'/add_to_database/<int:id>'>
  File "/Users/wbabich/Documents/plantApp/plant_app/venv/lib/python3.11/site-packages/werkzeug/routing/converters.py", line 156, in to_url
    value = str(self.num_convert(value))
                ^^^^^^^^^^^^^^^^^^^^^^^
jinja2.exceptions.UndefinedError: 'next_id' is undefined
2023-04-23 22:30:44,778 - app - ERROR - Exception on /add_plant [GET]
Traceback (most recent call last):
  File "/Users/wbabich/Documents/plantApp/plant_app/venv/lib/python3.11/site-packages/flask/app.py", line 2528, in wsgi_app
    response = self.full_dispatch_request()
               ^^^^^^^^^^^^^^^^^^^^^^^^^^^^
  File "/Users/wbabich/Documents/plantApp/plant_app/venv/lib/python3.11/site-packages/flask/app.py", line 1825, in full_dispatch_request
    rv = self.handle_user_exception(e)
         ^^^^^^^^^^^^^^^^^^^^^^^^^^^^^
  File "/Users/wbabich/Documents/plantApp/plant_app/venv/lib/python3.11/site-packages/flask/app.py", line 1823, in full_dispatch_request
    rv = self.dispatch_request()
         ^^^^^^^^^^^^^^^^^^^^^^^
  File "/Users/wbabich/Documents/plantApp/plant_app/venv/lib/python3.11/site-packages/flask/app.py", line 1799, in dispatch_request
    return self.ensure_sync(self.view_functions[rule.endpoint])(**view_args)
           ^^^^^^^^^^^^^^^^^^^^^^^^^^^^^^^^^^^^^^^^^^^^^^^^^^^^^^^^^^^^^^^^^
  File "/Users/wbabich/Documents/plantApp/plant_app/app.py", line 156, in add_plant
    return render_template('add_plant.html', plant=plant, next_id=next_id)
                                                                  ^^^^^^^
NameError: name 'next_id' is not defined
2023-04-23 22:31:44,371 - app - ERROR - Exception on /add_plant [GET]
Traceback (most recent call last):
  File "/Users/wbabich/Documents/plantApp/plant_app/venv/lib/python3.11/site-packages/flask/app.py", line 2528, in wsgi_app
    response = self.full_dispatch_request()
               ^^^^^^^^^^^^^^^^^^^^^^^^^^^^
  File "/Users/wbabich/Documents/plantApp/plant_app/venv/lib/python3.11/site-packages/flask/app.py", line 1825, in full_dispatch_request
    rv = self.handle_user_exception(e)
         ^^^^^^^^^^^^^^^^^^^^^^^^^^^^^
  File "/Users/wbabich/Documents/plantApp/plant_app/venv/lib/python3.11/site-packages/flask/app.py", line 1823, in full_dispatch_request
    rv = self.dispatch_request()
         ^^^^^^^^^^^^^^^^^^^^^^^
  File "/Users/wbabich/Documents/plantApp/plant_app/venv/lib/python3.11/site-packages/flask/app.py", line 1799, in dispatch_request
    return self.ensure_sync(self.view_functions[rule.endpoint])(**view_args)
           ^^^^^^^^^^^^^^^^^^^^^^^^^^^^^^^^^^^^^^^^^^^^^^^^^^^^^^^^^^^^^^^^^
TypeError: add_plant() missing 1 required positional argument: 'next_id'
2023-04-23 22:33:53,578 - app - ERROR - Exception on /add_plant [GET]
Traceback (most recent call last):
  File "/Users/wbabich/Documents/plantApp/plant_app/venv/lib/python3.11/site-packages/flask/app.py", line 2528, in wsgi_app
    response = self.full_dispatch_request()
               ^^^^^^^^^^^^^^^^^^^^^^^^^^^^
  File "/Users/wbabich/Documents/plantApp/plant_app/venv/lib/python3.11/site-packages/flask/app.py", line 1825, in full_dispatch_request
    rv = self.handle_user_exception(e)
         ^^^^^^^^^^^^^^^^^^^^^^^^^^^^^
  File "/Users/wbabich/Documents/plantApp/plant_app/venv/lib/python3.11/site-packages/flask/app.py", line 1823, in full_dispatch_request
    rv = self.dispatch_request()
         ^^^^^^^^^^^^^^^^^^^^^^^
  File "/Users/wbabich/Documents/plantApp/plant_app/venv/lib/python3.11/site-packages/flask/app.py", line 1799, in dispatch_request
    return self.ensure_sync(self.view_functions[rule.endpoint])(**view_args)
           ^^^^^^^^^^^^^^^^^^^^^^^^^^^^^^^^^^^^^^^^^^^^^^^^^^^^^^^^^^^^^^^^^
TypeError: add_plant() missing 1 required positional argument: 'next_id'
2023-04-23 22:36:31,253 - app - ERROR - Exception on /add_plant [GET]
Traceback (most recent call last):
  File "/Users/wbabich/Documents/plantApp/plant_app/venv/lib/python3.11/site-packages/flask/app.py", line 2528, in wsgi_app
    response = self.full_dispatch_request()
               ^^^^^^^^^^^^^^^^^^^^^^^^^^^^
  File "/Users/wbabich/Documents/plantApp/plant_app/venv/lib/python3.11/site-packages/flask/app.py", line 1825, in full_dispatch_request
    rv = self.handle_user_exception(e)
         ^^^^^^^^^^^^^^^^^^^^^^^^^^^^^
  File "/Users/wbabich/Documents/plantApp/plant_app/venv/lib/python3.11/site-packages/flask/app.py", line 1823, in full_dispatch_request
    rv = self.dispatch_request()
         ^^^^^^^^^^^^^^^^^^^^^^^
  File "/Users/wbabich/Documents/plantApp/plant_app/venv/lib/python3.11/site-packages/flask/app.py", line 1799, in dispatch_request
    return self.ensure_sync(self.view_functions[rule.endpoint])(**view_args)
           ^^^^^^^^^^^^^^^^^^^^^^^^^^^^^^^^^^^^^^^^^^^^^^^^^^^^^^^^^^^^^^^^^
  File "/Users/wbabich/Documents/plantApp/plant_app/app.py", line 156, in add_plant
    return render_template('add_plant.html', plant=plant, next_id=next_id)
                                                                  ^^^^^^^
NameError: name 'next_id' is not defined
2023-04-23 22:37:02,957 - app - ERROR - Exception on /add_plant [GET]
Traceback (most recent call last):
  File "/Users/wbabich/Documents/plantApp/plant_app/venv/lib/python3.11/site-packages/flask/app.py", line 2528, in wsgi_app
    response = self.full_dispatch_request()
               ^^^^^^^^^^^^^^^^^^^^^^^^^^^^
  File "/Users/wbabich/Documents/plantApp/plant_app/venv/lib/python3.11/site-packages/flask/app.py", line 1825, in full_dispatch_request
    rv = self.handle_user_exception(e)
         ^^^^^^^^^^^^^^^^^^^^^^^^^^^^^
  File "/Users/wbabich/Documents/plantApp/plant_app/venv/lib/python3.11/site-packages/flask/app.py", line 1823, in full_dispatch_request
    rv = self.dispatch_request()
         ^^^^^^^^^^^^^^^^^^^^^^^
  File "/Users/wbabich/Documents/plantApp/plant_app/venv/lib/python3.11/site-packages/flask/app.py", line 1799, in dispatch_request
    return self.ensure_sync(self.view_functions[rule.endpoint])(**view_args)
           ^^^^^^^^^^^^^^^^^^^^^^^^^^^^^^^^^^^^^^^^^^^^^^^^^^^^^^^^^^^^^^^^^
  File "/Users/wbabich/Documents/plantApp/plant_app/app.py", line 156, in add_plant
    return render_template('add_plant.html', plant=plant, next_id=next_id)
                                                                  ^^^^^^^
NameError: name 'next_id' is not defined
2023-04-23 22:37:32,179 - app - ERROR - Exception on /add_plant [GET]
Traceback (most recent call last):
  File "/Users/wbabich/Documents/plantApp/plant_app/venv/lib/python3.11/site-packages/flask/app.py", line 2528, in wsgi_app
    response = self.full_dispatch_request()
               ^^^^^^^^^^^^^^^^^^^^^^^^^^^^
  File "/Users/wbabich/Documents/plantApp/plant_app/venv/lib/python3.11/site-packages/flask/app.py", line 1825, in full_dispatch_request
    rv = self.handle_user_exception(e)
         ^^^^^^^^^^^^^^^^^^^^^^^^^^^^^
  File "/Users/wbabich/Documents/plantApp/plant_app/venv/lib/python3.11/site-packages/flask/app.py", line 1823, in full_dispatch_request
    rv = self.dispatch_request()
         ^^^^^^^^^^^^^^^^^^^^^^^
  File "/Users/wbabich/Documents/plantApp/plant_app/venv/lib/python3.11/site-packages/flask/app.py", line 1799, in dispatch_request
    return self.ensure_sync(self.view_functions[rule.endpoint])(**view_args)
           ^^^^^^^^^^^^^^^^^^^^^^^^^^^^^^^^^^^^^^^^^^^^^^^^^^^^^^^^^^^^^^^^^
  File "/Users/wbabich/Documents/plantApp/plant_app/app.py", line 156, in add_plant
    return render_template('add_plant.html', plant=plant)
           ^^^^^^^^^^^^^^^^^^^^^^^^^^^^^^^^^^^^^^^^^^^^^^
  File "/Users/wbabich/Documents/plantApp/plant_app/venv/lib/python3.11/site-packages/flask/templating.py", line 146, in render_template
    template = app.jinja_env.get_or_select_template(template_name_or_list)
               ^^^^^^^^^^^^^^^^^^^^^^^^^^^^^^^^^^^^^^^^^^^^^^^^^^^^^^^^^^^
  File "/Users/wbabich/Documents/plantApp/plant_app/venv/lib/python3.11/site-packages/jinja2/environment.py", line 1081, in get_or_select_template
    return self.get_template(template_name_or_list, parent, globals)
           ^^^^^^^^^^^^^^^^^^^^^^^^^^^^^^^^^^^^^^^^^^^^^^^^^^^^^^^^^
  File "/Users/wbabich/Documents/plantApp/plant_app/venv/lib/python3.11/site-packages/jinja2/environment.py", line 1010, in get_template
    return self._load_template(name, globals)
           ^^^^^^^^^^^^^^^^^^^^^^^^^^^^^^^^^^
  File "/Users/wbabich/Documents/plantApp/plant_app/venv/lib/python3.11/site-packages/jinja2/environment.py", line 969, in _load_template
    template = self.loader.load(self, name, self.make_globals(globals))
               ^^^^^^^^^^^^^^^^^^^^^^^^^^^^^^^^^^^^^^^^^^^^^^^^^^^^^^^^
  File "/Users/wbabich/Documents/plantApp/plant_app/venv/lib/python3.11/site-packages/jinja2/loaders.py", line 138, in load
    code = environment.compile(source, name, filename)
           ^^^^^^^^^^^^^^^^^^^^^^^^^^^^^^^^^^^^^^^^^^^
  File "/Users/wbabich/Documents/plantApp/plant_app/venv/lib/python3.11/site-packages/jinja2/environment.py", line 768, in compile
    self.handle_exception(source=source_hint)
  File "/Users/wbabich/Documents/plantApp/plant_app/venv/lib/python3.11/site-packages/jinja2/environment.py", line 936, in handle_exception
    raise rewrite_traceback_stack(source=source)
  File "/Users/wbabich/Documents/plantApp/plant_app/templates/add_plant.html", line 48, in template
    <form id="submit-form" action="{{ url_for('add_to_database'}}" method="POST" onsubmit="return false;">
    ^^^^^^^^^^^^^^^^^^^^^^^^^
jinja2.exceptions.TemplateSyntaxError: unexpected '}', expected ')'
2023-04-23 22:39:43,263 - app - ERROR - Exception on /add_plant [GET]
Traceback (most recent call last):
  File "/Users/wbabich/Documents/plantApp/plant_app/venv/lib/python3.11/site-packages/flask/app.py", line 2528, in wsgi_app
    response = self.full_dispatch_request()
               ^^^^^^^^^^^^^^^^^^^^^^^^^^^^
  File "/Users/wbabich/Documents/plantApp/plant_app/venv/lib/python3.11/site-packages/flask/app.py", line 1825, in full_dispatch_request
    rv = self.handle_user_exception(e)
         ^^^^^^^^^^^^^^^^^^^^^^^^^^^^^
  File "/Users/wbabich/Documents/plantApp/plant_app/venv/lib/python3.11/site-packages/flask/app.py", line 1823, in full_dispatch_request
    rv = self.dispatch_request()
         ^^^^^^^^^^^^^^^^^^^^^^^
  File "/Users/wbabich/Documents/plantApp/plant_app/venv/lib/python3.11/site-packages/flask/app.py", line 1799, in dispatch_request
    return self.ensure_sync(self.view_functions[rule.endpoint])(**view_args)
           ^^^^^^^^^^^^^^^^^^^^^^^^^^^^^^^^^^^^^^^^^^^^^^^^^^^^^^^^^^^^^^^^^
  File "/Users/wbabich/Documents/plantApp/plant_app/app.py", line 156, in add_plant
    return render_template('add_plant.html', plant=plant)
           ^^^^^^^^^^^^^^^^^^^^^^^^^^^^^^^^^^^^^^^^^^^^^^
  File "/Users/wbabich/Documents/plantApp/plant_app/venv/lib/python3.11/site-packages/flask/templating.py", line 147, in render_template
    return _render(app, template, context)
           ^^^^^^^^^^^^^^^^^^^^^^^^^^^^^^^
  File "/Users/wbabich/Documents/plantApp/plant_app/venv/lib/python3.11/site-packages/flask/templating.py", line 130, in _render
    rv = template.render(context)
         ^^^^^^^^^^^^^^^^^^^^^^^^
  File "/Users/wbabich/Documents/plantApp/plant_app/venv/lib/python3.11/site-packages/jinja2/environment.py", line 1301, in render
    self.environment.handle_exception()
  File "/Users/wbabich/Documents/plantApp/plant_app/venv/lib/python3.11/site-packages/jinja2/environment.py", line 936, in handle_exception
    raise rewrite_traceback_stack(source=source)
  File "/Users/wbabich/Documents/plantApp/plant_app/templates/add_plant.html", line 1, in top-level template code
    {% extends 'base.html' %}
  File "/Users/wbabich/Documents/plantApp/plant_app/templates/base.html", line 45, in top-level template code
    {% block content %}
  File "/Users/wbabich/Documents/plantApp/plant_app/templates/add_plant.html", line 48, in block 'content'
    <form id="submit-form" action="{{ url_for('add_to_database') }}" method="POST" onsubmit="return false;">
    ^^^^^^^^^^^^^^^^^^^^^^^^^
  File "/Users/wbabich/Documents/plantApp/plant_app/venv/lib/python3.11/site-packages/flask/app.py", line 2034, in url_for
    return self.handle_url_build_error(error, endpoint, values)
           ^^^^^^^^^^^^^^^^^^^^^^^^^^^^^^^^^^^^^^^^^^^^^^^^^^^^
  File "/Users/wbabich/Documents/plantApp/plant_app/venv/lib/python3.11/site-packages/flask/app.py", line 2023, in url_for
    rv = url_adapter.build(  # type: ignore[union-attr]
         ^^^^^^^^^^^^^^^^^^^^^^^^^^^^^^^^^^^^^^^^^^^^^^
  File "/Users/wbabich/Documents/plantApp/plant_app/venv/lib/python3.11/site-packages/werkzeug/routing/map.py", line 917, in build
    raise BuildError(endpoint, values, method, self)
werkzeug.routing.exceptions.BuildError: Could not build url for endpoint 'add_to_database'. Did you forget to specify values ['id']?
2023-04-23 22:46:06,395 - app - ERROR - Exception on /add_plant [GET]
Traceback (most recent call last):
  File "/Users/wbabich/Documents/plantApp/plant_app/venv/lib/python3.11/site-packages/flask/app.py", line 2528, in wsgi_app
    response = self.full_dispatch_request()
               ^^^^^^^^^^^^^^^^^^^^^^^^^^^^
  File "/Users/wbabich/Documents/plantApp/plant_app/venv/lib/python3.11/site-packages/flask/app.py", line 1825, in full_dispatch_request
    rv = self.handle_user_exception(e)
         ^^^^^^^^^^^^^^^^^^^^^^^^^^^^^
  File "/Users/wbabich/Documents/plantApp/plant_app/venv/lib/python3.11/site-packages/flask/app.py", line 1823, in full_dispatch_request
    rv = self.dispatch_request()
         ^^^^^^^^^^^^^^^^^^^^^^^
  File "/Users/wbabich/Documents/plantApp/plant_app/venv/lib/python3.11/site-packages/flask/app.py", line 1799, in dispatch_request
    return self.ensure_sync(self.view_functions[rule.endpoint])(**view_args)
           ^^^^^^^^^^^^^^^^^^^^^^^^^^^^^^^^^^^^^^^^^^^^^^^^^^^^^^^^^^^^^^^^^
  File "/Users/wbabich/Documents/plantApp/plant_app/app.py", line 156, in add_plant
    return render_template('add_plant.html', plant=plant)
           ^^^^^^^^^^^^^^^^^^^^^^^^^^^^^^^^^^^^^^^^^^^^^^
  File "/Users/wbabich/Documents/plantApp/plant_app/venv/lib/python3.11/site-packages/flask/templating.py", line 147, in render_template
    return _render(app, template, context)
           ^^^^^^^^^^^^^^^^^^^^^^^^^^^^^^^
  File "/Users/wbabich/Documents/plantApp/plant_app/venv/lib/python3.11/site-packages/flask/templating.py", line 130, in _render
    rv = template.render(context)
         ^^^^^^^^^^^^^^^^^^^^^^^^
  File "/Users/wbabich/Documents/plantApp/plant_app/venv/lib/python3.11/site-packages/jinja2/environment.py", line 1301, in render
    self.environment.handle_exception()
  File "/Users/wbabich/Documents/plantApp/plant_app/venv/lib/python3.11/site-packages/jinja2/environment.py", line 936, in handle_exception
    raise rewrite_traceback_stack(source=source)
  File "/Users/wbabich/Documents/plantApp/plant_app/templates/add_plant.html", line 1, in top-level template code
    {% extends 'base.html' %}
  File "/Users/wbabich/Documents/plantApp/plant_app/templates/base.html", line 45, in top-level template code
    {% block content %}
  File "/Users/wbabich/Documents/plantApp/plant_app/templates/add_plant.html", line 48, in block 'content'
    <form id="submit-form" action="{{ url_for('add_to_database') }}" method="POST" onsubmit="return false;">
    ^^^^^^^^^^^^^^^^^^^^^^^^^
  File "/Users/wbabich/Documents/plantApp/plant_app/venv/lib/python3.11/site-packages/flask/app.py", line 2034, in url_for
    return self.handle_url_build_error(error, endpoint, values)
           ^^^^^^^^^^^^^^^^^^^^^^^^^^^^^^^^^^^^^^^^^^^^^^^^^^^^
  File "/Users/wbabich/Documents/plantApp/plant_app/venv/lib/python3.11/site-packages/flask/app.py", line 2023, in url_for
    rv = url_adapter.build(  # type: ignore[union-attr]
         ^^^^^^^^^^^^^^^^^^^^^^^^^^^^^^^^^^^^^^^^^^^^^^
  File "/Users/wbabich/Documents/plantApp/plant_app/venv/lib/python3.11/site-packages/werkzeug/routing/map.py", line 917, in build
    raise BuildError(endpoint, values, method, self)
werkzeug.routing.exceptions.BuildError: Could not build url for endpoint 'add_to_database'. Did you forget to specify values ['id']?
2023-04-23 22:50:08,657 - app - ERROR - Exception on /add_plant [GET]
Traceback (most recent call last):
  File "/Users/wbabich/Documents/plantApp/plant_app/venv/lib/python3.11/site-packages/flask/app.py", line 2528, in wsgi_app
    response = self.full_dispatch_request()
               ^^^^^^^^^^^^^^^^^^^^^^^^^^^^
  File "/Users/wbabich/Documents/plantApp/plant_app/venv/lib/python3.11/site-packages/flask/app.py", line 1825, in full_dispatch_request
    rv = self.handle_user_exception(e)
         ^^^^^^^^^^^^^^^^^^^^^^^^^^^^^
  File "/Users/wbabich/Documents/plantApp/plant_app/venv/lib/python3.11/site-packages/flask/app.py", line 1823, in full_dispatch_request
    rv = self.dispatch_request()
         ^^^^^^^^^^^^^^^^^^^^^^^
  File "/Users/wbabich/Documents/plantApp/plant_app/venv/lib/python3.11/site-packages/flask/app.py", line 1799, in dispatch_request
    return self.ensure_sync(self.view_functions[rule.endpoint])(**view_args)
           ^^^^^^^^^^^^^^^^^^^^^^^^^^^^^^^^^^^^^^^^^^^^^^^^^^^^^^^^^^^^^^^^^
  File "/Users/wbabich/Documents/plantApp/plant_app/app.py", line 91, in add_plant
    plant = Plant()
            ^^^^^^^
TypeError: __init__() missing 2 required positional arguments: 'common_name' and 'scientific_name'
2023-04-23 22:52:35,475 - app - ERROR - Exception on /add_plant [GET]
Traceback (most recent call last):
  File "/Users/wbabich/Documents/plantApp/plant_app/venv/lib/python3.11/site-packages/flask/app.py", line 2528, in wsgi_app
    response = self.full_dispatch_request()
               ^^^^^^^^^^^^^^^^^^^^^^^^^^^^
  File "/Users/wbabich/Documents/plantApp/plant_app/venv/lib/python3.11/site-packages/flask/app.py", line 1825, in full_dispatch_request
    rv = self.handle_user_exception(e)
         ^^^^^^^^^^^^^^^^^^^^^^^^^^^^^
  File "/Users/wbabich/Documents/plantApp/plant_app/venv/lib/python3.11/site-packages/flask/app.py", line 1823, in full_dispatch_request
    rv = self.dispatch_request()
         ^^^^^^^^^^^^^^^^^^^^^^^
  File "/Users/wbabich/Documents/plantApp/plant_app/venv/lib/python3.11/site-packages/flask/app.py", line 1799, in dispatch_request
    return self.ensure_sync(self.view_functions[rule.endpoint])(**view_args)
           ^^^^^^^^^^^^^^^^^^^^^^^^^^^^^^^^^^^^^^^^^^^^^^^^^^^^^^^^^^^^^^^^^
  File "/Users/wbabich/Documents/plantApp/plant_app/app.py", line 157, in add_plant
    return render_template('add_plant.html', plant=plant)
           ^^^^^^^^^^^^^^^^^^^^^^^^^^^^^^^^^^^^^^^^^^^^^^
  File "/Users/wbabich/Documents/plantApp/plant_app/venv/lib/python3.11/site-packages/flask/templating.py", line 147, in render_template
    return _render(app, template, context)
           ^^^^^^^^^^^^^^^^^^^^^^^^^^^^^^^
  File "/Users/wbabich/Documents/plantApp/plant_app/venv/lib/python3.11/site-packages/flask/templating.py", line 130, in _render
    rv = template.render(context)
         ^^^^^^^^^^^^^^^^^^^^^^^^
  File "/Users/wbabich/Documents/plantApp/plant_app/venv/lib/python3.11/site-packages/jinja2/environment.py", line 1301, in render
    self.environment.handle_exception()
  File "/Users/wbabich/Documents/plantApp/plant_app/venv/lib/python3.11/site-packages/jinja2/environment.py", line 936, in handle_exception
    raise rewrite_traceback_stack(source=source)
  File "/Users/wbabich/Documents/plantApp/plant_app/templates/add_plant.html", line 1, in top-level template code
    {% extends 'base.html' %}
  File "/Users/wbabich/Documents/plantApp/plant_app/templates/base.html", line 45, in top-level template code
    {% block content %}
  File "/Users/wbabich/Documents/plantApp/plant_app/templates/add_plant.html", line 51, in block 'content'
    <input type="hidden" name="plant_info[scientific_name]" value="{{ plant_info['scientific_name'] }}">
    ^^^^^^^^^^^^^^^^^^^^^^^^^
  File "/Users/wbabich/Documents/plantApp/plant_app/venv/lib/python3.11/site-packages/jinja2/environment.py", line 466, in getitem
    return obj[argument]
           ~~~^^^^^^^^^^
jinja2.exceptions.UndefinedError: 'plant_info' is undefined
2023-04-23 22:53:58,385 - app - ERROR - Exception on /add_plant [GET]
Traceback (most recent call last):
  File "/Users/wbabich/Documents/plantApp/plant_app/venv/lib/python3.11/site-packages/flask/app.py", line 2528, in wsgi_app
    response = self.full_dispatch_request()
               ^^^^^^^^^^^^^^^^^^^^^^^^^^^^
  File "/Users/wbabich/Documents/plantApp/plant_app/venv/lib/python3.11/site-packages/flask/app.py", line 1825, in full_dispatch_request
    rv = self.handle_user_exception(e)
         ^^^^^^^^^^^^^^^^^^^^^^^^^^^^^
  File "/Users/wbabich/Documents/plantApp/plant_app/venv/lib/python3.11/site-packages/flask/app.py", line 1823, in full_dispatch_request
    rv = self.dispatch_request()
         ^^^^^^^^^^^^^^^^^^^^^^^
  File "/Users/wbabich/Documents/plantApp/plant_app/venv/lib/python3.11/site-packages/flask/app.py", line 1799, in dispatch_request
    return self.ensure_sync(self.view_functions[rule.endpoint])(**view_args)
           ^^^^^^^^^^^^^^^^^^^^^^^^^^^^^^^^^^^^^^^^^^^^^^^^^^^^^^^^^^^^^^^^^
  File "/Users/wbabich/Documents/plantApp/plant_app/app.py", line 91, in add_plant
    plant = Plant()
            ^^^^^^^
TypeError: __init__() missing 2 required positional arguments: 'common_name' and 'scientific_name'
2023-04-23 23:04:35,849 - app - ERROR - Exception on /add_plant [GET]
Traceback (most recent call last):
  File "/Users/wbabich/Documents/plantApp/plant_app/venv/lib/python3.11/site-packages/flask/app.py", line 2528, in wsgi_app
    response = self.full_dispatch_request()
               ^^^^^^^^^^^^^^^^^^^^^^^^^^^^
  File "/Users/wbabich/Documents/plantApp/plant_app/venv/lib/python3.11/site-packages/flask/app.py", line 1825, in full_dispatch_request
    rv = self.handle_user_exception(e)
         ^^^^^^^^^^^^^^^^^^^^^^^^^^^^^
  File "/Users/wbabich/Documents/plantApp/plant_app/venv/lib/python3.11/site-packages/flask/app.py", line 1823, in full_dispatch_request
    rv = self.dispatch_request()
         ^^^^^^^^^^^^^^^^^^^^^^^
  File "/Users/wbabich/Documents/plantApp/plant_app/venv/lib/python3.11/site-packages/flask/app.py", line 1799, in dispatch_request
    return self.ensure_sync(self.view_functions[rule.endpoint])(**view_args)
           ^^^^^^^^^^^^^^^^^^^^^^^^^^^^^^^^^^^^^^^^^^^^^^^^^^^^^^^^^^^^^^^^^
  File "/Users/wbabich/Documents/plantApp/plant_app/app.py", line 103, in add_plant
    return render_template('add_plant.html')
           ^^^^^^^^^^^^^^^^^^^^^^^^^^^^^^^^^
  File "/Users/wbabich/Documents/plantApp/plant_app/venv/lib/python3.11/site-packages/flask/templating.py", line 147, in render_template
    return _render(app, template, context)
           ^^^^^^^^^^^^^^^^^^^^^^^^^^^^^^^
  File "/Users/wbabich/Documents/plantApp/plant_app/venv/lib/python3.11/site-packages/flask/templating.py", line 130, in _render
    rv = template.render(context)
         ^^^^^^^^^^^^^^^^^^^^^^^^
  File "/Users/wbabich/Documents/plantApp/plant_app/venv/lib/python3.11/site-packages/jinja2/environment.py", line 1301, in render
    self.environment.handle_exception()
  File "/Users/wbabich/Documents/plantApp/plant_app/venv/lib/python3.11/site-packages/jinja2/environment.py", line 936, in handle_exception
    raise rewrite_traceback_stack(source=source)
  File "/Users/wbabich/Documents/plantApp/plant_app/templates/add_plant.html", line 1, in top-level template code
    {% extends 'base.html' %}
  File "/Users/wbabich/Documents/plantApp/plant_app/templates/base.html", line 45, in top-level template code
    {% block content %}
  File "/Users/wbabich/Documents/plantApp/plant_app/templates/add_plant.html", line 50, in block 'content'
    <input type="hidden" name="plant_info[scientific_name]" value="{{ plant_info['scientific_name'] }}">
    ^^^^^^^^^^^^^^^^^^^^^^^^^
  File "/Users/wbabich/Documents/plantApp/plant_app/venv/lib/python3.11/site-packages/jinja2/environment.py", line 466, in getitem
    return obj[argument]
           ~~~^^^^^^^^^^
jinja2.exceptions.UndefinedError: 'plant_info' is undefined
2023-04-23 23:09:10,408 - app - ERROR - Exception on /add_plant [GET]
Traceback (most recent call last):
  File "/Users/wbabich/Documents/plantApp/plant_app/venv/lib/python3.11/site-packages/flask/app.py", line 2528, in wsgi_app
    response = self.full_dispatch_request()
               ^^^^^^^^^^^^^^^^^^^^^^^^^^^^
  File "/Users/wbabich/Documents/plantApp/plant_app/venv/lib/python3.11/site-packages/flask/app.py", line 1825, in full_dispatch_request
    rv = self.handle_user_exception(e)
         ^^^^^^^^^^^^^^^^^^^^^^^^^^^^^
  File "/Users/wbabich/Documents/plantApp/plant_app/venv/lib/python3.11/site-packages/flask/app.py", line 1823, in full_dispatch_request
    rv = self.dispatch_request()
         ^^^^^^^^^^^^^^^^^^^^^^^
  File "/Users/wbabich/Documents/plantApp/plant_app/venv/lib/python3.11/site-packages/flask/app.py", line 1799, in dispatch_request
    return self.ensure_sync(self.view_functions[rule.endpoint])(**view_args)
           ^^^^^^^^^^^^^^^^^^^^^^^^^^^^^^^^^^^^^^^^^^^^^^^^^^^^^^^^^^^^^^^^^
  File "/Users/wbabich/Documents/plantApp/plant_app/app.py", line 119, in add_plant
    return render_template('add_plant.html')
           ^^^^^^^^^^^^^^^^^^^^^^^^^^^^^^^^^
  File "/Users/wbabich/Documents/plantApp/plant_app/venv/lib/python3.11/site-packages/flask/templating.py", line 147, in render_template
    return _render(app, template, context)
           ^^^^^^^^^^^^^^^^^^^^^^^^^^^^^^^
  File "/Users/wbabich/Documents/plantApp/plant_app/venv/lib/python3.11/site-packages/flask/templating.py", line 130, in _render
    rv = template.render(context)
         ^^^^^^^^^^^^^^^^^^^^^^^^
  File "/Users/wbabich/Documents/plantApp/plant_app/venv/lib/python3.11/site-packages/jinja2/environment.py", line 1301, in render
    self.environment.handle_exception()
  File "/Users/wbabich/Documents/plantApp/plant_app/venv/lib/python3.11/site-packages/jinja2/environment.py", line 936, in handle_exception
    raise rewrite_traceback_stack(source=source)
  File "/Users/wbabich/Documents/plantApp/plant_app/templates/add_plant.html", line 1, in top-level template code
    {% extends 'base.html' %}
  File "/Users/wbabich/Documents/plantApp/plant_app/templates/base.html", line 45, in top-level template code
    {% block content %}
  File "/Users/wbabich/Documents/plantApp/plant_app/templates/add_plant.html", line 50, in block 'content'
    <input type="hidden" name="plant_info[scientific_name]" value="{{ plant_info['scientific_name'] }}">
    ^^^^^^^^^^^^^^^^^^^^^^^^^
  File "/Users/wbabich/Documents/plantApp/plant_app/venv/lib/python3.11/site-packages/jinja2/environment.py", line 466, in getitem
    return obj[argument]
           ~~~^^^^^^^^^^
jinja2.exceptions.UndefinedError: 'plant_info' is undefined
