2023-04-27 15:52:53,573 - app - ERROR - Exception on /search_plant [POST]
Traceback (most recent call last):
  File "/Users/wbabich/Documents/plantApp/plant_app/venv/lib/python3.11/site-packages/flask/app.py", line 2528, in wsgi_app
    response = self.full_dispatch_request()
               ^^^^^^^^^^^^^^^^^^^^^^^^^^^^
  File "/Users/wbabich/Documents/plantApp/plant_app/venv/lib/python3.11/site-packages/flask/app.py", line 1825, in full_dispatch_request
    rv = self.handle_user_exception(e)
         ^^^^^^^^^^^^^^^^^^^^^^^^^^^^^
  File "/Users/wbabich/Documents/plantApp/plant_app/venv/lib/python3.11/site-packages/flask/app.py", line 1823, in full_dispatch_request
    rv = self.dispatch_request()
         ^^^^^^^^^^^^^^^^^^^^^^^
  File "/Users/wbabich/Documents/plantApp/plant_app/venv/lib/python3.11/site-packages/flask/app.py", line 1799, in dispatch_request
    return self.ensure_sync(self.view_functions[rule.endpoint])(**view_args)
           ^^^^^^^^^^^^^^^^^^^^^^^^^^^^^^^^^^^^^^^^^^^^^^^^^^^^^^^^^^^^^^^^^
  File "/Users/wbabich/Documents/plantApp/plant_app/app.py", line 87, in search_plant
    return jsonify(results)
           ^^^^^^^^^^^^^^^^
TypeError: 'module' object is not callable
2023-04-28 09:16:09,168 - app - ERROR - Exception on /search_plant [GET]
Traceback (most recent call last):
  File "/opt/homebrew/lib/python3.11/site-packages/flask/app.py", line 2528, in wsgi_app
    response = self.full_dispatch_request()
               ^^^^^^^^^^^^^^^^^^^^^^^^^^^^
  File "/opt/homebrew/lib/python3.11/site-packages/flask/app.py", line 1825, in full_dispatch_request
    rv = self.handle_user_exception(e)
         ^^^^^^^^^^^^^^^^^^^^^^^^^^^^^
  File "/opt/homebrew/lib/python3.11/site-packages/flask/app.py", line 1823, in full_dispatch_request
    rv = self.dispatch_request()
         ^^^^^^^^^^^^^^^^^^^^^^^
  File "/opt/homebrew/lib/python3.11/site-packages/flask/app.py", line 1799, in dispatch_request
    return self.ensure_sync(self.view_functions[rule.endpoint])(**view_args)
           ^^^^^^^^^^^^^^^^^^^^^^^^^^^^^^^^^^^^^^^^^^^^^^^^^^^^^^^^^^^^^^^^^
  File "/Users/wbabich/PycharmProjects/plant_app/app.py", line 63, in search_plant
    results = plant_info.search_plant(query)
              ^^^^^^^^^^
NameError: name 'plant_info' is not defined
2023-04-28 09:21:44,416 - app - ERROR - Exception on /search_plant [GET]
Traceback (most recent call last):
  File "/opt/homebrew/lib/python3.11/site-packages/flask/app.py", line 2528, in wsgi_app
    response = self.full_dispatch_request()
               ^^^^^^^^^^^^^^^^^^^^^^^^^^^^
  File "/opt/homebrew/lib/python3.11/site-packages/flask/app.py", line 1825, in full_dispatch_request
    rv = self.handle_user_exception(e)
         ^^^^^^^^^^^^^^^^^^^^^^^^^^^^^
  File "/opt/homebrew/lib/python3.11/site-packages/flask/app.py", line 1823, in full_dispatch_request
    rv = self.dispatch_request()
         ^^^^^^^^^^^^^^^^^^^^^^^
  File "/opt/homebrew/lib/python3.11/site-packages/flask/app.py", line 1799, in dispatch_request
    return self.ensure_sync(self.view_functions[rule.endpoint])(**view_args)
           ^^^^^^^^^^^^^^^^^^^^^^^^^^^^^^^^^^^^^^^^^^^^^^^^^^^^^^^^^^^^^^^^^
  File "/Users/wbabich/PycharmProjects/plant_app/app.py", line 63, in search_plant
    results = plant_info.search_plant(query)
              ^^^^^^^^^^
NameError: name 'plant_info' is not defined
2023-04-28 09:22:58,019 - app - ERROR - Exception on /search_plant [GET]
Traceback (most recent call last):
  File "/opt/homebrew/lib/python3.11/site-packages/flask/app.py", line 2528, in wsgi_app
    response = self.full_dispatch_request()
               ^^^^^^^^^^^^^^^^^^^^^^^^^^^^
  File "/opt/homebrew/lib/python3.11/site-packages/flask/app.py", line 1825, in full_dispatch_request
    rv = self.handle_user_exception(e)
         ^^^^^^^^^^^^^^^^^^^^^^^^^^^^^
  File "/opt/homebrew/lib/python3.11/site-packages/flask/app.py", line 1823, in full_dispatch_request
    rv = self.dispatch_request()
         ^^^^^^^^^^^^^^^^^^^^^^^
  File "/opt/homebrew/lib/python3.11/site-packages/flask/app.py", line 1799, in dispatch_request
    return self.ensure_sync(self.view_functions[rule.endpoint])(**view_args)
           ^^^^^^^^^^^^^^^^^^^^^^^^^^^^^^^^^^^^^^^^^^^^^^^^^^^^^^^^^^^^^^^^^
  File "/Users/wbabich/PycharmProjects/plant_app/app.py", line 63, in search_plant
    results = get_plant_info.search_plant(query)
              ^^^^^^^^^^^^^^^^^^^^^^^^^^^
AttributeError: 'function' object has no attribute 'search_plant'
2023-04-28 09:50:23,304 - app - ERROR - Exception on /search_plant [GET]
Traceback (most recent call last):
  File "/opt/homebrew/lib/python3.11/site-packages/flask/app.py", line 2528, in wsgi_app
    response = self.full_dispatch_request()
               ^^^^^^^^^^^^^^^^^^^^^^^^^^^^
  File "/opt/homebrew/lib/python3.11/site-packages/flask/app.py", line 1825, in full_dispatch_request
    rv = self.handle_user_exception(e)
         ^^^^^^^^^^^^^^^^^^^^^^^^^^^^^
  File "/opt/homebrew/lib/python3.11/site-packages/flask/app.py", line 1823, in full_dispatch_request
    rv = self.dispatch_request()
         ^^^^^^^^^^^^^^^^^^^^^^^
  File "/opt/homebrew/lib/python3.11/site-packages/flask/app.py", line 1799, in dispatch_request
    return self.ensure_sync(self.view_functions[rule.endpoint])(**view_args)
           ^^^^^^^^^^^^^^^^^^^^^^^^^^^^^^^^^^^^^^^^^^^^^^^^^^^^^^^^^^^^^^^^^
  File "/Users/wbabich/PycharmProjects/plant_app/app.py", line 63, in search_plant
    results = Plant.search_plant(query)
              ^^^^^^^^^^^^^^^^^^
AttributeError: type object 'Plant' has no attribute 'search_plant'
2023-04-28 11:17:58,406 - app - ERROR - Exception on /search_plant [GET]
Traceback (most recent call last):
  File "/opt/homebrew/lib/python3.11/site-packages/flask/app.py", line 2528, in wsgi_app
    response = self.full_dispatch_request()
               ^^^^^^^^^^^^^^^^^^^^^^^^^^^^
  File "/opt/homebrew/lib/python3.11/site-packages/flask/app.py", line 1825, in full_dispatch_request
    rv = self.handle_user_exception(e)
         ^^^^^^^^^^^^^^^^^^^^^^^^^^^^^
  File "/opt/homebrew/lib/python3.11/site-packages/flask/app.py", line 1823, in full_dispatch_request
    rv = self.dispatch_request()
         ^^^^^^^^^^^^^^^^^^^^^^^
  File "/opt/homebrew/lib/python3.11/site-packages/flask/app.py", line 1799, in dispatch_request
    return self.ensure_sync(self.view_functions[rule.endpoint])(**view_args)
           ^^^^^^^^^^^^^^^^^^^^^^^^^^^^^^^^^^^^^^^^^^^^^^^^^^^^^^^^^^^^^^^^^
  File "/Users/wbabich/PycharmProjects/plant_app/app.py", line 70, in search_plant
    return render_template('search_plant.html')
           ^^^^^^^^^^^^^^^^^^^^^^^^^^^^^^^^^^^^
  File "/opt/homebrew/lib/python3.11/site-packages/flask/templating.py", line 147, in render_template
    return _render(app, template, context)
           ^^^^^^^^^^^^^^^^^^^^^^^^^^^^^^^
  File "/opt/homebrew/lib/python3.11/site-packages/flask/templating.py", line 130, in _render
    rv = template.render(context)
         ^^^^^^^^^^^^^^^^^^^^^^^^
  File "/opt/homebrew/lib/python3.11/site-packages/jinja2/environment.py", line 1301, in render
    self.environment.handle_exception()
  File "/opt/homebrew/lib/python3.11/site-packages/jinja2/environment.py", line 936, in handle_exception
    raise rewrite_traceback_stack(source=source)
  File "/Users/wbabich/PycharmProjects/plant_app/templates/search_plant.html", line 1, in top-level template code
    {% extends 'base.html' %}
  File "/Users/wbabich/PycharmProjects/plant_app/templates/base.html", line 43, in top-level template code
    {% block content %}
  File "/Users/wbabich/PycharmProjects/plant_app/templates/search_plant.html", line 5, in block 'content'
    <form method="POST" action="{{ url_for('search_results') }}">
    ^^^^^^^^^^^^^^^^^^^^^^^^^
  File "/opt/homebrew/lib/python3.11/site-packages/flask/app.py", line 2034, in url_for
    return self.handle_url_build_error(error, endpoint, values)
           ^^^^^^^^^^^^^^^^^^^^^^^^^^^^^^^^^^^^^^^^^^^^^^^^^^^^
  File "/opt/homebrew/lib/python3.11/site-packages/flask/app.py", line 2023, in url_for
    rv = url_adapter.build(  # type: ignore[union-attr]
         ^^^^^^^^^^^^^^^^^^^^^^^^^^^^^^^^^^^^^^^^^^^^^^
  File "/opt/homebrew/lib/python3.11/site-packages/werkzeug/routing/map.py", line 917, in build
    raise BuildError(endpoint, values, method, self)
werkzeug.routing.exceptions.BuildError: Could not build url for endpoint 'search_results'. Did you mean 'search_plant' instead?
2023-04-28 11:58:53,044 - app - ERROR - Exception on /search_plant [POST]
Traceback (most recent call last):
  File "/opt/homebrew/lib/python3.11/site-packages/flask/app.py", line 2528, in wsgi_app
    response = self.full_dispatch_request()
               ^^^^^^^^^^^^^^^^^^^^^^^^^^^^
  File "/opt/homebrew/lib/python3.11/site-packages/flask/app.py", line 1825, in full_dispatch_request
    rv = self.handle_user_exception(e)
         ^^^^^^^^^^^^^^^^^^^^^^^^^^^^^
  File "/opt/homebrew/lib/python3.11/site-packages/flask/app.py", line 1823, in full_dispatch_request
    rv = self.dispatch_request()
         ^^^^^^^^^^^^^^^^^^^^^^^
  File "/opt/homebrew/lib/python3.11/site-packages/flask/app.py", line 1799, in dispatch_request
    return self.ensure_sync(self.view_functions[rule.endpoint])(**view_args)
           ^^^^^^^^^^^^^^^^^^^^^^^^^^^^^^^^^^^^^^^^^^^^^^^^^^^^^^^^^^^^^^^^^
  File "/Users/wbabich/PycharmProjects/plant_app/app.py", line 64, in search_plant
    data = search_plant_info(query)
           ^^^^^^^^^^^^^^^^^
NameError: name 'search_plant_info' is not defined
2023-04-28 11:59:52,637 - app - ERROR - Exception on /search_plant [POST]
Traceback (most recent call last):
  File "/opt/homebrew/lib/python3.11/site-packages/flask/app.py", line 2528, in wsgi_app
    response = self.full_dispatch_request()
               ^^^^^^^^^^^^^^^^^^^^^^^^^^^^
  File "/opt/homebrew/lib/python3.11/site-packages/flask/app.py", line 1825, in full_dispatch_request
    rv = self.handle_user_exception(e)
         ^^^^^^^^^^^^^^^^^^^^^^^^^^^^^
  File "/opt/homebrew/lib/python3.11/site-packages/flask/app.py", line 1823, in full_dispatch_request
    rv = self.dispatch_request()
         ^^^^^^^^^^^^^^^^^^^^^^^
  File "/opt/homebrew/lib/python3.11/site-packages/flask/app.py", line 1799, in dispatch_request
    return self.ensure_sync(self.view_functions[rule.endpoint])(**view_args)
           ^^^^^^^^^^^^^^^^^^^^^^^^^^^^^^^^^^^^^^^^^^^^^^^^^^^^^^^^^^^^^^^^^
  File "/Users/wbabich/PycharmProjects/plant_app/app.py", line 64, in search_plant
    data = plant_info(query)
           ^^^^^^^^^^
NameError: name 'plant_info' is not defined
2023-04-28 12:25:17,063 - app - ERROR - Exception on /search_plant [POST]
Traceback (most recent call last):
  File "/opt/homebrew/lib/python3.11/site-packages/flask/app.py", line 2528, in wsgi_app
    response = self.full_dispatch_request()
               ^^^^^^^^^^^^^^^^^^^^^^^^^^^^
  File "/opt/homebrew/lib/python3.11/site-packages/flask/app.py", line 1825, in full_dispatch_request
    rv = self.handle_user_exception(e)
         ^^^^^^^^^^^^^^^^^^^^^^^^^^^^^
  File "/opt/homebrew/lib/python3.11/site-packages/flask/app.py", line 1823, in full_dispatch_request
    rv = self.dispatch_request()
         ^^^^^^^^^^^^^^^^^^^^^^^
  File "/opt/homebrew/lib/python3.11/site-packages/flask/app.py", line 1799, in dispatch_request
    return self.ensure_sync(self.view_functions[rule.endpoint])(**view_args)
           ^^^^^^^^^^^^^^^^^^^^^^^^^^^^^^^^^^^^^^^^^^^^^^^^^^^^^^^^^^^^^^^^^
  File "/Users/wbabich/PycharmProjects/plant_app/app.py", line 71, in search_plant
    plant_info = plant_info.get_plant_info(plant_name)
                 ^^^^^^^^^^
UnboundLocalError: cannot access local variable 'plant_info' where it is not associated with a value
2023-04-28 12:26:16,005 - app - ERROR - Exception on /search_plant [POST]
Traceback (most recent call last):
  File "/opt/homebrew/lib/python3.11/site-packages/flask/app.py", line 2528, in wsgi_app
    response = self.full_dispatch_request()
               ^^^^^^^^^^^^^^^^^^^^^^^^^^^^
  File "/opt/homebrew/lib/python3.11/site-packages/flask/app.py", line 1825, in full_dispatch_request
    rv = self.handle_user_exception(e)
         ^^^^^^^^^^^^^^^^^^^^^^^^^^^^^
  File "/opt/homebrew/lib/python3.11/site-packages/flask/app.py", line 1823, in full_dispatch_request
    rv = self.dispatch_request()
         ^^^^^^^^^^^^^^^^^^^^^^^
  File "/opt/homebrew/lib/python3.11/site-packages/flask/app.py", line 1799, in dispatch_request
    return self.ensure_sync(self.view_functions[rule.endpoint])(**view_args)
           ^^^^^^^^^^^^^^^^^^^^^^^^^^^^^^^^^^^^^^^^^^^^^^^^^^^^^^^^^^^^^^^^^
  File "/Users/wbabich/PycharmProjects/plant_app/app.py", line 68, in search_plant
    return render_template('plant_info.html', plant=plant)
           ^^^^^^^^^^^^^^^^^^^^^^^^^^^^^^^^^^^^^^^^^^^^^^^
  File "/opt/homebrew/lib/python3.11/site-packages/flask/templating.py", line 146, in render_template
    template = app.jinja_env.get_or_select_template(template_name_or_list)
               ^^^^^^^^^^^^^^^^^^^^^^^^^^^^^^^^^^^^^^^^^^^^^^^^^^^^^^^^^^^
  File "/opt/homebrew/lib/python3.11/site-packages/jinja2/environment.py", line 1081, in get_or_select_template
    return self.get_template(template_name_or_list, parent, globals)
           ^^^^^^^^^^^^^^^^^^^^^^^^^^^^^^^^^^^^^^^^^^^^^^^^^^^^^^^^^
  File "/opt/homebrew/lib/python3.11/site-packages/jinja2/environment.py", line 1010, in get_template
    return self._load_template(name, globals)
           ^^^^^^^^^^^^^^^^^^^^^^^^^^^^^^^^^^
  File "/opt/homebrew/lib/python3.11/site-packages/jinja2/environment.py", line 969, in _load_template
    template = self.loader.load(self, name, self.make_globals(globals))
               ^^^^^^^^^^^^^^^^^^^^^^^^^^^^^^^^^^^^^^^^^^^^^^^^^^^^^^^^
  File "/opt/homebrew/lib/python3.11/site-packages/jinja2/loaders.py", line 126, in load
    source, filename, uptodate = self.get_source(environment, name)
                                 ^^^^^^^^^^^^^^^^^^^^^^^^^^^^^^^^^^
  File "/opt/homebrew/lib/python3.11/site-packages/flask/templating.py", line 62, in get_source
    return self._get_source_fast(environment, template)
           ^^^^^^^^^^^^^^^^^^^^^^^^^^^^^^^^^^^^^^^^^^^^
  File "/opt/homebrew/lib/python3.11/site-packages/flask/templating.py", line 98, in _get_source_fast
    raise TemplateNotFound(template)
jinja2.exceptions.TemplateNotFound: plant_info.html
2023-04-28 12:28:59,133 - app - ERROR - Exception on /search_plant [POST]
Traceback (most recent call last):
  File "/opt/homebrew/lib/python3.11/site-packages/flask/app.py", line 2528, in wsgi_app
    response = self.full_dispatch_request()
               ^^^^^^^^^^^^^^^^^^^^^^^^^^^^
  File "/opt/homebrew/lib/python3.11/site-packages/flask/app.py", line 1825, in full_dispatch_request
    rv = self.handle_user_exception(e)
         ^^^^^^^^^^^^^^^^^^^^^^^^^^^^^
  File "/opt/homebrew/lib/python3.11/site-packages/flask/app.py", line 1823, in full_dispatch_request
    rv = self.dispatch_request()
         ^^^^^^^^^^^^^^^^^^^^^^^
  File "/opt/homebrew/lib/python3.11/site-packages/flask/app.py", line 1799, in dispatch_request
    return self.ensure_sync(self.view_functions[rule.endpoint])(**view_args)
           ^^^^^^^^^^^^^^^^^^^^^^^^^^^^^^^^^^^^^^^^^^^^^^^^^^^^^^^^^^^^^^^^^
  File "/Users/wbabich/PycharmProjects/plant_app/app.py", line 73, in search_plant
    return render_template('plant_search_results.html', plant_info=plant_info)
           ^^^^^^^^^^^^^^^^^^^^^^^^^^^^^^^^^^^^^^^^^^^^^^^^^^^^^^^^^^^^^^^^^^^
  File "/opt/homebrew/lib/python3.11/site-packages/flask/templating.py", line 146, in render_template
    template = app.jinja_env.get_or_select_template(template_name_or_list)
               ^^^^^^^^^^^^^^^^^^^^^^^^^^^^^^^^^^^^^^^^^^^^^^^^^^^^^^^^^^^
  File "/opt/homebrew/lib/python3.11/site-packages/jinja2/environment.py", line 1081, in get_or_select_template
    return self.get_template(template_name_or_list, parent, globals)
           ^^^^^^^^^^^^^^^^^^^^^^^^^^^^^^^^^^^^^^^^^^^^^^^^^^^^^^^^^
  File "/opt/homebrew/lib/python3.11/site-packages/jinja2/environment.py", line 1010, in get_template
    return self._load_template(name, globals)
           ^^^^^^^^^^^^^^^^^^^^^^^^^^^^^^^^^^
  File "/opt/homebrew/lib/python3.11/site-packages/jinja2/environment.py", line 969, in _load_template
    template = self.loader.load(self, name, self.make_globals(globals))
               ^^^^^^^^^^^^^^^^^^^^^^^^^^^^^^^^^^^^^^^^^^^^^^^^^^^^^^^^
  File "/opt/homebrew/lib/python3.11/site-packages/jinja2/loaders.py", line 126, in load
    source, filename, uptodate = self.get_source(environment, name)
                                 ^^^^^^^^^^^^^^^^^^^^^^^^^^^^^^^^^^
  File "/opt/homebrew/lib/python3.11/site-packages/flask/templating.py", line 62, in get_source
    return self._get_source_fast(environment, template)
           ^^^^^^^^^^^^^^^^^^^^^^^^^^^^^^^^^^^^^^^^^^^^
  File "/opt/homebrew/lib/python3.11/site-packages/flask/templating.py", line 98, in _get_source_fast
    raise TemplateNotFound(template)
jinja2.exceptions.TemplateNotFound: plant_search_results.html
2023-04-28 12:40:23,141 - app - ERROR - Exception on /search_plant [GET]
Traceback (most recent call last):
  File "/opt/homebrew/lib/python3.11/site-packages/flask/app.py", line 2528, in wsgi_app
    response = self.full_dispatch_request()
               ^^^^^^^^^^^^^^^^^^^^^^^^^^^^
  File "/opt/homebrew/lib/python3.11/site-packages/flask/app.py", line 1825, in full_dispatch_request
    rv = self.handle_user_exception(e)
         ^^^^^^^^^^^^^^^^^^^^^^^^^^^^^
  File "/opt/homebrew/lib/python3.11/site-packages/flask/app.py", line 1823, in full_dispatch_request
    rv = self.dispatch_request()
         ^^^^^^^^^^^^^^^^^^^^^^^
  File "/opt/homebrew/lib/python3.11/site-packages/flask/app.py", line 1799, in dispatch_request
    return self.ensure_sync(self.view_functions[rule.endpoint])(**view_args)
           ^^^^^^^^^^^^^^^^^^^^^^^^^^^^^^^^^^^^^^^^^^^^^^^^^^^^^^^^^^^^^^^^^
  File "/Users/wbabich/PycharmProjects/plant_app/app.py", line 74, in search_plant
    return render_template('search_plant.html')
           ^^^^^^^^^^^^^^^^^^^^^^^^^^^^^^^^^^^^
  File "/opt/homebrew/lib/python3.11/site-packages/flask/templating.py", line 147, in render_template
    return _render(app, template, context)
           ^^^^^^^^^^^^^^^^^^^^^^^^^^^^^^^
  File "/opt/homebrew/lib/python3.11/site-packages/flask/templating.py", line 130, in _render
    rv = template.render(context)
         ^^^^^^^^^^^^^^^^^^^^^^^^
  File "/opt/homebrew/lib/python3.11/site-packages/jinja2/environment.py", line 1301, in render
    self.environment.handle_exception()
  File "/opt/homebrew/lib/python3.11/site-packages/jinja2/environment.py", line 936, in handle_exception
    raise rewrite_traceback_stack(source=source)
  File "/Users/wbabich/PycharmProjects/plant_app/templates/search_plant.html", line 1, in top-level template code
    {% extends 'base.html' %}
  File "/Users/wbabich/PycharmProjects/plant_app/templates/base.html", line 44, in top-level template code
    {% block content %}
  File "/Users/wbabich/PycharmProjects/plant_app/templates/search_plant.html", line 22, in block 'content'
    <p>Would you like to <a href="{{ url_for('add_plant') }}">add it to our database</a>?</p>
    ^^^^^^^^^^^^^^^^^^^^^^^^^
  File "/opt/homebrew/lib/python3.11/site-packages/flask/app.py", line 2034, in url_for
    return self.handle_url_build_error(error, endpoint, values)
           ^^^^^^^^^^^^^^^^^^^^^^^^^^^^^^^^^^^^^^^^^^^^^^^^^^^^
  File "/opt/homebrew/lib/python3.11/site-packages/flask/app.py", line 2023, in url_for
    rv = url_adapter.build(  # type: ignore[union-attr]
         ^^^^^^^^^^^^^^^^^^^^^^^^^^^^^^^^^^^^^^^^^^^^^^
  File "/opt/homebrew/lib/python3.11/site-packages/werkzeug/routing/map.py", line 917, in build
    raise BuildError(endpoint, values, method, self)
werkzeug.routing.exceptions.BuildError: Could not build url for endpoint 'add_plant'. Did you mean 'search_plant' instead?
2023-04-28 12:40:29,929 - app - ERROR - Exception on /search_plant [GET]
Traceback (most recent call last):
  File "/opt/homebrew/lib/python3.11/site-packages/flask/app.py", line 2528, in wsgi_app
    response = self.full_dispatch_request()
               ^^^^^^^^^^^^^^^^^^^^^^^^^^^^
  File "/opt/homebrew/lib/python3.11/site-packages/flask/app.py", line 1825, in full_dispatch_request
    rv = self.handle_user_exception(e)
         ^^^^^^^^^^^^^^^^^^^^^^^^^^^^^
  File "/opt/homebrew/lib/python3.11/site-packages/flask/app.py", line 1823, in full_dispatch_request
    rv = self.dispatch_request()
         ^^^^^^^^^^^^^^^^^^^^^^^
  File "/opt/homebrew/lib/python3.11/site-packages/flask/app.py", line 1799, in dispatch_request
    return self.ensure_sync(self.view_functions[rule.endpoint])(**view_args)
           ^^^^^^^^^^^^^^^^^^^^^^^^^^^^^^^^^^^^^^^^^^^^^^^^^^^^^^^^^^^^^^^^^
  File "/Users/wbabich/PycharmProjects/plant_app/app.py", line 71, in search_plant
    return render_template('plant_search_results.html', plant_info=plant_info)
           ^^^^^^^^^^^^^^^^^^^^^^^^^^^^^^^^^^^^^^^^^^^^^^^^^^^^^^^^^^^^^^^^^^^
  File "/opt/homebrew/lib/python3.11/site-packages/flask/templating.py", line 146, in render_template
    template = app.jinja_env.get_or_select_template(template_name_or_list)
               ^^^^^^^^^^^^^^^^^^^^^^^^^^^^^^^^^^^^^^^^^^^^^^^^^^^^^^^^^^^
  File "/opt/homebrew/lib/python3.11/site-packages/jinja2/environment.py", line 1081, in get_or_select_template
    return self.get_template(template_name_or_list, parent, globals)
           ^^^^^^^^^^^^^^^^^^^^^^^^^^^^^^^^^^^^^^^^^^^^^^^^^^^^^^^^^
  File "/opt/homebrew/lib/python3.11/site-packages/jinja2/environment.py", line 1010, in get_template
    return self._load_template(name, globals)
           ^^^^^^^^^^^^^^^^^^^^^^^^^^^^^^^^^^
  File "/opt/homebrew/lib/python3.11/site-packages/jinja2/environment.py", line 969, in _load_template
    template = self.loader.load(self, name, self.make_globals(globals))
               ^^^^^^^^^^^^^^^^^^^^^^^^^^^^^^^^^^^^^^^^^^^^^^^^^^^^^^^^
  File "/opt/homebrew/lib/python3.11/site-packages/jinja2/loaders.py", line 126, in load
    source, filename, uptodate = self.get_source(environment, name)
                                 ^^^^^^^^^^^^^^^^^^^^^^^^^^^^^^^^^^
  File "/opt/homebrew/lib/python3.11/site-packages/flask/templating.py", line 62, in get_source
    return self._get_source_fast(environment, template)
           ^^^^^^^^^^^^^^^^^^^^^^^^^^^^^^^^^^^^^^^^^^^^
  File "/opt/homebrew/lib/python3.11/site-packages/flask/templating.py", line 98, in _get_source_fast
    raise TemplateNotFound(template)
jinja2.exceptions.TemplateNotFound: plant_search_results.html
2023-04-28 12:41:28,452 - app - ERROR - Exception on /search_plant [GET]
Traceback (most recent call last):
  File "/opt/homebrew/lib/python3.11/site-packages/flask/app.py", line 2528, in wsgi_app
    response = self.full_dispatch_request()
               ^^^^^^^^^^^^^^^^^^^^^^^^^^^^
  File "/opt/homebrew/lib/python3.11/site-packages/flask/app.py", line 1825, in full_dispatch_request
    rv = self.handle_user_exception(e)
         ^^^^^^^^^^^^^^^^^^^^^^^^^^^^^
  File "/opt/homebrew/lib/python3.11/site-packages/flask/app.py", line 1823, in full_dispatch_request
    rv = self.dispatch_request()
         ^^^^^^^^^^^^^^^^^^^^^^^
  File "/opt/homebrew/lib/python3.11/site-packages/flask/app.py", line 1799, in dispatch_request
    return self.ensure_sync(self.view_functions[rule.endpoint])(**view_args)
           ^^^^^^^^^^^^^^^^^^^^^^^^^^^^^^^^^^^^^^^^^^^^^^^^^^^^^^^^^^^^^^^^^
  File "/Users/wbabich/PycharmProjects/plant_app/app.py", line 71, in search_plant
    return render_template('plant_info.html', plant_info=plant_info)
           ^^^^^^^^^^^^^^^^^^^^^^^^^^^^^^^^^^^^^^^^^^^^^^^^^^^^^^^^^
  File "/opt/homebrew/lib/python3.11/site-packages/flask/templating.py", line 147, in render_template
    return _render(app, template, context)
           ^^^^^^^^^^^^^^^^^^^^^^^^^^^^^^^
  File "/opt/homebrew/lib/python3.11/site-packages/flask/templating.py", line 130, in _render
    rv = template.render(context)
         ^^^^^^^^^^^^^^^^^^^^^^^^
  File "/opt/homebrew/lib/python3.11/site-packages/jinja2/environment.py", line 1301, in render
    self.environment.handle_exception()
  File "/opt/homebrew/lib/python3.11/site-packages/jinja2/environment.py", line 936, in handle_exception
    raise rewrite_traceback_stack(source=source)
  File "/Users/wbabich/PycharmProjects/plant_app/templates/plant_info.html", line 1, in top-level template code
    {% extends 'base.html' %}
  File "/Users/wbabich/PycharmProjects/plant_app/templates/base.html", line 44, in top-level template code
    {% block content %}
  File "/Users/wbabich/PycharmProjects/plant_app/templates/plant_info.html", line 22, in block 'content'
    <td>{{ plant.common_name if plant.common_name else "No data" }}</td>
    ^^^^^^^^^^^^^^^^^^^^^^^^^
  File "/opt/homebrew/lib/python3.11/site-packages/jinja2/environment.py", line 485, in getattr
    return getattr(obj, attribute)
           ^^^^^^^^^^^^^^^^^^^^^^^
jinja2.exceptions.UndefinedError: 'plant' is undefined
2023-04-28 14:36:59,167 - app - ERROR - Exception on /search_plant [GET]
Traceback (most recent call last):
  File "/opt/homebrew/lib/python3.11/site-packages/flask/app.py", line 2528, in wsgi_app
    response = self.full_dispatch_request()
               ^^^^^^^^^^^^^^^^^^^^^^^^^^^^
  File "/opt/homebrew/lib/python3.11/site-packages/flask/app.py", line 1825, in full_dispatch_request
    rv = self.handle_user_exception(e)
         ^^^^^^^^^^^^^^^^^^^^^^^^^^^^^
  File "/opt/homebrew/lib/python3.11/site-packages/flask/app.py", line 1823, in full_dispatch_request
    rv = self.dispatch_request()
         ^^^^^^^^^^^^^^^^^^^^^^^
  File "/opt/homebrew/lib/python3.11/site-packages/flask/app.py", line 1799, in dispatch_request
    return self.ensure_sync(self.view_functions[rule.endpoint])(**view_args)
           ^^^^^^^^^^^^^^^^^^^^^^^^^^^^^^^^^^^^^^^^^^^^^^^^^^^^^^^^^^^^^^^^^
  File "/Users/wbabich/PycharmProjects/plant_app/app.py", line 71, in search_plant
    return render_template('plant_info.html', plant_info=plant_info)
           ^^^^^^^^^^^^^^^^^^^^^^^^^^^^^^^^^^^^^^^^^^^^^^^^^^^^^^^^^
  File "/opt/homebrew/lib/python3.11/site-packages/flask/templating.py", line 147, in render_template
    return _render(app, template, context)
           ^^^^^^^^^^^^^^^^^^^^^^^^^^^^^^^
  File "/opt/homebrew/lib/python3.11/site-packages/flask/templating.py", line 130, in _render
    rv = template.render(context)
         ^^^^^^^^^^^^^^^^^^^^^^^^
  File "/opt/homebrew/lib/python3.11/site-packages/jinja2/environment.py", line 1301, in render
    self.environment.handle_exception()
  File "/opt/homebrew/lib/python3.11/site-packages/jinja2/environment.py", line 936, in handle_exception
    raise rewrite_traceback_stack(source=source)
  File "/Users/wbabich/PycharmProjects/plant_app/templates/plant_info.html", line 1, in top-level template code
    {% extends 'base.html' %}
  File "/Users/wbabich/PycharmProjects/plant_app/templates/base.html", line 44, in top-level template code
    {% block content %}
  File "/Users/wbabich/PycharmProjects/plant_app/templates/plant_info.html", line 22, in block 'content'
    <td>{{ plant.common_name if plant.common_name else "No data" }}</td>
    ^^^^^^^^^^^^^^^^^^^^^^^^^
  File "/opt/homebrew/lib/python3.11/site-packages/jinja2/environment.py", line 485, in getattr
    return getattr(obj, attribute)
           ^^^^^^^^^^^^^^^^^^^^^^^
jinja2.exceptions.UndefinedError: 'plant' is undefined
2023-04-28 14:40:13,640 - app - ERROR - Exception on /search_plant [GET]
Traceback (most recent call last):
  File "/opt/homebrew/lib/python3.11/site-packages/flask/app.py", line 2528, in wsgi_app
    response = self.full_dispatch_request()
               ^^^^^^^^^^^^^^^^^^^^^^^^^^^^
  File "/opt/homebrew/lib/python3.11/site-packages/flask/app.py", line 1825, in full_dispatch_request
    rv = self.handle_user_exception(e)
         ^^^^^^^^^^^^^^^^^^^^^^^^^^^^^
  File "/opt/homebrew/lib/python3.11/site-packages/flask/app.py", line 1823, in full_dispatch_request
    rv = self.dispatch_request()
         ^^^^^^^^^^^^^^^^^^^^^^^
  File "/opt/homebrew/lib/python3.11/site-packages/flask/app.py", line 1799, in dispatch_request
    return self.ensure_sync(self.view_functions[rule.endpoint])(**view_args)
           ^^^^^^^^^^^^^^^^^^^^^^^^^^^^^^^^^^^^^^^^^^^^^^^^^^^^^^^^^^^^^^^^^
  File "/Users/wbabich/PycharmProjects/plant_app/app.py", line 71, in search_plant
    return render_template('plant_info.html', plant_info=plant_info)
           ^^^^^^^^^^^^^^^^^^^^^^^^^^^^^^^^^^^^^^^^^^^^^^^^^^^^^^^^^
  File "/opt/homebrew/lib/python3.11/site-packages/flask/templating.py", line 147, in render_template
    return _render(app, template, context)
           ^^^^^^^^^^^^^^^^^^^^^^^^^^^^^^^
  File "/opt/homebrew/lib/python3.11/site-packages/flask/templating.py", line 130, in _render
    rv = template.render(context)
         ^^^^^^^^^^^^^^^^^^^^^^^^
  File "/opt/homebrew/lib/python3.11/site-packages/jinja2/environment.py", line 1301, in render
    self.environment.handle_exception()
  File "/opt/homebrew/lib/python3.11/site-packages/jinja2/environment.py", line 936, in handle_exception
    raise rewrite_traceback_stack(source=source)
  File "/Users/wbabich/PycharmProjects/plant_app/templates/plant_info.html", line 1, in top-level template code
    {% extends 'base.html' %}
  File "/Users/wbabich/PycharmProjects/plant_app/templates/base.html", line 44, in top-level template code
    {% block content %}
  File "/Users/wbabich/PycharmProjects/plant_app/templates/plant_info.html", line 22, in block 'content'
    <td>{{ plant.common_name if plant.common_name else "No data" }}</td>
    ^^^^^^^^^^^^^^^^^^^^^^^^^
  File "/opt/homebrew/lib/python3.11/site-packages/jinja2/environment.py", line 485, in getattr
    return getattr(obj, attribute)
           ^^^^^^^^^^^^^^^^^^^^^^^
jinja2.exceptions.UndefinedError: 'plant' is undefined
2023-04-28 14:41:30,408 - app - ERROR - Exception on /search_plant [GET]
Traceback (most recent call last):
  File "/opt/homebrew/lib/python3.11/site-packages/flask/app.py", line 2528, in wsgi_app
    response = self.full_dispatch_request()
               ^^^^^^^^^^^^^^^^^^^^^^^^^^^^
  File "/opt/homebrew/lib/python3.11/site-packages/flask/app.py", line 1825, in full_dispatch_request
    rv = self.handle_user_exception(e)
         ^^^^^^^^^^^^^^^^^^^^^^^^^^^^^
  File "/opt/homebrew/lib/python3.11/site-packages/flask/app.py", line 1823, in full_dispatch_request
    rv = self.dispatch_request()
         ^^^^^^^^^^^^^^^^^^^^^^^
  File "/opt/homebrew/lib/python3.11/site-packages/flask/app.py", line 1799, in dispatch_request
    return self.ensure_sync(self.view_functions[rule.endpoint])(**view_args)
           ^^^^^^^^^^^^^^^^^^^^^^^^^^^^^^^^^^^^^^^^^^^^^^^^^^^^^^^^^^^^^^^^^
  File "/Users/wbabich/PycharmProjects/plant_app/app.py", line 74, in search_plant
    return render_template('search_plant.html')
           ^^^^^^^^^^^^^^^^^^^^^^^^^^^^^^^^^^^^
  File "/opt/homebrew/lib/python3.11/site-packages/flask/templating.py", line 147, in render_template
    return _render(app, template, context)
           ^^^^^^^^^^^^^^^^^^^^^^^^^^^^^^^
  File "/opt/homebrew/lib/python3.11/site-packages/flask/templating.py", line 130, in _render
    rv = template.render(context)
         ^^^^^^^^^^^^^^^^^^^^^^^^
  File "/opt/homebrew/lib/python3.11/site-packages/jinja2/environment.py", line 1301, in render
    self.environment.handle_exception()
  File "/opt/homebrew/lib/python3.11/site-packages/jinja2/environment.py", line 936, in handle_exception
    raise rewrite_traceback_stack(source=source)
  File "/Users/wbabich/PycharmProjects/plant_app/templates/search_plant.html", line 1, in top-level template code
    {% extends 'base.html' %}
  File "/Users/wbabich/PycharmProjects/plant_app/templates/base.html", line 44, in top-level template code
    {% block content %}
  File "/Users/wbabich/PycharmProjects/plant_app/templates/search_plant.html", line 22, in block 'content'
    <p>Would you like to <a href="{{ url_for('add_plant') }}">add it to our database</a>?</p>
    ^^^^^^^^^^^^^^^^^^^^^^^^^
  File "/opt/homebrew/lib/python3.11/site-packages/flask/app.py", line 2034, in url_for
    return self.handle_url_build_error(error, endpoint, values)
           ^^^^^^^^^^^^^^^^^^^^^^^^^^^^^^^^^^^^^^^^^^^^^^^^^^^^
  File "/opt/homebrew/lib/python3.11/site-packages/flask/app.py", line 2023, in url_for
    rv = url_adapter.build(  # type: ignore[union-attr]
         ^^^^^^^^^^^^^^^^^^^^^^^^^^^^^^^^^^^^^^^^^^^^^^
  File "/opt/homebrew/lib/python3.11/site-packages/werkzeug/routing/map.py", line 917, in build
    raise BuildError(endpoint, values, method, self)
werkzeug.routing.exceptions.BuildError: Could not build url for endpoint 'add_plant'. Did you mean 'search_plant' instead?
2023-04-28 15:09:28,101 - app - ERROR - Exception on /search_plant [GET]
Traceback (most recent call last):
  File "/opt/homebrew/lib/python3.11/site-packages/flask/app.py", line 2528, in wsgi_app
    response = self.full_dispatch_request()
               ^^^^^^^^^^^^^^^^^^^^^^^^^^^^
  File "/opt/homebrew/lib/python3.11/site-packages/flask/app.py", line 1825, in full_dispatch_request
    rv = self.handle_user_exception(e)
         ^^^^^^^^^^^^^^^^^^^^^^^^^^^^^
  File "/opt/homebrew/lib/python3.11/site-packages/flask/app.py", line 1823, in full_dispatch_request
    rv = self.dispatch_request()
         ^^^^^^^^^^^^^^^^^^^^^^^
  File "/opt/homebrew/lib/python3.11/site-packages/flask/app.py", line 1799, in dispatch_request
    return self.ensure_sync(self.view_functions[rule.endpoint])(**view_args)
           ^^^^^^^^^^^^^^^^^^^^^^^^^^^^^^^^^^^^^^^^^^^^^^^^^^^^^^^^^^^^^^^^^
  File "/Users/wbabich/PycharmProjects/plant_app/app.py", line 63, in search_plant
    matching_plants = search_plants(query)
                      ^^^^^^^^^^^^^
NameError: name 'search_plants' is not defined
2023-04-28 15:14:05,319 - app - ERROR - Exception on /search_plant [GET]
Traceback (most recent call last):
  File "/opt/homebrew/lib/python3.11/site-packages/flask/app.py", line 2528, in wsgi_app
    response = self.full_dispatch_request()
               ^^^^^^^^^^^^^^^^^^^^^^^^^^^^
  File "/opt/homebrew/lib/python3.11/site-packages/flask/app.py", line 1825, in full_dispatch_request
    rv = self.handle_user_exception(e)
         ^^^^^^^^^^^^^^^^^^^^^^^^^^^^^
  File "/opt/homebrew/lib/python3.11/site-packages/flask/app.py", line 1823, in full_dispatch_request
    rv = self.dispatch_request()
         ^^^^^^^^^^^^^^^^^^^^^^^
  File "/opt/homebrew/lib/python3.11/site-packages/flask/app.py", line 1799, in dispatch_request
    return self.ensure_sync(self.view_functions[rule.endpoint])(**view_args)
           ^^^^^^^^^^^^^^^^^^^^^^^^^^^^^^^^^^^^^^^^^^^^^^^^^^^^^^^^^^^^^^^^^
  File "/Users/wbabich/PycharmProjects/plant_app/app.py", line 63, in search_plant
    matching_plants = search_plant(query)
                      ^^^^^^^^^^^^^^^^^^^
TypeError: search_plant() takes 0 positional arguments but 1 was given
2023-04-28 15:31:42,607 - app - ERROR - Exception on /search_plant [GET]
Traceback (most recent call last):
  File "/opt/homebrew/lib/python3.11/site-packages/flask/app.py", line 2528, in wsgi_app
    response = self.full_dispatch_request()
               ^^^^^^^^^^^^^^^^^^^^^^^^^^^^
  File "/opt/homebrew/lib/python3.11/site-packages/flask/app.py", line 1825, in full_dispatch_request
    rv = self.handle_user_exception(e)
         ^^^^^^^^^^^^^^^^^^^^^^^^^^^^^
  File "/opt/homebrew/lib/python3.11/site-packages/flask/app.py", line 1823, in full_dispatch_request
    rv = self.dispatch_request()
         ^^^^^^^^^^^^^^^^^^^^^^^
  File "/opt/homebrew/lib/python3.11/site-packages/flask/app.py", line 1799, in dispatch_request
    return self.ensure_sync(self.view_functions[rule.endpoint])(**view_args)
           ^^^^^^^^^^^^^^^^^^^^^^^^^^^^^^^^^^^^^^^^^^^^^^^^^^^^^^^^^^^^^^^^^
  File "/Users/wbabich/PycharmProjects/plant_app/app.py", line 63, in search_plant
    matching_plants = search_plant(query)
                      ^^^^^^^^^^^^^^^^^^^
TypeError: search_plant() takes 0 positional arguments but 1 was given
2023-04-28 15:33:14,062 - app - ERROR - Exception on /search_plant [GET]
Traceback (most recent call last):
  File "/opt/homebrew/lib/python3.11/site-packages/flask/app.py", line 2528, in wsgi_app
    response = self.full_dispatch_request()
               ^^^^^^^^^^^^^^^^^^^^^^^^^^^^
  File "/opt/homebrew/lib/python3.11/site-packages/flask/app.py", line 1825, in full_dispatch_request
    rv = self.handle_user_exception(e)
         ^^^^^^^^^^^^^^^^^^^^^^^^^^^^^
  File "/opt/homebrew/lib/python3.11/site-packages/flask/app.py", line 1823, in full_dispatch_request
    rv = self.dispatch_request()
         ^^^^^^^^^^^^^^^^^^^^^^^
  File "/opt/homebrew/lib/python3.11/site-packages/flask/app.py", line 1799, in dispatch_request
    return self.ensure_sync(self.view_functions[rule.endpoint])(**view_args)
           ^^^^^^^^^^^^^^^^^^^^^^^^^^^^^^^^^^^^^^^^^^^^^^^^^^^^^^^^^^^^^^^^^
  File "/Users/wbabich/PycharmProjects/plant_app/app.py", line 63, in search_plant
    matching_plants = search_plant(query)
                      ^^^^^^^^^^^^^^^^^^^
TypeError: search_plant() takes 0 positional arguments but 1 was given
2023-04-28 15:33:22,111 - app - ERROR - Exception on /search_plant [GET]
Traceback (most recent call last):
  File "/opt/homebrew/lib/python3.11/site-packages/flask/app.py", line 2528, in wsgi_app
    response = self.full_dispatch_request()
               ^^^^^^^^^^^^^^^^^^^^^^^^^^^^
  File "/opt/homebrew/lib/python3.11/site-packages/flask/app.py", line 1825, in full_dispatch_request
    rv = self.handle_user_exception(e)
         ^^^^^^^^^^^^^^^^^^^^^^^^^^^^^
  File "/opt/homebrew/lib/python3.11/site-packages/flask/app.py", line 1823, in full_dispatch_request
    rv = self.dispatch_request()
         ^^^^^^^^^^^^^^^^^^^^^^^
  File "/opt/homebrew/lib/python3.11/site-packages/flask/app.py", line 1799, in dispatch_request
    return self.ensure_sync(self.view_functions[rule.endpoint])(**view_args)
           ^^^^^^^^^^^^^^^^^^^^^^^^^^^^^^^^^^^^^^^^^^^^^^^^^^^^^^^^^^^^^^^^^
  File "/Users/wbabich/PycharmProjects/plant_app/app.py", line 63, in search_plant
    matching_plants = search_plant(query)
                      ^^^^^^^^^^^^^^^^^^^
TypeError: search_plant() takes 0 positional arguments but 1 was given
2023-04-28 15:38:00,893 - app - ERROR - Exception on /search [GET]
Traceback (most recent call last):
  File "/opt/homebrew/lib/python3.11/site-packages/flask/app.py", line 2528, in wsgi_app
    response = self.full_dispatch_request()
               ^^^^^^^^^^^^^^^^^^^^^^^^^^^^
  File "/opt/homebrew/lib/python3.11/site-packages/flask/app.py", line 1825, in full_dispatch_request
    rv = self.handle_user_exception(e)
         ^^^^^^^^^^^^^^^^^^^^^^^^^^^^^
  File "/opt/homebrew/lib/python3.11/site-packages/flask/app.py", line 1823, in full_dispatch_request
    rv = self.dispatch_request()
         ^^^^^^^^^^^^^^^^^^^^^^^
  File "/opt/homebrew/lib/python3.11/site-packages/flask/app.py", line 1799, in dispatch_request
    return self.ensure_sync(self.view_functions[rule.endpoint])(**view_args)
           ^^^^^^^^^^^^^^^^^^^^^^^^^^^^^^^^^^^^^^^^^^^^^^^^^^^^^^^^^^^^^^^^^
  File "/Users/wbabich/PycharmProjects/plant_app/app.py", line 63, in search_plant
    plants = db_session.query(Plant).filter(or_(Plant.common_name.ilike(f'%{query}%'), Plant.scientific_name.ilike(f'%{query}%'))).all()
             ^^^^^^^^^^
NameError: name 'db_session' is not defined
2023-04-28 15:53:43,883 - app - ERROR - Exception on /search [GET]
Traceback (most recent call last):
  File "/opt/homebrew/lib/python3.11/site-packages/flask/app.py", line 2528, in wsgi_app
    response = self.full_dispatch_request()
               ^^^^^^^^^^^^^^^^^^^^^^^^^^^^
  File "/opt/homebrew/lib/python3.11/site-packages/flask/app.py", line 1825, in full_dispatch_request
    rv = self.handle_user_exception(e)
         ^^^^^^^^^^^^^^^^^^^^^^^^^^^^^
  File "/opt/homebrew/lib/python3.11/site-packages/flask/app.py", line 1823, in full_dispatch_request
    rv = self.dispatch_request()
         ^^^^^^^^^^^^^^^^^^^^^^^
  File "/opt/homebrew/lib/python3.11/site-packages/flask/app.py", line 1799, in dispatch_request
    return self.ensure_sync(self.view_functions[rule.endpoint])(**view_args)
           ^^^^^^^^^^^^^^^^^^^^^^^^^^^^^^^^^^^^^^^^^^^^^^^^^^^^^^^^^^^^^^^^^
  File "/Users/wbabich/PycharmProjects/plant_app/app.py", line 75, in search_plant
    return render_template('plants_info.html', plants=plants, query=query)
           ^^^^^^^^^^^^^^^^^^^^^^^^^^^^^^^^^^^^^^^^^^^^^^^^^^^^^^^^^^^^^^^
  File "/opt/homebrew/lib/python3.11/site-packages/flask/templating.py", line 146, in render_template
    template = app.jinja_env.get_or_select_template(template_name_or_list)
               ^^^^^^^^^^^^^^^^^^^^^^^^^^^^^^^^^^^^^^^^^^^^^^^^^^^^^^^^^^^
  File "/opt/homebrew/lib/python3.11/site-packages/jinja2/environment.py", line 1081, in get_or_select_template
    return self.get_template(template_name_or_list, parent, globals)
           ^^^^^^^^^^^^^^^^^^^^^^^^^^^^^^^^^^^^^^^^^^^^^^^^^^^^^^^^^
  File "/opt/homebrew/lib/python3.11/site-packages/jinja2/environment.py", line 1010, in get_template
    return self._load_template(name, globals)
           ^^^^^^^^^^^^^^^^^^^^^^^^^^^^^^^^^^
  File "/opt/homebrew/lib/python3.11/site-packages/jinja2/environment.py", line 969, in _load_template
    template = self.loader.load(self, name, self.make_globals(globals))
               ^^^^^^^^^^^^^^^^^^^^^^^^^^^^^^^^^^^^^^^^^^^^^^^^^^^^^^^^
  File "/opt/homebrew/lib/python3.11/site-packages/jinja2/loaders.py", line 126, in load
    source, filename, uptodate = self.get_source(environment, name)
                                 ^^^^^^^^^^^^^^^^^^^^^^^^^^^^^^^^^^
  File "/opt/homebrew/lib/python3.11/site-packages/flask/templating.py", line 62, in get_source
    return self._get_source_fast(environment, template)
           ^^^^^^^^^^^^^^^^^^^^^^^^^^^^^^^^^^^^^^^^^^^^
  File "/opt/homebrew/lib/python3.11/site-packages/flask/templating.py", line 98, in _get_source_fast
    raise TemplateNotFound(template)
jinja2.exceptions.TemplateNotFound: plants_info.html
2023-04-28 15:56:35,327 - app - ERROR - Exception on /search [GET]
Traceback (most recent call last):
  File "/opt/homebrew/lib/python3.11/site-packages/flask/app.py", line 2528, in wsgi_app
    response = self.full_dispatch_request()
               ^^^^^^^^^^^^^^^^^^^^^^^^^^^^
  File "/opt/homebrew/lib/python3.11/site-packages/flask/app.py", line 1825, in full_dispatch_request
    rv = self.handle_user_exception(e)
         ^^^^^^^^^^^^^^^^^^^^^^^^^^^^^
  File "/opt/homebrew/lib/python3.11/site-packages/flask/app.py", line 1823, in full_dispatch_request
    rv = self.dispatch_request()
         ^^^^^^^^^^^^^^^^^^^^^^^
  File "/opt/homebrew/lib/python3.11/site-packages/flask/app.py", line 1799, in dispatch_request
    return self.ensure_sync(self.view_functions[rule.endpoint])(**view_args)
           ^^^^^^^^^^^^^^^^^^^^^^^^^^^^^^^^^^^^^^^^^^^^^^^^^^^^^^^^^^^^^^^^^
  File "/Users/wbabich/PycharmProjects/plant_app/app.py", line 75, in search_plant
    return render_template('plant_info.html', plants=plants, query=query)
           ^^^^^^^^^^^^^^^^^^^^^^^^^^^^^^^^^^^^^^^^^^^^^^^^^^^^^^^^^^^^^^
  File "/opt/homebrew/lib/python3.11/site-packages/flask/templating.py", line 147, in render_template
    return _render(app, template, context)
           ^^^^^^^^^^^^^^^^^^^^^^^^^^^^^^^
  File "/opt/homebrew/lib/python3.11/site-packages/flask/templating.py", line 130, in _render
    rv = template.render(context)
         ^^^^^^^^^^^^^^^^^^^^^^^^
  File "/opt/homebrew/lib/python3.11/site-packages/jinja2/environment.py", line 1301, in render
    self.environment.handle_exception()
  File "/opt/homebrew/lib/python3.11/site-packages/jinja2/environment.py", line 936, in handle_exception
    raise rewrite_traceback_stack(source=source)
  File "/Users/wbabich/PycharmProjects/plant_app/templates/plant_info.html", line 1, in top-level template code
    {% extends 'base.html' %}
  File "/Users/wbabich/PycharmProjects/plant_app/templates/base.html", line 43, in top-level template code
    {% block content %}
  File "/Users/wbabich/PycharmProjects/plant_app/templates/plant_info.html", line 22, in block 'content'
    <td>{{ plant_info.common_name if plant_info.common_name else "No data" }}</td>
    ^^^^^^^^^^^^^^^^^^^^^^^^^
  File "/opt/homebrew/lib/python3.11/site-packages/jinja2/environment.py", line 485, in getattr
    return getattr(obj, attribute)
           ^^^^^^^^^^^^^^^^^^^^^^^
jinja2.exceptions.UndefinedError: 'plant_info' is undefined
2023-04-28 15:59:34,376 - app - ERROR - Exception on /search [GET]
Traceback (most recent call last):
  File "/opt/homebrew/lib/python3.11/site-packages/flask/app.py", line 2528, in wsgi_app
    response = self.full_dispatch_request()
               ^^^^^^^^^^^^^^^^^^^^^^^^^^^^
  File "/opt/homebrew/lib/python3.11/site-packages/flask/app.py", line 1825, in full_dispatch_request
    rv = self.handle_user_exception(e)
         ^^^^^^^^^^^^^^^^^^^^^^^^^^^^^
  File "/opt/homebrew/lib/python3.11/site-packages/flask/app.py", line 1823, in full_dispatch_request
    rv = self.dispatch_request()
         ^^^^^^^^^^^^^^^^^^^^^^^
  File "/opt/homebrew/lib/python3.11/site-packages/flask/app.py", line 1799, in dispatch_request
    return self.ensure_sync(self.view_functions[rule.endpoint])(**view_args)
           ^^^^^^^^^^^^^^^^^^^^^^^^^^^^^^^^^^^^^^^^^^^^^^^^^^^^^^^^^^^^^^^^^
  File "/Users/wbabich/PycharmProjects/plant_app/app.py", line 75, in search_plant
    return render_template('plant_info.html', plants=plant_info, query=query)
                                                     ^^^^^^^^^^
NameError: name 'plant_info' is not defined
2023-04-28 16:26:37,386 - app - ERROR - Exception on /search [POST]
Traceback (most recent call last):
  File "/opt/homebrew/lib/python3.11/site-packages/flask/app.py", line 2528, in wsgi_app
    response = self.full_dispatch_request()
               ^^^^^^^^^^^^^^^^^^^^^^^^^^^^
  File "/opt/homebrew/lib/python3.11/site-packages/flask/app.py", line 1825, in full_dispatch_request
    rv = self.handle_user_exception(e)
         ^^^^^^^^^^^^^^^^^^^^^^^^^^^^^
  File "/opt/homebrew/lib/python3.11/site-packages/flask/app.py", line 1823, in full_dispatch_request
    rv = self.dispatch_request()
         ^^^^^^^^^^^^^^^^^^^^^^^
  File "/opt/homebrew/lib/python3.11/site-packages/flask/app.py", line 1799, in dispatch_request
    return self.ensure_sync(self.view_functions[rule.endpoint])(**view_args)
           ^^^^^^^^^^^^^^^^^^^^^^^^^^^^^^^^^^^^^^^^^^^^^^^^^^^^^^^^^^^^^^^^^
  File "/Users/wbabich/PycharmProjects/plant_app/app.py", line 81, in search_plant
    return redirect(url_for('plant_info', id=plant.id))
                    ^^^^^^^^^^^^^^^^^^^^^^^^^^^^^^^^^^
  File "/opt/homebrew/lib/python3.11/site-packages/flask/helpers.py", line 256, in url_for
    return current_app.url_for(
           ^^^^^^^^^^^^^^^^^^^^
  File "/opt/homebrew/lib/python3.11/site-packages/flask/app.py", line 2034, in url_for
    return self.handle_url_build_error(error, endpoint, values)
           ^^^^^^^^^^^^^^^^^^^^^^^^^^^^^^^^^^^^^^^^^^^^^^^^^^^^
  File "/opt/homebrew/lib/python3.11/site-packages/flask/app.py", line 2023, in url_for
    rv = url_adapter.build(  # type: ignore[union-attr]
         ^^^^^^^^^^^^^^^^^^^^^^^^^^^^^^^^^^^^^^^^^^^^^^
  File "/opt/homebrew/lib/python3.11/site-packages/werkzeug/routing/map.py", line 917, in build
    raise BuildError(endpoint, values, method, self)
werkzeug.routing.exceptions.BuildError: Could not build url for endpoint 'plant_info' with values ['id']. Did you mean 'plant_information' instead?
2023-04-28 16:28:44,608 - app - ERROR - Exception on /add_plant [GET]
Traceback (most recent call last):
  File "/opt/homebrew/lib/python3.11/site-packages/flask/app.py", line 2528, in wsgi_app
    response = self.full_dispatch_request()
               ^^^^^^^^^^^^^^^^^^^^^^^^^^^^
  File "/opt/homebrew/lib/python3.11/site-packages/flask/app.py", line 1825, in full_dispatch_request
    rv = self.handle_user_exception(e)
         ^^^^^^^^^^^^^^^^^^^^^^^^^^^^^
  File "/opt/homebrew/lib/python3.11/site-packages/flask/app.py", line 1823, in full_dispatch_request
    rv = self.dispatch_request()
         ^^^^^^^^^^^^^^^^^^^^^^^
  File "/opt/homebrew/lib/python3.11/site-packages/flask/app.py", line 1799, in dispatch_request
    return self.ensure_sync(self.view_functions[rule.endpoint])(**view_args)
           ^^^^^^^^^^^^^^^^^^^^^^^^^^^^^^^^^^^^^^^^^^^^^^^^^^^^^^^^^^^^^^^^^
  File "/Users/wbabich/PycharmProjects/plant_app/app.py", line 101, in add_plant
    plant_info = get_plant_info()
                 ^^^^^^^^^^^^^^^^
TypeError: get_plant_info() missing 1 required positional argument: 'plant_name'
2023-04-28 16:56:38,340 - app - ERROR - Exception on /add_plant [GET]
Traceback (most recent call last):
  File "/opt/homebrew/lib/python3.11/site-packages/flask/app.py", line 2528, in wsgi_app
    response = self.full_dispatch_request()
               ^^^^^^^^^^^^^^^^^^^^^^^^^^^^
  File "/opt/homebrew/lib/python3.11/site-packages/flask/app.py", line 1825, in full_dispatch_request
    rv = self.handle_user_exception(e)
         ^^^^^^^^^^^^^^^^^^^^^^^^^^^^^
  File "/opt/homebrew/lib/python3.11/site-packages/flask/app.py", line 1823, in full_dispatch_request
    rv = self.dispatch_request()
         ^^^^^^^^^^^^^^^^^^^^^^^
  File "/opt/homebrew/lib/python3.11/site-packages/flask/app.py", line 1799, in dispatch_request
    return self.ensure_sync(self.view_functions[rule.endpoint])(**view_args)
           ^^^^^^^^^^^^^^^^^^^^^^^^^^^^^^^^^^^^^^^^^^^^^^^^^^^^^^^^^^^^^^^^^
  File "/Users/wbabich/PycharmProjects/plant_app/app.py", line 108, in add_plant
    return render_template('search_plant.html')
           ^^^^^^^^^^^^^^^^^^^^^^^^^^^^^^^^^^^^
  File "/opt/homebrew/lib/python3.11/site-packages/flask/templating.py", line 147, in render_template
    return _render(app, template, context)
           ^^^^^^^^^^^^^^^^^^^^^^^^^^^^^^^
  File "/opt/homebrew/lib/python3.11/site-packages/flask/templating.py", line 130, in _render
    rv = template.render(context)
         ^^^^^^^^^^^^^^^^^^^^^^^^
  File "/opt/homebrew/lib/python3.11/site-packages/jinja2/environment.py", line 1301, in render
    self.environment.handle_exception()
  File "/opt/homebrew/lib/python3.11/site-packages/jinja2/environment.py", line 936, in handle_exception
    raise rewrite_traceback_stack(source=source)
  File "/Users/wbabich/PycharmProjects/plant_app/templates/search_plant.html", line 1, in top-level template code
    {% extends 'base.html' %}
  File "/Users/wbabich/PycharmProjects/plant_app/templates/base.html", line 43, in top-level template code
    {% block content %}
  File "/Users/wbabich/PycharmProjects/plant_app/templates/search_plant.html", line 11, in block 'content'
    <form method="GET" action="{{ url_for('search_results') }}">
    ^^^^^^^^^^^^^^^^^^^^^^^^^
  File "/opt/homebrew/lib/python3.11/site-packages/flask/app.py", line 2034, in url_for
    return self.handle_url_build_error(error, endpoint, values)
           ^^^^^^^^^^^^^^^^^^^^^^^^^^^^^^^^^^^^^^^^^^^^^^^^^^^^
  File "/opt/homebrew/lib/python3.11/site-packages/flask/app.py", line 2023, in url_for
    rv = url_adapter.build(  # type: ignore[union-attr]
         ^^^^^^^^^^^^^^^^^^^^^^^^^^^^^^^^^^^^^^^^^^^^^^
  File "/opt/homebrew/lib/python3.11/site-packages/werkzeug/routing/map.py", line 917, in build
    raise BuildError(endpoint, values, method, self)
werkzeug.routing.exceptions.BuildError: Could not build url for endpoint 'search_results'. Did you mean 'search_plant' instead?
2023-04-28 17:12:30,620 - app - ERROR - Exception on /search_plant [POST]
Traceback (most recent call last):
  File "/opt/homebrew/lib/python3.11/site-packages/sqlalchemy/sql/base.py", line 2120, in _entity_namespace_key
    return getattr(ns, key)  # type: ignore
           ^^^^^^^^^^^^^^^^
AttributeError: type object 'Plant' has no attribute 'name'

The above exception was the direct cause of the following exception:

Traceback (most recent call last):
  File "/opt/homebrew/lib/python3.11/site-packages/flask/app.py", line 2528, in wsgi_app
    response = self.full_dispatch_request()
               ^^^^^^^^^^^^^^^^^^^^^^^^^^^^
  File "/opt/homebrew/lib/python3.11/site-packages/flask/app.py", line 1825, in full_dispatch_request
    rv = self.handle_user_exception(e)
         ^^^^^^^^^^^^^^^^^^^^^^^^^^^^^
  File "/opt/homebrew/lib/python3.11/site-packages/flask/app.py", line 1823, in full_dispatch_request
    rv = self.dispatch_request()
         ^^^^^^^^^^^^^^^^^^^^^^^
  File "/opt/homebrew/lib/python3.11/site-packages/flask/app.py", line 1799, in dispatch_request
    return self.ensure_sync(self.view_functions[rule.endpoint])(**view_args)
           ^^^^^^^^^^^^^^^^^^^^^^^^^^^^^^^^^^^^^^^^^^^^^^^^^^^^^^^^^^^^^^^^^
  File "/Users/wbabich/PycharmProjects/plant_app/app.py", line 74, in search_plant
    plant = Plant.query.filter_by(name=name).first()
            ^^^^^^^^^^^^^^^^^^^^^^^^^^^^^^^^
  File "/opt/homebrew/lib/python3.11/site-packages/sqlalchemy/orm/query.py", line 1998, in filter_by
    clauses = [
              ^
  File "/opt/homebrew/lib/python3.11/site-packages/sqlalchemy/orm/query.py", line 1999, in <listcomp>
    _entity_namespace_key(from_entity, key) == value
    ^^^^^^^^^^^^^^^^^^^^^^^^^^^^^^^^^^^^^^^
  File "/opt/homebrew/lib/python3.11/site-packages/sqlalchemy/sql/base.py", line 2122, in _entity_namespace_key
    raise exc.InvalidRequestError(
sqlalchemy.exc.InvalidRequestError: Entity namespace for "plants" has no property "name"
2023-04-28 17:25:06,414 - app - ERROR - Exception on /add_plant [GET]
Traceback (most recent call last):
  File "/opt/homebrew/lib/python3.11/site-packages/flask/app.py", line 2528, in wsgi_app
    response = self.full_dispatch_request()
               ^^^^^^^^^^^^^^^^^^^^^^^^^^^^
  File "/opt/homebrew/lib/python3.11/site-packages/flask/app.py", line 1825, in full_dispatch_request
    rv = self.handle_user_exception(e)
         ^^^^^^^^^^^^^^^^^^^^^^^^^^^^^
  File "/opt/homebrew/lib/python3.11/site-packages/flask/app.py", line 1823, in full_dispatch_request
    rv = self.dispatch_request()
         ^^^^^^^^^^^^^^^^^^^^^^^
  File "/opt/homebrew/lib/python3.11/site-packages/flask/app.py", line 1799, in dispatch_request
    return self.ensure_sync(self.view_functions[rule.endpoint])(**view_args)
           ^^^^^^^^^^^^^^^^^^^^^^^^^^^^^^^^^^^^^^^^^^^^^^^^^^^^^^^^^^^^^^^^^
  File "/Users/wbabich/PycharmProjects/plant_app/app.py", line 116, in add_plant
    return render_template('add_plant.html')
           ^^^^^^^^^^^^^^^^^^^^^^^^^^^^^^^^^
  File "/opt/homebrew/lib/python3.11/site-packages/flask/templating.py", line 147, in render_template
    return _render(app, template, context)
           ^^^^^^^^^^^^^^^^^^^^^^^^^^^^^^^
  File "/opt/homebrew/lib/python3.11/site-packages/flask/templating.py", line 130, in _render
    rv = template.render(context)
         ^^^^^^^^^^^^^^^^^^^^^^^^
  File "/opt/homebrew/lib/python3.11/site-packages/jinja2/environment.py", line 1301, in render
    self.environment.handle_exception()
  File "/opt/homebrew/lib/python3.11/site-packages/jinja2/environment.py", line 936, in handle_exception
    raise rewrite_traceback_stack(source=source)
  File "/Users/wbabich/PycharmProjects/plant_app/templates/add_plant.html", line 1, in top-level template code
    {% extends 'base.html' %}
  File "/Users/wbabich/PycharmProjects/plant_app/templates/base.html", line 43, in top-level template code
    {% block content %}
  File "/Users/wbabich/PycharmProjects/plant_app/templates/add_plant.html", line 13, in block 'content'
    {{ csrf_field() }}
  File "/opt/homebrew/lib/python3.11/site-packages/jinja2/utils.py", line 83, in from_obj
    if hasattr(obj, "jinja_pass_arg"):
       ^^^^^^^^^^^^^^^^^^^^^^^^^^^^^^
jinja2.exceptions.UndefinedError: 'csrf_field' is undefined
2023-04-28 17:26:59,694 - app - ERROR - Exception on /add_plant [GET]
Traceback (most recent call last):
  File "/opt/homebrew/lib/python3.11/site-packages/flask/app.py", line 2528, in wsgi_app
    response = self.full_dispatch_request()
               ^^^^^^^^^^^^^^^^^^^^^^^^^^^^
  File "/opt/homebrew/lib/python3.11/site-packages/flask/app.py", line 1825, in full_dispatch_request
    rv = self.handle_user_exception(e)
         ^^^^^^^^^^^^^^^^^^^^^^^^^^^^^
  File "/opt/homebrew/lib/python3.11/site-packages/flask/app.py", line 1823, in full_dispatch_request
    rv = self.dispatch_request()
         ^^^^^^^^^^^^^^^^^^^^^^^
  File "/opt/homebrew/lib/python3.11/site-packages/flask/app.py", line 1799, in dispatch_request
    return self.ensure_sync(self.view_functions[rule.endpoint])(**view_args)
           ^^^^^^^^^^^^^^^^^^^^^^^^^^^^^^^^^^^^^^^^^^^^^^^^^^^^^^^^^^^^^^^^^
  File "/Users/wbabich/PycharmProjects/plant_app/app.py", line 116, in add_plant
    return render_template('add_plant.html')
           ^^^^^^^^^^^^^^^^^^^^^^^^^^^^^^^^^
  File "/opt/homebrew/lib/python3.11/site-packages/flask/templating.py", line 147, in render_template
    return _render(app, template, context)
           ^^^^^^^^^^^^^^^^^^^^^^^^^^^^^^^
  File "/opt/homebrew/lib/python3.11/site-packages/flask/templating.py", line 130, in _render
    rv = template.render(context)
         ^^^^^^^^^^^^^^^^^^^^^^^^
  File "/opt/homebrew/lib/python3.11/site-packages/jinja2/environment.py", line 1301, in render
    self.environment.handle_exception()
  File "/opt/homebrew/lib/python3.11/site-packages/jinja2/environment.py", line 936, in handle_exception
    raise rewrite_traceback_stack(source=source)
  File "/Users/wbabich/PycharmProjects/plant_app/templates/add_plant.html", line 1, in top-level template code
    {% extends 'base.html' %}
  File "/Users/wbabich/PycharmProjects/plant_app/templates/base.html", line 43, in top-level template code
    {% block content %}
  File "/Users/wbabich/PycharmProjects/plant_app/templates/add_plant.html", line 13, in block 'content'
    {{ csrf_field() }}
  File "/opt/homebrew/lib/python3.11/site-packages/jinja2/utils.py", line 83, in from_obj
    if hasattr(obj, "jinja_pass_arg"):
       ^^^^^^^^^^^^^^^^^^^^^^^^^^^^^^
jinja2.exceptions.UndefinedError: 'csrf_field' is undefined
2023-04-28 17:29:14,015 - app - ERROR - Exception on /add_plant [GET]
Traceback (most recent call last):
  File "/opt/homebrew/lib/python3.11/site-packages/flask/app.py", line 2528, in wsgi_app
    response = self.full_dispatch_request()
               ^^^^^^^^^^^^^^^^^^^^^^^^^^^^
  File "/opt/homebrew/lib/python3.11/site-packages/flask/app.py", line 1825, in full_dispatch_request
    rv = self.handle_user_exception(e)
         ^^^^^^^^^^^^^^^^^^^^^^^^^^^^^
  File "/opt/homebrew/lib/python3.11/site-packages/flask/app.py", line 1823, in full_dispatch_request
    rv = self.dispatch_request()
         ^^^^^^^^^^^^^^^^^^^^^^^
  File "/opt/homebrew/lib/python3.11/site-packages/flask/app.py", line 1799, in dispatch_request
    return self.ensure_sync(self.view_functions[rule.endpoint])(**view_args)
           ^^^^^^^^^^^^^^^^^^^^^^^^^^^^^^^^^^^^^^^^^^^^^^^^^^^^^^^^^^^^^^^^^
  File "/Users/wbabich/PycharmProjects/plant_app/app.py", line 116, in add_plant
    return render_template('add_plant.html')
           ^^^^^^^^^^^^^^^^^^^^^^^^^^^^^^^^^
  File "/opt/homebrew/lib/python3.11/site-packages/flask/templating.py", line 147, in render_template
    return _render(app, template, context)
           ^^^^^^^^^^^^^^^^^^^^^^^^^^^^^^^
  File "/opt/homebrew/lib/python3.11/site-packages/flask/templating.py", line 130, in _render
    rv = template.render(context)
         ^^^^^^^^^^^^^^^^^^^^^^^^
  File "/opt/homebrew/lib/python3.11/site-packages/jinja2/environment.py", line 1301, in render
    self.environment.handle_exception()
  File "/opt/homebrew/lib/python3.11/site-packages/jinja2/environment.py", line 936, in handle_exception
    raise rewrite_traceback_stack(source=source)
  File "/Users/wbabich/PycharmProjects/plant_app/templates/add_plant.html", line 1, in top-level template code
    {% extends 'base.html' %}
  File "/Users/wbabich/PycharmProjects/plant_app/templates/base.html", line 43, in top-level template code
    {% block content %}
  File "/Users/wbabich/PycharmProjects/plant_app/templates/add_plant.html", line 13, in block 'content'
    {{ form.csrf_token }}
  File "/opt/homebrew/lib/python3.11/site-packages/jinja2/environment.py", line 485, in getattr
    return getattr(obj, attribute)
           ^^^^^^^^^^^^^^^^^^^^^^^
jinja2.exceptions.UndefinedError: 'form' is undefined
2023-04-28 17:30:49,479 - app - ERROR - Exception on /add_plant [GET]
Traceback (most recent call last):
  File "/opt/homebrew/lib/python3.11/site-packages/flask/app.py", line 2528, in wsgi_app
    response = self.full_dispatch_request()
               ^^^^^^^^^^^^^^^^^^^^^^^^^^^^
  File "/opt/homebrew/lib/python3.11/site-packages/flask/app.py", line 1825, in full_dispatch_request
    rv = self.handle_user_exception(e)
         ^^^^^^^^^^^^^^^^^^^^^^^^^^^^^
  File "/opt/homebrew/lib/python3.11/site-packages/flask/app.py", line 1823, in full_dispatch_request
    rv = self.dispatch_request()
         ^^^^^^^^^^^^^^^^^^^^^^^
  File "/opt/homebrew/lib/python3.11/site-packages/flask/app.py", line 1799, in dispatch_request
    return self.ensure_sync(self.view_functions[rule.endpoint])(**view_args)
           ^^^^^^^^^^^^^^^^^^^^^^^^^^^^^^^^^^^^^^^^^^^^^^^^^^^^^^^^^^^^^^^^^
  File "/Users/wbabich/PycharmProjects/plant_app/app.py", line 116, in add_plant
    form = AddPlantForm()
           ^^^^^^^^^^^^
NameError: name 'AddPlantForm' is not defined
2023-04-28 17:33:32,660 - app - ERROR - Exception on /search_results [POST]
Traceback (most recent call last):
  File "/opt/homebrew/lib/python3.11/site-packages/sqlalchemy/sql/base.py", line 2120, in _entity_namespace_key
    return getattr(ns, key)  # type: ignore
           ^^^^^^^^^^^^^^^^
AttributeError: type object 'Plant' has no attribute 'name'

The above exception was the direct cause of the following exception:

Traceback (most recent call last):
  File "/opt/homebrew/lib/python3.11/site-packages/flask/app.py", line 2528, in wsgi_app
    response = self.full_dispatch_request()
               ^^^^^^^^^^^^^^^^^^^^^^^^^^^^
  File "/opt/homebrew/lib/python3.11/site-packages/flask/app.py", line 1825, in full_dispatch_request
    rv = self.handle_user_exception(e)
         ^^^^^^^^^^^^^^^^^^^^^^^^^^^^^
  File "/opt/homebrew/lib/python3.11/site-packages/flask/app.py", line 1823, in full_dispatch_request
    rv = self.dispatch_request()
         ^^^^^^^^^^^^^^^^^^^^^^^
  File "/opt/homebrew/lib/python3.11/site-packages/flask/app.py", line 1799, in dispatch_request
    return self.ensure_sync(self.view_functions[rule.endpoint])(**view_args)
           ^^^^^^^^^^^^^^^^^^^^^^^^^^^^^^^^^^^^^^^^^^^^^^^^^^^^^^^^^^^^^^^^^
  File "/Users/wbabich/PycharmProjects/plant_app/app.py", line 95, in search_results
    plant = Plant.query.filter_by(name=name).first()
            ^^^^^^^^^^^^^^^^^^^^^^^^^^^^^^^^
  File "/opt/homebrew/lib/python3.11/site-packages/sqlalchemy/orm/query.py", line 1998, in filter_by
    clauses = [
              ^
  File "/opt/homebrew/lib/python3.11/site-packages/sqlalchemy/orm/query.py", line 1999, in <listcomp>
    _entity_namespace_key(from_entity, key) == value
    ^^^^^^^^^^^^^^^^^^^^^^^^^^^^^^^^^^^^^^^
  File "/opt/homebrew/lib/python3.11/site-packages/sqlalchemy/sql/base.py", line 2122, in _entity_namespace_key
    raise exc.InvalidRequestError(
sqlalchemy.exc.InvalidRequestError: Entity namespace for "plants" has no property "name"
2023-04-28 17:36:09,961 - app - ERROR - Exception on /add_plant [GET]
Traceback (most recent call last):
  File "/opt/homebrew/lib/python3.11/site-packages/flask/app.py", line 2528, in wsgi_app
    response = self.full_dispatch_request()
               ^^^^^^^^^^^^^^^^^^^^^^^^^^^^
  File "/opt/homebrew/lib/python3.11/site-packages/flask/app.py", line 1825, in full_dispatch_request
    rv = self.handle_user_exception(e)
         ^^^^^^^^^^^^^^^^^^^^^^^^^^^^^
  File "/opt/homebrew/lib/python3.11/site-packages/flask/app.py", line 1823, in full_dispatch_request
    rv = self.dispatch_request()
         ^^^^^^^^^^^^^^^^^^^^^^^
  File "/opt/homebrew/lib/python3.11/site-packages/flask/app.py", line 1799, in dispatch_request
    return self.ensure_sync(self.view_functions[rule.endpoint])(**view_args)
           ^^^^^^^^^^^^^^^^^^^^^^^^^^^^^^^^^^^^^^^^^^^^^^^^^^^^^^^^^^^^^^^^^
  File "/Users/wbabich/PycharmProjects/plant_app/app.py", line 120, in add_plant
    return render_template('add_plant.html', form=form)
           ^^^^^^^^^^^^^^^^^^^^^^^^^^^^^^^^^^^^^^^^^^^^
  File "/opt/homebrew/lib/python3.11/site-packages/flask/templating.py", line 147, in render_template
    return _render(app, template, context)
           ^^^^^^^^^^^^^^^^^^^^^^^^^^^^^^^
  File "/opt/homebrew/lib/python3.11/site-packages/flask/templating.py", line 130, in _render
    rv = template.render(context)
         ^^^^^^^^^^^^^^^^^^^^^^^^
  File "/opt/homebrew/lib/python3.11/site-packages/jinja2/environment.py", line 1301, in render
    self.environment.handle_exception()
  File "/opt/homebrew/lib/python3.11/site-packages/jinja2/environment.py", line 936, in handle_exception
    raise rewrite_traceback_stack(source=source)
  File "/Users/wbabich/PycharmProjects/plant_app/templates/add_plant.html", line 1, in top-level template code
    {% extends 'base.html' %}
  File "/Users/wbabich/PycharmProjects/plant_app/templates/base.html", line 43, in top-level template code
    {% block content %}
  File "/Users/wbabich/PycharmProjects/plant_app/templates/add_plant.html", line 16, in block 'content'
    {{ form.common_name(class="form-control", id="common_name") }}
    ^^^^^^^^^^^^^^^^^^^^^^^^^
  File "/opt/homebrew/lib/python3.11/site-packages/jinja2/utils.py", line 83, in from_obj
    if hasattr(obj, "jinja_pass_arg"):
       ^^^^^^^^^^^^^^^^^^^^^^^^^^^^^^
jinja2.exceptions.UndefinedError: 'forms.AddPlantForm object' has no attribute 'common_name'
2023-04-28 17:38:01,514 - app - ERROR - Exception on /add_plant [GET]
Traceback (most recent call last):
  File "/opt/homebrew/lib/python3.11/site-packages/flask/app.py", line 2528, in wsgi_app
    response = self.full_dispatch_request()
               ^^^^^^^^^^^^^^^^^^^^^^^^^^^^
  File "/opt/homebrew/lib/python3.11/site-packages/flask/app.py", line 1826, in full_dispatch_request
    return self.finalize_request(rv)
           ^^^^^^^^^^^^^^^^^^^^^^^^^
  File "/opt/homebrew/lib/python3.11/site-packages/flask/app.py", line 1845, in finalize_request
    response = self.make_response(rv)
               ^^^^^^^^^^^^^^^^^^^^^^
  File "/opt/homebrew/lib/python3.11/site-packages/flask/app.py", line 2137, in make_response
    raise TypeError(
TypeError: The view function for 'add_plant' did not return a valid response. The function either returned None or ended without a return statement.
2023-04-29 09:20:39,446 - app - ERROR - Exception on /add_plant [GET]
Traceback (most recent call last):
  File "/opt/homebrew/lib/python3.11/site-packages/flask/app.py", line 2528, in wsgi_app
    response = self.full_dispatch_request()
               ^^^^^^^^^^^^^^^^^^^^^^^^^^^^
  File "/opt/homebrew/lib/python3.11/site-packages/flask/app.py", line 1825, in full_dispatch_request
    rv = self.handle_user_exception(e)
         ^^^^^^^^^^^^^^^^^^^^^^^^^^^^^
  File "/opt/homebrew/lib/python3.11/site-packages/flask/app.py", line 1823, in full_dispatch_request
    rv = self.dispatch_request()
         ^^^^^^^^^^^^^^^^^^^^^^^
  File "/opt/homebrew/lib/python3.11/site-packages/flask/app.py", line 1799, in dispatch_request
    return self.ensure_sync(self.view_functions[rule.endpoint])(**view_args)
           ^^^^^^^^^^^^^^^^^^^^^^^^^^^^^^^^^^^^^^^^^^^^^^^^^^^^^^^^^^^^^^^^^
  File "/Users/wbabich/PycharmProjects/plant_app/app.py", line 123, in add_plant
    return render_template('add_plant.html')
           ^^^^^^^^^^^^^^^^^^^^^^^^^^^^^^^^^
  File "/opt/homebrew/lib/python3.11/site-packages/flask/templating.py", line 147, in render_template
    return _render(app, template, context)
           ^^^^^^^^^^^^^^^^^^^^^^^^^^^^^^^
  File "/opt/homebrew/lib/python3.11/site-packages/flask/templating.py", line 130, in _render
    rv = template.render(context)
         ^^^^^^^^^^^^^^^^^^^^^^^^
  File "/opt/homebrew/lib/python3.11/site-packages/jinja2/environment.py", line 1301, in render
    self.environment.handle_exception()
  File "/opt/homebrew/lib/python3.11/site-packages/jinja2/environment.py", line 936, in handle_exception
    raise rewrite_traceback_stack(source=source)
  File "/Users/wbabich/PycharmProjects/plant_app/templates/add_plant.html", line 1, in top-level template code
    {% extends 'base.html' %}
  File "/Users/wbabich/PycharmProjects/plant_app/templates/base.html", line 43, in top-level template code
    {% block content %}
  File "/Users/wbabich/PycharmProjects/plant_app/templates/add_plant.html", line 13, in block 'content'
    {{ form.hidden_tag() }}
  File "/opt/homebrew/lib/python3.11/site-packages/jinja2/environment.py", line 485, in getattr
    return getattr(obj, attribute)
           ^^^^^^^^^^^^^^^^^^^^^^^
jinja2.exceptions.UndefinedError: 'form' is undefined
2023-04-29 09:24:09,398 - app - ERROR - Exception on /add_plant [GET]
Traceback (most recent call last):
  File "/opt/homebrew/lib/python3.11/site-packages/flask/app.py", line 2528, in wsgi_app
    response = self.full_dispatch_request()
               ^^^^^^^^^^^^^^^^^^^^^^^^^^^^
  File "/opt/homebrew/lib/python3.11/site-packages/flask/app.py", line 1825, in full_dispatch_request
    rv = self.handle_user_exception(e)
         ^^^^^^^^^^^^^^^^^^^^^^^^^^^^^
  File "/opt/homebrew/lib/python3.11/site-packages/flask/app.py", line 1823, in full_dispatch_request
    rv = self.dispatch_request()
         ^^^^^^^^^^^^^^^^^^^^^^^
  File "/opt/homebrew/lib/python3.11/site-packages/flask/app.py", line 1799, in dispatch_request
    return self.ensure_sync(self.view_functions[rule.endpoint])(**view_args)
           ^^^^^^^^^^^^^^^^^^^^^^^^^^^^^^^^^^^^^^^^^^^^^^^^^^^^^^^^^^^^^^^^^
  File "/Users/wbabich/PycharmProjects/plant_app/app.py", line 124, in add_plant
    return render_template('add_plant.html', form=form)
           ^^^^^^^^^^^^^^^^^^^^^^^^^^^^^^^^^^^^^^^^^^^^
  File "/opt/homebrew/lib/python3.11/site-packages/flask/templating.py", line 147, in render_template
    return _render(app, template, context)
           ^^^^^^^^^^^^^^^^^^^^^^^^^^^^^^^
  File "/opt/homebrew/lib/python3.11/site-packages/flask/templating.py", line 130, in _render
    rv = template.render(context)
         ^^^^^^^^^^^^^^^^^^^^^^^^
  File "/opt/homebrew/lib/python3.11/site-packages/jinja2/environment.py", line 1301, in render
    self.environment.handle_exception()
  File "/opt/homebrew/lib/python3.11/site-packages/jinja2/environment.py", line 936, in handle_exception
    raise rewrite_traceback_stack(source=source)
  File "/Users/wbabich/PycharmProjects/plant_app/templates/add_plant.html", line 1, in top-level template code
    {% extends 'base.html' %}
  File "/Users/wbabich/PycharmProjects/plant_app/templates/base.html", line 43, in top-level template code
    {% block content %}
  File "/Users/wbabich/PycharmProjects/plant_app/templates/add_plant.html", line 18, in block 'content'
    {{ form.common_name(class="form-control", id="common_name") }}
    ^^^^^^^^^^^^^^^^^^^^^^^^^
  File "/opt/homebrew/lib/python3.11/site-packages/jinja2/utils.py", line 83, in from_obj
    if hasattr(obj, "jinja_pass_arg"):
       ^^^^^^^^^^^^^^^^^^^^^^^^^^^^^^
jinja2.exceptions.UndefinedError: 'forms.SearchForm object' has no attribute 'common_name'
2023-05-02 14:16:25,136 - app - ERROR - Exception on /search [GET]
Traceback (most recent call last):
  File "/opt/homebrew/lib/python3.11/site-packages/flask/app.py", line 2528, in wsgi_app
    response = self.full_dispatch_request()
               ^^^^^^^^^^^^^^^^^^^^^^^^^^^^
  File "/opt/homebrew/lib/python3.11/site-packages/flask/app.py", line 1825, in full_dispatch_request
    rv = self.handle_user_exception(e)
         ^^^^^^^^^^^^^^^^^^^^^^^^^^^^^
  File "/opt/homebrew/lib/python3.11/site-packages/flask/app.py", line 1823, in full_dispatch_request
    rv = self.dispatch_request()
         ^^^^^^^^^^^^^^^^^^^^^^^
  File "/opt/homebrew/lib/python3.11/site-packages/flask/app.py", line 1799, in dispatch_request
    return self.ensure_sync(self.view_functions[rule.endpoint])(**view_args)
           ^^^^^^^^^^^^^^^^^^^^^^^^^^^^^^^^^^^^^^^^^^^^^^^^^^^^^^^^^^^^^^^^^
  File "/Users/wbabich/PycharmProjects/plant_app/app.py", line 81, in search_plant
    plant_info = plant_info.get_plant_info(form.query.data.strip())
                 ^^^^^^^^^^
UnboundLocalError: cannot access local variable 'plant_info' where it is not associated with a value
2023-05-02 14:25:14,439 - app - ERROR - Exception on /search [POST]
Traceback (most recent call last):
  File "/opt/homebrew/lib/python3.11/site-packages/flask/app.py", line 2528, in wsgi_app
    response = self.full_dispatch_request()
               ^^^^^^^^^^^^^^^^^^^^^^^^^^^^
  File "/opt/homebrew/lib/python3.11/site-packages/flask/app.py", line 1825, in full_dispatch_request
    rv = self.handle_user_exception(e)
         ^^^^^^^^^^^^^^^^^^^^^^^^^^^^^
  File "/opt/homebrew/lib/python3.11/site-packages/flask/app.py", line 1823, in full_dispatch_request
    rv = self.dispatch_request()
         ^^^^^^^^^^^^^^^^^^^^^^^
  File "/opt/homebrew/lib/python3.11/site-packages/flask/app.py", line 1799, in dispatch_request
    return self.ensure_sync(self.view_functions[rule.endpoint])(**view_args)
           ^^^^^^^^^^^^^^^^^^^^^^^^^^^^^^^^^^^^^^^^^^^^^^^^^^^^^^^^^^^^^^^^^
  File "/Users/wbabich/PycharmProjects/plant_app/app.py", line 84, in search_plant
    plant_info = plant_info.get_plant_info(query.strip())
                 ^^^^^^^^^^
UnboundLocalError: cannot access local variable 'plant_info' where it is not associated with a value
2023-05-02 14:28:29,925 - app - ERROR - Exception on /search [POST]
Traceback (most recent call last):
  File "/opt/homebrew/lib/python3.11/site-packages/flask/app.py", line 2528, in wsgi_app
    response = self.full_dispatch_request()
               ^^^^^^^^^^^^^^^^^^^^^^^^^^^^
  File "/opt/homebrew/lib/python3.11/site-packages/flask/app.py", line 1825, in full_dispatch_request
    rv = self.handle_user_exception(e)
         ^^^^^^^^^^^^^^^^^^^^^^^^^^^^^
  File "/opt/homebrew/lib/python3.11/site-packages/flask/app.py", line 1823, in full_dispatch_request
    rv = self.dispatch_request()
         ^^^^^^^^^^^^^^^^^^^^^^^
  File "/opt/homebrew/lib/python3.11/site-packages/flask/app.py", line 1799, in dispatch_request
    return self.ensure_sync(self.view_functions[rule.endpoint])(**view_args)
           ^^^^^^^^^^^^^^^^^^^^^^^^^^^^^^^^^^^^^^^^^^^^^^^^^^^^^^^^^^^^^^^^^
  File "/Users/wbabich/PycharmProjects/plant_app/app.py", line 84, in search_plant
    fetched_plant_info = plant_info.get_plant_info(query.strip())
                         ^^^^^^^^^^
NameError: name 'plant_info' is not defined
2023-05-02 14:34:43,259 - app - ERROR - Exception on /add_to_database [POST]
Traceback (most recent call last):
  File "/opt/homebrew/lib/python3.11/site-packages/sqlalchemy/engine/base.py", line 1808, in _execute_context
    context = constructor(
              ^^^^^^^^^^^^
  File "/opt/homebrew/lib/python3.11/site-packages/sqlalchemy/engine/default.py", line 1294, in _init_compiled
    d_param = {
              ^
  File "/opt/homebrew/lib/python3.11/site-packages/sqlalchemy/engine/default.py", line 1295, in <dictcomp>
    key: flattened_processors[key](compiled_params[key])
         ^^^^^^^^^^^^^^^^^^^^^^^^^^^^^^^^^^^^^^^^^^^^^^^
  File "/opt/homebrew/lib/python3.11/site-packages/sqlalchemy/sql/sqltypes.py", line 2014, in process
    value = _strict_as_bool(value)
            ^^^^^^^^^^^^^^^^^^^^^^
  File "/opt/homebrew/lib/python3.11/site-packages/sqlalchemy/sql/sqltypes.py", line 1986, in _strict_as_bool
    raise TypeError("Not a boolean value: %r" % (value,))
TypeError: Not a boolean value: ''

The above exception was the direct cause of the following exception:

Traceback (most recent call last):
  File "/opt/homebrew/lib/python3.11/site-packages/flask/app.py", line 2528, in wsgi_app
    response = self.full_dispatch_request()
               ^^^^^^^^^^^^^^^^^^^^^^^^^^^^
  File "/opt/homebrew/lib/python3.11/site-packages/flask/app.py", line 1825, in full_dispatch_request
    rv = self.handle_user_exception(e)
         ^^^^^^^^^^^^^^^^^^^^^^^^^^^^^
  File "/opt/homebrew/lib/python3.11/site-packages/flask/app.py", line 1823, in full_dispatch_request
    rv = self.dispatch_request()
         ^^^^^^^^^^^^^^^^^^^^^^^
  File "/opt/homebrew/lib/python3.11/site-packages/flask/app.py", line 1799, in dispatch_request
    return self.ensure_sync(self.view_functions[rule.endpoint])(**view_args)
           ^^^^^^^^^^^^^^^^^^^^^^^^^^^^^^^^^^^^^^^^^^^^^^^^^^^^^^^^^^^^^^^^^
  File "/Users/wbabich/PycharmProjects/plant_app/app.py", line 193, in add_to_database
    db_session.commit()
  File "/opt/homebrew/lib/python3.11/site-packages/sqlalchemy/orm/scoping.py", line 553, in commit
    return self._proxied.commit()
           ^^^^^^^^^^^^^^^^^^^^^^
  File "/opt/homebrew/lib/python3.11/site-packages/sqlalchemy/orm/session.py", line 1903, in commit
    trans.commit(_to_root=True)
  File "<string>", line 2, in commit
  File "/opt/homebrew/lib/python3.11/site-packages/sqlalchemy/orm/state_changes.py", line 137, in _go
    ret_value = fn(self, *arg, **kw)
                ^^^^^^^^^^^^^^^^^^^^
  File "/opt/homebrew/lib/python3.11/site-packages/sqlalchemy/orm/session.py", line 1218, in commit
    self._prepare_impl()
  File "<string>", line 2, in _prepare_impl
  File "/opt/homebrew/lib/python3.11/site-packages/sqlalchemy/orm/state_changes.py", line 137, in _go
    ret_value = fn(self, *arg, **kw)
                ^^^^^^^^^^^^^^^^^^^^
  File "/opt/homebrew/lib/python3.11/site-packages/sqlalchemy/orm/session.py", line 1193, in _prepare_impl
    self.session.flush()
  File "/opt/homebrew/lib/python3.11/site-packages/sqlalchemy/orm/session.py", line 4155, in flush
    self._flush(objects)
  File "/opt/homebrew/lib/python3.11/site-packages/sqlalchemy/orm/session.py", line 4291, in _flush
    with util.safe_reraise():
  File "/opt/homebrew/lib/python3.11/site-packages/sqlalchemy/util/langhelpers.py", line 147, in __exit__
    raise exc_value.with_traceback(exc_tb)
  File "/opt/homebrew/lib/python3.11/site-packages/sqlalchemy/orm/session.py", line 4252, in _flush
    flush_context.execute()
  File "/opt/homebrew/lib/python3.11/site-packages/sqlalchemy/orm/unitofwork.py", line 467, in execute
    rec.execute(self)
  File "/opt/homebrew/lib/python3.11/site-packages/sqlalchemy/orm/unitofwork.py", line 644, in execute
    util.preloaded.orm_persistence.save_obj(
  File "/opt/homebrew/lib/python3.11/site-packages/sqlalchemy/orm/persistence.py", line 93, in save_obj
    _emit_insert_statements(
  File "/opt/homebrew/lib/python3.11/site-packages/sqlalchemy/orm/persistence.py", line 1184, in _emit_insert_statements
    result = connection.execute(
             ^^^^^^^^^^^^^^^^^^^
  File "/opt/homebrew/lib/python3.11/site-packages/sqlalchemy/engine/base.py", line 1414, in execute
    return meth(
           ^^^^^
  File "/opt/homebrew/lib/python3.11/site-packages/sqlalchemy/sql/elements.py", line 486, in _execute_on_connection
    return connection._execute_clauseelement(
           ^^^^^^^^^^^^^^^^^^^^^^^^^^^^^^^^^^
  File "/opt/homebrew/lib/python3.11/site-packages/sqlalchemy/engine/base.py", line 1638, in _execute_clauseelement
    ret = self._execute_context(
          ^^^^^^^^^^^^^^^^^^^^^^
  File "/opt/homebrew/lib/python3.11/site-packages/sqlalchemy/engine/base.py", line 1814, in _execute_context
    self._handle_dbapi_exception(
  File "/opt/homebrew/lib/python3.11/site-packages/sqlalchemy/engine/base.py", line 2326, in _handle_dbapi_exception
    raise sqlalchemy_exception.with_traceback(exc_info[2]) from e
  File "/opt/homebrew/lib/python3.11/site-packages/sqlalchemy/engine/base.py", line 1808, in _execute_context
    context = constructor(
              ^^^^^^^^^^^^
  File "/opt/homebrew/lib/python3.11/site-packages/sqlalchemy/engine/default.py", line 1294, in _init_compiled
    d_param = {
              ^
  File "/opt/homebrew/lib/python3.11/site-packages/sqlalchemy/engine/default.py", line 1295, in <dictcomp>
    key: flattened_processors[key](compiled_params[key])
         ^^^^^^^^^^^^^^^^^^^^^^^^^^^^^^^^^^^^^^^^^^^^^^^
  File "/opt/homebrew/lib/python3.11/site-packages/sqlalchemy/sql/sqltypes.py", line 2014, in process
    value = _strict_as_bool(value)
            ^^^^^^^^^^^^^^^^^^^^^^
  File "/opt/homebrew/lib/python3.11/site-packages/sqlalchemy/sql/sqltypes.py", line 1986, in _strict_as_bool
    raise TypeError("Not a boolean value: %r" % (value,))
sqlalchemy.exc.StatementError: (builtins.TypeError) Not a boolean value: ''
[SQL: INSERT INTO plants (common_name, scientific_name, sunlight_care, water_care, temperature_care, humidity_care, growing_tips, propagation_tips, common_pests, image_url, family, genus, year, edible, edible_part, edible_notes, medicinal, medicinal_notes, toxicity, synonyms, native_status, conservation_status, timestamp) VALUES (%(common_name)s, %(scientific_name)s, %(sunlight_care)s, %(water_care)s, %(temperature_care)s, %(humidity_care)s, %(growing_tips)s, %(propagation_tips)s, %(common_pests)s, %(image_url)s, %(family)s, %(genus)s, %(year)s, %(edible)s, %(edible_part)s, %(edible_notes)s, %(medicinal)s, %(medicinal_notes)s, %(toxicity)s, %(synonyms)s, %(native_status)s, %(conservation_status)s, %(timestamp)s) RETURNING plants.id]
[parameters: [{'native_status': '', 'image_url': '', 'propagation_tips': '', 'water_care': '', 'scientific_name': 'Adonidia merrillii', 'edible': '', 'common_pests' ... (155 characters truncated) ... mily': '', 'temperature_care': '', 'year': '', 'conservation_status': '', 'medicinal': '', 'sunlight_care': 'None', 'edible_part': '', 'synonyms': ''}]]
2023-05-02 14:36:43,872 - app - ERROR - Exception on /add_to_database [POST]
Traceback (most recent call last):
  File "/opt/homebrew/lib/python3.11/site-packages/sqlalchemy/engine/base.py", line 1808, in _execute_context
    context = constructor(
              ^^^^^^^^^^^^
  File "/opt/homebrew/lib/python3.11/site-packages/sqlalchemy/engine/default.py", line 1294, in _init_compiled
    d_param = {
              ^
  File "/opt/homebrew/lib/python3.11/site-packages/sqlalchemy/engine/default.py", line 1295, in <dictcomp>
    key: flattened_processors[key](compiled_params[key])
         ^^^^^^^^^^^^^^^^^^^^^^^^^^^^^^^^^^^^^^^^^^^^^^^
  File "/opt/homebrew/lib/python3.11/site-packages/sqlalchemy/sql/sqltypes.py", line 2014, in process
    value = _strict_as_bool(value)
            ^^^^^^^^^^^^^^^^^^^^^^
  File "/opt/homebrew/lib/python3.11/site-packages/sqlalchemy/sql/sqltypes.py", line 1986, in _strict_as_bool
    raise TypeError("Not a boolean value: %r" % (value,))
TypeError: Not a boolean value: ''

The above exception was the direct cause of the following exception:

Traceback (most recent call last):
  File "/opt/homebrew/lib/python3.11/site-packages/flask/app.py", line 2528, in wsgi_app
    response = self.full_dispatch_request()
               ^^^^^^^^^^^^^^^^^^^^^^^^^^^^
  File "/opt/homebrew/lib/python3.11/site-packages/flask/app.py", line 1825, in full_dispatch_request
    rv = self.handle_user_exception(e)
         ^^^^^^^^^^^^^^^^^^^^^^^^^^^^^
  File "/opt/homebrew/lib/python3.11/site-packages/flask/app.py", line 1823, in full_dispatch_request
    rv = self.dispatch_request()
         ^^^^^^^^^^^^^^^^^^^^^^^
  File "/opt/homebrew/lib/python3.11/site-packages/flask/app.py", line 1799, in dispatch_request
    return self.ensure_sync(self.view_functions[rule.endpoint])(**view_args)
           ^^^^^^^^^^^^^^^^^^^^^^^^^^^^^^^^^^^^^^^^^^^^^^^^^^^^^^^^^^^^^^^^^
  File "/Users/wbabich/PycharmProjects/plant_app/app.py", line 193, in add_to_database
    db_session.commit()
  File "/opt/homebrew/lib/python3.11/site-packages/sqlalchemy/orm/scoping.py", line 553, in commit
    return self._proxied.commit()
           ^^^^^^^^^^^^^^^^^^^^^^
  File "/opt/homebrew/lib/python3.11/site-packages/sqlalchemy/orm/session.py", line 1903, in commit
    trans.commit(_to_root=True)
  File "<string>", line 2, in commit
  File "/opt/homebrew/lib/python3.11/site-packages/sqlalchemy/orm/state_changes.py", line 137, in _go
    ret_value = fn(self, *arg, **kw)
                ^^^^^^^^^^^^^^^^^^^^
  File "/opt/homebrew/lib/python3.11/site-packages/sqlalchemy/orm/session.py", line 1218, in commit
    self._prepare_impl()
  File "<string>", line 2, in _prepare_impl
  File "/opt/homebrew/lib/python3.11/site-packages/sqlalchemy/orm/state_changes.py", line 137, in _go
    ret_value = fn(self, *arg, **kw)
                ^^^^^^^^^^^^^^^^^^^^
  File "/opt/homebrew/lib/python3.11/site-packages/sqlalchemy/orm/session.py", line 1193, in _prepare_impl
    self.session.flush()
  File "/opt/homebrew/lib/python3.11/site-packages/sqlalchemy/orm/session.py", line 4155, in flush
    self._flush(objects)
  File "/opt/homebrew/lib/python3.11/site-packages/sqlalchemy/orm/session.py", line 4291, in _flush
    with util.safe_reraise():
  File "/opt/homebrew/lib/python3.11/site-packages/sqlalchemy/util/langhelpers.py", line 147, in __exit__
    raise exc_value.with_traceback(exc_tb)
  File "/opt/homebrew/lib/python3.11/site-packages/sqlalchemy/orm/session.py", line 4252, in _flush
    flush_context.execute()
  File "/opt/homebrew/lib/python3.11/site-packages/sqlalchemy/orm/unitofwork.py", line 467, in execute
    rec.execute(self)
  File "/opt/homebrew/lib/python3.11/site-packages/sqlalchemy/orm/unitofwork.py", line 644, in execute
    util.preloaded.orm_persistence.save_obj(
  File "/opt/homebrew/lib/python3.11/site-packages/sqlalchemy/orm/persistence.py", line 93, in save_obj
    _emit_insert_statements(
  File "/opt/homebrew/lib/python3.11/site-packages/sqlalchemy/orm/persistence.py", line 1184, in _emit_insert_statements
    result = connection.execute(
             ^^^^^^^^^^^^^^^^^^^
  File "/opt/homebrew/lib/python3.11/site-packages/sqlalchemy/engine/base.py", line 1414, in execute
    return meth(
           ^^^^^
  File "/opt/homebrew/lib/python3.11/site-packages/sqlalchemy/sql/elements.py", line 486, in _execute_on_connection
    return connection._execute_clauseelement(
           ^^^^^^^^^^^^^^^^^^^^^^^^^^^^^^^^^^
  File "/opt/homebrew/lib/python3.11/site-packages/sqlalchemy/engine/base.py", line 1638, in _execute_clauseelement
    ret = self._execute_context(
          ^^^^^^^^^^^^^^^^^^^^^^
  File "/opt/homebrew/lib/python3.11/site-packages/sqlalchemy/engine/base.py", line 1814, in _execute_context
    self._handle_dbapi_exception(
  File "/opt/homebrew/lib/python3.11/site-packages/sqlalchemy/engine/base.py", line 2326, in _handle_dbapi_exception
    raise sqlalchemy_exception.with_traceback(exc_info[2]) from e
  File "/opt/homebrew/lib/python3.11/site-packages/sqlalchemy/engine/base.py", line 1808, in _execute_context
    context = constructor(
              ^^^^^^^^^^^^
  File "/opt/homebrew/lib/python3.11/site-packages/sqlalchemy/engine/default.py", line 1294, in _init_compiled
    d_param = {
              ^
  File "/opt/homebrew/lib/python3.11/site-packages/sqlalchemy/engine/default.py", line 1295, in <dictcomp>
    key: flattened_processors[key](compiled_params[key])
         ^^^^^^^^^^^^^^^^^^^^^^^^^^^^^^^^^^^^^^^^^^^^^^^
  File "/opt/homebrew/lib/python3.11/site-packages/sqlalchemy/sql/sqltypes.py", line 2014, in process
    value = _strict_as_bool(value)
            ^^^^^^^^^^^^^^^^^^^^^^
  File "/opt/homebrew/lib/python3.11/site-packages/sqlalchemy/sql/sqltypes.py", line 1986, in _strict_as_bool
    raise TypeError("Not a boolean value: %r" % (value,))
sqlalchemy.exc.StatementError: (builtins.TypeError) Not a boolean value: ''
[SQL: INSERT INTO plants (common_name, scientific_name, sunlight_care, water_care, temperature_care, humidity_care, growing_tips, propagation_tips, common_pests, image_url, family, genus, year, edible, edible_part, edible_notes, medicinal, medicinal_notes, toxicity, synonyms, native_status, conservation_status, timestamp) VALUES (%(common_name)s, %(scientific_name)s, %(sunlight_care)s, %(water_care)s, %(temperature_care)s, %(humidity_care)s, %(growing_tips)s, %(propagation_tips)s, %(common_pests)s, %(image_url)s, %(family)s, %(genus)s, %(year)s, %(edible)s, %(edible_part)s, %(edible_notes)s, %(medicinal)s, %(medicinal_notes)s, %(toxicity)s, %(synonyms)s, %(native_status)s, %(conservation_status)s, %(timestamp)s) RETURNING plants.id]
[parameters: [{'year': '', 'temperature_care': '', 'sunlight_care': 'None', 'image_url': '', 'genus': '', 'growing_tips': '', 'water_care': '', 'common_pests': '',  ... (152 characters truncated) ... e': '', 'edible_part': '', 'common_name': 'Yellow-water-lily', 'propagation_tips': '', 'conservation_status': '', 'edible_notes': '', 'medicinal': ''}]]
2023-05-02 14:46:55,754 - app - ERROR - Exception on /search [POST]
Traceback (most recent call last):
  File "/opt/homebrew/lib/python3.11/site-packages/flask/app.py", line 2528, in wsgi_app
    response = self.full_dispatch_request()
               ^^^^^^^^^^^^^^^^^^^^^^^^^^^^
  File "/opt/homebrew/lib/python3.11/site-packages/flask/app.py", line 1825, in full_dispatch_request
    rv = self.handle_user_exception(e)
         ^^^^^^^^^^^^^^^^^^^^^^^^^^^^^
  File "/opt/homebrew/lib/python3.11/site-packages/flask/app.py", line 1823, in full_dispatch_request
    rv = self.dispatch_request()
         ^^^^^^^^^^^^^^^^^^^^^^^
  File "/opt/homebrew/lib/python3.11/site-packages/flask/app.py", line 1799, in dispatch_request
    return self.ensure_sync(self.view_functions[rule.endpoint])(**view_args)
           ^^^^^^^^^^^^^^^^^^^^^^^^^^^^^^^^^^^^^^^^^^^^^^^^^^^^^^^^^^^^^^^^^
  File "/Users/wbabich/PycharmProjects/plant_app/app.py", line 88, in search_plant
    return render_template('search_results.html', name=query, result=fetched_plant_info)
           ^^^^^^^^^^^^^^^^^^^^^^^^^^^^^^^^^^^^^^^^^^^^^^^^^^^^^^^^^^^^^^^^^^^^^^^^^^^^^
  File "/opt/homebrew/lib/python3.11/site-packages/flask/templating.py", line 147, in render_template
    return _render(app, template, context)
           ^^^^^^^^^^^^^^^^^^^^^^^^^^^^^^^
  File "/opt/homebrew/lib/python3.11/site-packages/flask/templating.py", line 130, in _render
    rv = template.render(context)
         ^^^^^^^^^^^^^^^^^^^^^^^^
  File "/opt/homebrew/lib/python3.11/site-packages/jinja2/environment.py", line 1301, in render
    self.environment.handle_exception()
  File "/opt/homebrew/lib/python3.11/site-packages/jinja2/environment.py", line 936, in handle_exception
    raise rewrite_traceback_stack(source=source)
  File "/Users/wbabich/PycharmProjects/plant_app/templates/search_results.html", line 1, in top-level template code
    {% extends 'base.html' %}
  File "/Users/wbabich/PycharmProjects/plant_app/templates/base.html", line 43, in top-level template code
    {% block content %}
  File "/Users/wbabich/PycharmProjects/plant_app/templates/search_results.html", line 33, in block 'content'
    <input type="hidden" name="edible" value="{{ str(edible).lower() }}">
    ^^^^^^^^^^^^^^^^^^^^^^^^^
  File "/opt/homebrew/lib/python3.11/site-packages/jinja2/utils.py", line 83, in from_obj
    if hasattr(obj, "jinja_pass_arg"):
       ^^^^^^^^^^^^^^^^^^^^^^^^^^^^^^
jinja2.exceptions.UndefinedError: 'str' is undefined
2023-05-02 14:48:20,123 - app - ERROR - Exception on /search [POST]
Traceback (most recent call last):
  File "/opt/homebrew/lib/python3.11/site-packages/flask/app.py", line 2528, in wsgi_app
    response = self.full_dispatch_request()
               ^^^^^^^^^^^^^^^^^^^^^^^^^^^^
  File "/opt/homebrew/lib/python3.11/site-packages/flask/app.py", line 1825, in full_dispatch_request
    rv = self.handle_user_exception(e)
         ^^^^^^^^^^^^^^^^^^^^^^^^^^^^^
  File "/opt/homebrew/lib/python3.11/site-packages/flask/app.py", line 1823, in full_dispatch_request
    rv = self.dispatch_request()
         ^^^^^^^^^^^^^^^^^^^^^^^
  File "/opt/homebrew/lib/python3.11/site-packages/flask/app.py", line 1799, in dispatch_request
    return self.ensure_sync(self.view_functions[rule.endpoint])(**view_args)
           ^^^^^^^^^^^^^^^^^^^^^^^^^^^^^^^^^^^^^^^^^^^^^^^^^^^^^^^^^^^^^^^^^
  File "/Users/wbabich/PycharmProjects/plant_app/app.py", line 88, in search_plant
    return render_template('search_results.html', name=query, result=fetched_plant_info)
           ^^^^^^^^^^^^^^^^^^^^^^^^^^^^^^^^^^^^^^^^^^^^^^^^^^^^^^^^^^^^^^^^^^^^^^^^^^^^^
  File "/opt/homebrew/lib/python3.11/site-packages/flask/templating.py", line 146, in render_template
    template = app.jinja_env.get_or_select_template(template_name_or_list)
               ^^^^^^^^^^^^^^^^^^^^^^^^^^^^^^^^^^^^^^^^^^^^^^^^^^^^^^^^^^^
  File "/opt/homebrew/lib/python3.11/site-packages/jinja2/environment.py", line 1081, in get_or_select_template
    return self.get_template(template_name_or_list, parent, globals)
           ^^^^^^^^^^^^^^^^^^^^^^^^^^^^^^^^^^^^^^^^^^^^^^^^^^^^^^^^^
  File "/opt/homebrew/lib/python3.11/site-packages/jinja2/environment.py", line 1010, in get_template
    return self._load_template(name, globals)
           ^^^^^^^^^^^^^^^^^^^^^^^^^^^^^^^^^^
  File "/opt/homebrew/lib/python3.11/site-packages/jinja2/environment.py", line 969, in _load_template
    template = self.loader.load(self, name, self.make_globals(globals))
               ^^^^^^^^^^^^^^^^^^^^^^^^^^^^^^^^^^^^^^^^^^^^^^^^^^^^^^^^
  File "/opt/homebrew/lib/python3.11/site-packages/jinja2/loaders.py", line 138, in load
    code = environment.compile(source, name, filename)
           ^^^^^^^^^^^^^^^^^^^^^^^^^^^^^^^^^^^^^^^^^^^
  File "/opt/homebrew/lib/python3.11/site-packages/jinja2/environment.py", line 768, in compile
    self.handle_exception(source=source_hint)
  File "/opt/homebrew/lib/python3.11/site-packages/jinja2/environment.py", line 936, in handle_exception
    raise rewrite_traceback_stack(source=source)
  File "/Users/wbabich/PycharmProjects/plant_app/templates/search_results.html", line 33, in template
    <input type="hidden" name="edible" value="{{ edible|string().lower() }}">
    ^^^^^^^^^^^^^^^^^^^^^^^^^
jinja2.exceptions.TemplateSyntaxError: expected token 'end of print statement', got '.'
2023-05-02 14:49:50,398 - app - ERROR - Exception on /add_to_database [POST]
Traceback (most recent call last):
  File "/opt/homebrew/lib/python3.11/site-packages/sqlalchemy/engine/base.py", line 1808, in _execute_context
    context = constructor(
              ^^^^^^^^^^^^
  File "/opt/homebrew/lib/python3.11/site-packages/sqlalchemy/engine/default.py", line 1294, in _init_compiled
    d_param = {
              ^
  File "/opt/homebrew/lib/python3.11/site-packages/sqlalchemy/engine/default.py", line 1295, in <dictcomp>
    key: flattened_processors[key](compiled_params[key])
         ^^^^^^^^^^^^^^^^^^^^^^^^^^^^^^^^^^^^^^^^^^^^^^^
  File "/opt/homebrew/lib/python3.11/site-packages/sqlalchemy/sql/sqltypes.py", line 2014, in process
    value = _strict_as_bool(value)
            ^^^^^^^^^^^^^^^^^^^^^^
  File "/opt/homebrew/lib/python3.11/site-packages/sqlalchemy/sql/sqltypes.py", line 1986, in _strict_as_bool
    raise TypeError("Not a boolean value: %r" % (value,))
TypeError: Not a boolean value: ''

The above exception was the direct cause of the following exception:

Traceback (most recent call last):
  File "/opt/homebrew/lib/python3.11/site-packages/flask/app.py", line 2528, in wsgi_app
    response = self.full_dispatch_request()
               ^^^^^^^^^^^^^^^^^^^^^^^^^^^^
  File "/opt/homebrew/lib/python3.11/site-packages/flask/app.py", line 1825, in full_dispatch_request
    rv = self.handle_user_exception(e)
         ^^^^^^^^^^^^^^^^^^^^^^^^^^^^^
  File "/opt/homebrew/lib/python3.11/site-packages/flask/app.py", line 1823, in full_dispatch_request
    rv = self.dispatch_request()
         ^^^^^^^^^^^^^^^^^^^^^^^
  File "/opt/homebrew/lib/python3.11/site-packages/flask/app.py", line 1799, in dispatch_request
    return self.ensure_sync(self.view_functions[rule.endpoint])(**view_args)
           ^^^^^^^^^^^^^^^^^^^^^^^^^^^^^^^^^^^^^^^^^^^^^^^^^^^^^^^^^^^^^^^^^
  File "/Users/wbabich/PycharmProjects/plant_app/app.py", line 193, in add_to_database
    db_session.commit()
  File "/opt/homebrew/lib/python3.11/site-packages/sqlalchemy/orm/scoping.py", line 553, in commit
    return self._proxied.commit()
           ^^^^^^^^^^^^^^^^^^^^^^
  File "/opt/homebrew/lib/python3.11/site-packages/sqlalchemy/orm/session.py", line 1903, in commit
    trans.commit(_to_root=True)
  File "<string>", line 2, in commit
  File "/opt/homebrew/lib/python3.11/site-packages/sqlalchemy/orm/state_changes.py", line 137, in _go
    ret_value = fn(self, *arg, **kw)
                ^^^^^^^^^^^^^^^^^^^^
  File "/opt/homebrew/lib/python3.11/site-packages/sqlalchemy/orm/session.py", line 1218, in commit
    self._prepare_impl()
  File "<string>", line 2, in _prepare_impl
  File "/opt/homebrew/lib/python3.11/site-packages/sqlalchemy/orm/state_changes.py", line 137, in _go
    ret_value = fn(self, *arg, **kw)
                ^^^^^^^^^^^^^^^^^^^^
  File "/opt/homebrew/lib/python3.11/site-packages/sqlalchemy/orm/session.py", line 1193, in _prepare_impl
    self.session.flush()
  File "/opt/homebrew/lib/python3.11/site-packages/sqlalchemy/orm/session.py", line 4155, in flush
    self._flush(objects)
  File "/opt/homebrew/lib/python3.11/site-packages/sqlalchemy/orm/session.py", line 4291, in _flush
    with util.safe_reraise():
  File "/opt/homebrew/lib/python3.11/site-packages/sqlalchemy/util/langhelpers.py", line 147, in __exit__
    raise exc_value.with_traceback(exc_tb)
  File "/opt/homebrew/lib/python3.11/site-packages/sqlalchemy/orm/session.py", line 4252, in _flush
    flush_context.execute()
  File "/opt/homebrew/lib/python3.11/site-packages/sqlalchemy/orm/unitofwork.py", line 467, in execute
    rec.execute(self)
  File "/opt/homebrew/lib/python3.11/site-packages/sqlalchemy/orm/unitofwork.py", line 644, in execute
    util.preloaded.orm_persistence.save_obj(
  File "/opt/homebrew/lib/python3.11/site-packages/sqlalchemy/orm/persistence.py", line 93, in save_obj
    _emit_insert_statements(
  File "/opt/homebrew/lib/python3.11/site-packages/sqlalchemy/orm/persistence.py", line 1184, in _emit_insert_statements
    result = connection.execute(
             ^^^^^^^^^^^^^^^^^^^
  File "/opt/homebrew/lib/python3.11/site-packages/sqlalchemy/engine/base.py", line 1414, in execute
    return meth(
           ^^^^^
  File "/opt/homebrew/lib/python3.11/site-packages/sqlalchemy/sql/elements.py", line 486, in _execute_on_connection
    return connection._execute_clauseelement(
           ^^^^^^^^^^^^^^^^^^^^^^^^^^^^^^^^^^
  File "/opt/homebrew/lib/python3.11/site-packages/sqlalchemy/engine/base.py", line 1638, in _execute_clauseelement
    ret = self._execute_context(
          ^^^^^^^^^^^^^^^^^^^^^^
  File "/opt/homebrew/lib/python3.11/site-packages/sqlalchemy/engine/base.py", line 1814, in _execute_context
    self._handle_dbapi_exception(
  File "/opt/homebrew/lib/python3.11/site-packages/sqlalchemy/engine/base.py", line 2326, in _handle_dbapi_exception
    raise sqlalchemy_exception.with_traceback(exc_info[2]) from e
  File "/opt/homebrew/lib/python3.11/site-packages/sqlalchemy/engine/base.py", line 1808, in _execute_context
    context = constructor(
              ^^^^^^^^^^^^
  File "/opt/homebrew/lib/python3.11/site-packages/sqlalchemy/engine/default.py", line 1294, in _init_compiled
    d_param = {
              ^
  File "/opt/homebrew/lib/python3.11/site-packages/sqlalchemy/engine/default.py", line 1295, in <dictcomp>
    key: flattened_processors[key](compiled_params[key])
         ^^^^^^^^^^^^^^^^^^^^^^^^^^^^^^^^^^^^^^^^^^^^^^^
  File "/opt/homebrew/lib/python3.11/site-packages/sqlalchemy/sql/sqltypes.py", line 2014, in process
    value = _strict_as_bool(value)
            ^^^^^^^^^^^^^^^^^^^^^^
  File "/opt/homebrew/lib/python3.11/site-packages/sqlalchemy/sql/sqltypes.py", line 1986, in _strict_as_bool
    raise TypeError("Not a boolean value: %r" % (value,))
sqlalchemy.exc.StatementError: (builtins.TypeError) Not a boolean value: ''
[SQL: INSERT INTO plants (common_name, scientific_name, sunlight_care, water_care, temperature_care, humidity_care, growing_tips, propagation_tips, common_pests, image_url, family, genus, year, edible, edible_part, edible_notes, medicinal, medicinal_notes, toxicity, synonyms, native_status, conservation_status, timestamp) VALUES (%(common_name)s, %(scientific_name)s, %(sunlight_care)s, %(water_care)s, %(temperature_care)s, %(humidity_care)s, %(growing_tips)s, %(propagation_tips)s, %(common_pests)s, %(image_url)s, %(family)s, %(genus)s, %(year)s, %(edible)s, %(edible_part)s, %(edible_notes)s, %(medicinal)s, %(medicinal_notes)s, %(toxicity)s, %(synonyms)s, %(native_status)s, %(conservation_status)s, %(timestamp)s) RETURNING plants.id]
[parameters: [{'growing_tips': '', 'medicinal': '', 'temperature_care': '', 'common_name': 'Thorn-apple', 'scientific_name': 'Datura stramonium', 'sunlight_care': ' ... (151 characters truncated) ... , 'humidity_care': '', 'common_pests': '', 'family': '', 'native_status': '', 'genus': '', 'edible': '', 'synonyms': '', 'water_care': '', 'year': ''}]]
2023-05-02 14:54:45,221 - app - ERROR - Exception on /add_to_database [POST]
Traceback (most recent call last):
  File "/opt/homebrew/lib/python3.11/site-packages/sqlalchemy/engine/base.py", line 1964, in _exec_single_context
    self.dialect.do_execute(
  File "/opt/homebrew/lib/python3.11/site-packages/sqlalchemy/engine/default.py", line 748, in do_execute
    cursor.execute(statement, parameters)
psycopg2.errors.InvalidTextRepresentation: invalid input syntax for type integer: ""
LINE 1: ...rix', 'None', '', '', '', '', '', '', '', '', '', '', false,...
                                                             ^


The above exception was the direct cause of the following exception:

Traceback (most recent call last):
  File "/opt/homebrew/lib/python3.11/site-packages/flask/app.py", line 2528, in wsgi_app
    response = self.full_dispatch_request()
               ^^^^^^^^^^^^^^^^^^^^^^^^^^^^
  File "/opt/homebrew/lib/python3.11/site-packages/flask/app.py", line 1825, in full_dispatch_request
    rv = self.handle_user_exception(e)
         ^^^^^^^^^^^^^^^^^^^^^^^^^^^^^
  File "/opt/homebrew/lib/python3.11/site-packages/flask/app.py", line 1823, in full_dispatch_request
    rv = self.dispatch_request()
         ^^^^^^^^^^^^^^^^^^^^^^^
  File "/opt/homebrew/lib/python3.11/site-packages/flask/app.py", line 1799, in dispatch_request
    return self.ensure_sync(self.view_functions[rule.endpoint])(**view_args)
           ^^^^^^^^^^^^^^^^^^^^^^^^^^^^^^^^^^^^^^^^^^^^^^^^^^^^^^^^^^^^^^^^^
  File "/Users/wbabich/PycharmProjects/plant_app/app.py", line 193, in add_to_database
    db_session.commit()
  File "/opt/homebrew/lib/python3.11/site-packages/sqlalchemy/orm/scoping.py", line 553, in commit
    return self._proxied.commit()
           ^^^^^^^^^^^^^^^^^^^^^^
  File "/opt/homebrew/lib/python3.11/site-packages/sqlalchemy/orm/session.py", line 1903, in commit
    trans.commit(_to_root=True)
  File "<string>", line 2, in commit
  File "/opt/homebrew/lib/python3.11/site-packages/sqlalchemy/orm/state_changes.py", line 137, in _go
    ret_value = fn(self, *arg, **kw)
                ^^^^^^^^^^^^^^^^^^^^
  File "/opt/homebrew/lib/python3.11/site-packages/sqlalchemy/orm/session.py", line 1218, in commit
    self._prepare_impl()
  File "<string>", line 2, in _prepare_impl
  File "/opt/homebrew/lib/python3.11/site-packages/sqlalchemy/orm/state_changes.py", line 137, in _go
    ret_value = fn(self, *arg, **kw)
                ^^^^^^^^^^^^^^^^^^^^
  File "/opt/homebrew/lib/python3.11/site-packages/sqlalchemy/orm/session.py", line 1193, in _prepare_impl
    self.session.flush()
  File "/opt/homebrew/lib/python3.11/site-packages/sqlalchemy/orm/session.py", line 4155, in flush
    self._flush(objects)
  File "/opt/homebrew/lib/python3.11/site-packages/sqlalchemy/orm/session.py", line 4291, in _flush
    with util.safe_reraise():
  File "/opt/homebrew/lib/python3.11/site-packages/sqlalchemy/util/langhelpers.py", line 147, in __exit__
    raise exc_value.with_traceback(exc_tb)
  File "/opt/homebrew/lib/python3.11/site-packages/sqlalchemy/orm/session.py", line 4252, in _flush
    flush_context.execute()
  File "/opt/homebrew/lib/python3.11/site-packages/sqlalchemy/orm/unitofwork.py", line 467, in execute
    rec.execute(self)
  File "/opt/homebrew/lib/python3.11/site-packages/sqlalchemy/orm/unitofwork.py", line 644, in execute
    util.preloaded.orm_persistence.save_obj(
  File "/opt/homebrew/lib/python3.11/site-packages/sqlalchemy/orm/persistence.py", line 93, in save_obj
    _emit_insert_statements(
  File "/opt/homebrew/lib/python3.11/site-packages/sqlalchemy/orm/persistence.py", line 1184, in _emit_insert_statements
    result = connection.execute(
             ^^^^^^^^^^^^^^^^^^^
  File "/opt/homebrew/lib/python3.11/site-packages/sqlalchemy/engine/base.py", line 1414, in execute
    return meth(
           ^^^^^
  File "/opt/homebrew/lib/python3.11/site-packages/sqlalchemy/sql/elements.py", line 486, in _execute_on_connection
    return connection._execute_clauseelement(
           ^^^^^^^^^^^^^^^^^^^^^^^^^^^^^^^^^^
  File "/opt/homebrew/lib/python3.11/site-packages/sqlalchemy/engine/base.py", line 1638, in _execute_clauseelement
    ret = self._execute_context(
          ^^^^^^^^^^^^^^^^^^^^^^
  File "/opt/homebrew/lib/python3.11/site-packages/sqlalchemy/engine/base.py", line 1842, in _execute_context
    return self._exec_single_context(
           ^^^^^^^^^^^^^^^^^^^^^^^^^^
  File "/opt/homebrew/lib/python3.11/site-packages/sqlalchemy/engine/base.py", line 1983, in _exec_single_context
    self._handle_dbapi_exception(
  File "/opt/homebrew/lib/python3.11/site-packages/sqlalchemy/engine/base.py", line 2326, in _handle_dbapi_exception
    raise sqlalchemy_exception.with_traceback(exc_info[2]) from e
  File "/opt/homebrew/lib/python3.11/site-packages/sqlalchemy/engine/base.py", line 1964, in _exec_single_context
    self.dialect.do_execute(
  File "/opt/homebrew/lib/python3.11/site-packages/sqlalchemy/engine/default.py", line 748, in do_execute
    cursor.execute(statement, parameters)
sqlalchemy.exc.DataError: (psycopg2.errors.InvalidTextRepresentation) invalid input syntax for type integer: ""
LINE 1: ...rix', 'None', '', '', '', '', '', '', '', '', '', '', false,...
                                                             ^

[SQL: INSERT INTO plants (common_name, scientific_name, sunlight_care, water_care, temperature_care, humidity_care, growing_tips, propagation_tips, common_pests, image_url, family, genus, year, edible, edible_part, edible_notes, medicinal, medicinal_notes, toxicity, synonyms, native_status, conservation_status, timestamp) VALUES (%(common_name)s, %(scientific_name)s, %(sunlight_care)s, %(water_care)s, %(temperature_care)s, %(humidity_care)s, %(growing_tips)s, %(propagation_tips)s, %(common_pests)s, %(image_url)s, %(family)s, %(genus)s, %(year)s, %(edible)s, %(edible_part)s, %(edible_notes)s, %(medicinal)s, %(medicinal_notes)s, %(toxicity)s, %(synonyms)s, %(native_status)s, %(conservation_status)s, %(timestamp)s) RETURNING plants.id]
[parameters: {'common_name': 'Kaffir lime', 'scientific_name': 'Citrus hystrix', 'sunlight_care': 'None', 'water_care': '', 'temperature_care': '', 'humidity_care': '', 'growing_tips': '', 'propagation_tips': '', 'common_pests': '', 'image_url': '', 'family': '', 'genus': '', 'year': '', 'edible': False, 'edible_part': '', 'edible_notes': '', 'medicinal': False, 'medicinal_notes': '', 'toxicity': '', 'synonyms': '', 'native_status': '', 'conservation_status': '', 'timestamp': datetime.datetime(2023, 5, 2, 18, 54, 45, 216688)}]
(Background on this error at: https://sqlalche.me/e/20/9h9h)
2023-05-02 14:55:31,268 - app - ERROR - Exception on /add_to_database [POST]
Traceback (most recent call last):
  File "/opt/homebrew/lib/python3.11/site-packages/flask/app.py", line 2528, in wsgi_app
    response = self.full_dispatch_request()
               ^^^^^^^^^^^^^^^^^^^^^^^^^^^^
  File "/opt/homebrew/lib/python3.11/site-packages/flask/app.py", line 1825, in full_dispatch_request
    rv = self.handle_user_exception(e)
         ^^^^^^^^^^^^^^^^^^^^^^^^^^^^^
  File "/opt/homebrew/lib/python3.11/site-packages/flask/app.py", line 1823, in full_dispatch_request
    rv = self.dispatch_request()
         ^^^^^^^^^^^^^^^^^^^^^^^
  File "/opt/homebrew/lib/python3.11/site-packages/flask/app.py", line 1799, in dispatch_request
    return self.ensure_sync(self.view_functions[rule.endpoint])(**view_args)
           ^^^^^^^^^^^^^^^^^^^^^^^^^^^^^^^^^^^^^^^^^^^^^^^^^^^^^^^^^^^^^^^^^
  File "/Users/wbabich/PycharmProjects/plant_app/app.py", line 153, in add_to_database
    edible = bool(request.form['edible']).lower()
             ^^^^^^^^^^^^^^^^^^^^^^^^^^^^^^^^^^
AttributeError: 'bool' object has no attribute 'lower'
2023-05-02 14:56:07,301 - app - ERROR - Exception on /add_to_database [POST]
Traceback (most recent call last):
  File "/opt/homebrew/lib/python3.11/site-packages/sqlalchemy/engine/base.py", line 1808, in _execute_context
    context = constructor(
              ^^^^^^^^^^^^
  File "/opt/homebrew/lib/python3.11/site-packages/sqlalchemy/engine/default.py", line 1294, in _init_compiled
    d_param = {
              ^
  File "/opt/homebrew/lib/python3.11/site-packages/sqlalchemy/engine/default.py", line 1295, in <dictcomp>
    key: flattened_processors[key](compiled_params[key])
         ^^^^^^^^^^^^^^^^^^^^^^^^^^^^^^^^^^^^^^^^^^^^^^^
  File "/opt/homebrew/lib/python3.11/site-packages/sqlalchemy/sql/sqltypes.py", line 2014, in process
    value = _strict_as_bool(value)
            ^^^^^^^^^^^^^^^^^^^^^^
  File "/opt/homebrew/lib/python3.11/site-packages/sqlalchemy/sql/sqltypes.py", line 1986, in _strict_as_bool
    raise TypeError("Not a boolean value: %r" % (value,))
TypeError: Not a boolean value: ''

The above exception was the direct cause of the following exception:

Traceback (most recent call last):
  File "/opt/homebrew/lib/python3.11/site-packages/flask/app.py", line 2528, in wsgi_app
    response = self.full_dispatch_request()
               ^^^^^^^^^^^^^^^^^^^^^^^^^^^^
  File "/opt/homebrew/lib/python3.11/site-packages/flask/app.py", line 1825, in full_dispatch_request
    rv = self.handle_user_exception(e)
         ^^^^^^^^^^^^^^^^^^^^^^^^^^^^^
  File "/opt/homebrew/lib/python3.11/site-packages/flask/app.py", line 1823, in full_dispatch_request
    rv = self.dispatch_request()
         ^^^^^^^^^^^^^^^^^^^^^^^
  File "/opt/homebrew/lib/python3.11/site-packages/flask/app.py", line 1799, in dispatch_request
    return self.ensure_sync(self.view_functions[rule.endpoint])(**view_args)
           ^^^^^^^^^^^^^^^^^^^^^^^^^^^^^^^^^^^^^^^^^^^^^^^^^^^^^^^^^^^^^^^^^
  File "/Users/wbabich/PycharmProjects/plant_app/app.py", line 193, in add_to_database
    db_session.commit()
  File "/opt/homebrew/lib/python3.11/site-packages/sqlalchemy/orm/scoping.py", line 553, in commit
    return self._proxied.commit()
           ^^^^^^^^^^^^^^^^^^^^^^
  File "/opt/homebrew/lib/python3.11/site-packages/sqlalchemy/orm/session.py", line 1903, in commit
    trans.commit(_to_root=True)
  File "<string>", line 2, in commit
  File "/opt/homebrew/lib/python3.11/site-packages/sqlalchemy/orm/state_changes.py", line 137, in _go
    ret_value = fn(self, *arg, **kw)
                ^^^^^^^^^^^^^^^^^^^^
  File "/opt/homebrew/lib/python3.11/site-packages/sqlalchemy/orm/session.py", line 1218, in commit
    self._prepare_impl()
  File "<string>", line 2, in _prepare_impl
  File "/opt/homebrew/lib/python3.11/site-packages/sqlalchemy/orm/state_changes.py", line 137, in _go
    ret_value = fn(self, *arg, **kw)
                ^^^^^^^^^^^^^^^^^^^^
  File "/opt/homebrew/lib/python3.11/site-packages/sqlalchemy/orm/session.py", line 1193, in _prepare_impl
    self.session.flush()
  File "/opt/homebrew/lib/python3.11/site-packages/sqlalchemy/orm/session.py", line 4155, in flush
    self._flush(objects)
  File "/opt/homebrew/lib/python3.11/site-packages/sqlalchemy/orm/session.py", line 4291, in _flush
    with util.safe_reraise():
  File "/opt/homebrew/lib/python3.11/site-packages/sqlalchemy/util/langhelpers.py", line 147, in __exit__
    raise exc_value.with_traceback(exc_tb)
  File "/opt/homebrew/lib/python3.11/site-packages/sqlalchemy/orm/session.py", line 4252, in _flush
    flush_context.execute()
  File "/opt/homebrew/lib/python3.11/site-packages/sqlalchemy/orm/unitofwork.py", line 467, in execute
    rec.execute(self)
  File "/opt/homebrew/lib/python3.11/site-packages/sqlalchemy/orm/unitofwork.py", line 644, in execute
    util.preloaded.orm_persistence.save_obj(
  File "/opt/homebrew/lib/python3.11/site-packages/sqlalchemy/orm/persistence.py", line 93, in save_obj
    _emit_insert_statements(
  File "/opt/homebrew/lib/python3.11/site-packages/sqlalchemy/orm/persistence.py", line 1184, in _emit_insert_statements
    result = connection.execute(
             ^^^^^^^^^^^^^^^^^^^
  File "/opt/homebrew/lib/python3.11/site-packages/sqlalchemy/engine/base.py", line 1414, in execute
    return meth(
           ^^^^^
  File "/opt/homebrew/lib/python3.11/site-packages/sqlalchemy/sql/elements.py", line 486, in _execute_on_connection
    return connection._execute_clauseelement(
           ^^^^^^^^^^^^^^^^^^^^^^^^^^^^^^^^^^
  File "/opt/homebrew/lib/python3.11/site-packages/sqlalchemy/engine/base.py", line 1638, in _execute_clauseelement
    ret = self._execute_context(
          ^^^^^^^^^^^^^^^^^^^^^^
  File "/opt/homebrew/lib/python3.11/site-packages/sqlalchemy/engine/base.py", line 1814, in _execute_context
    self._handle_dbapi_exception(
  File "/opt/homebrew/lib/python3.11/site-packages/sqlalchemy/engine/base.py", line 2326, in _handle_dbapi_exception
    raise sqlalchemy_exception.with_traceback(exc_info[2]) from e
  File "/opt/homebrew/lib/python3.11/site-packages/sqlalchemy/engine/base.py", line 1808, in _execute_context
    context = constructor(
              ^^^^^^^^^^^^
  File "/opt/homebrew/lib/python3.11/site-packages/sqlalchemy/engine/default.py", line 1294, in _init_compiled
    d_param = {
              ^
  File "/opt/homebrew/lib/python3.11/site-packages/sqlalchemy/engine/default.py", line 1295, in <dictcomp>
    key: flattened_processors[key](compiled_params[key])
         ^^^^^^^^^^^^^^^^^^^^^^^^^^^^^^^^^^^^^^^^^^^^^^^
  File "/opt/homebrew/lib/python3.11/site-packages/sqlalchemy/sql/sqltypes.py", line 2014, in process
    value = _strict_as_bool(value)
            ^^^^^^^^^^^^^^^^^^^^^^
  File "/opt/homebrew/lib/python3.11/site-packages/sqlalchemy/sql/sqltypes.py", line 1986, in _strict_as_bool
    raise TypeError("Not a boolean value: %r" % (value,))
sqlalchemy.exc.StatementError: (builtins.TypeError) Not a boolean value: ''
[SQL: INSERT INTO plants (common_name, scientific_name, sunlight_care, water_care, temperature_care, humidity_care, growing_tips, propagation_tips, common_pests, image_url, family, genus, year, edible, edible_part, edible_notes, medicinal, medicinal_notes, toxicity, synonyms, native_status, conservation_status, timestamp) VALUES (%(common_name)s, %(scientific_name)s, %(sunlight_care)s, %(water_care)s, %(temperature_care)s, %(humidity_care)s, %(growing_tips)s, %(propagation_tips)s, %(common_pests)s, %(image_url)s, %(family)s, %(genus)s, %(year)s, %(edible)s, %(edible_part)s, %(edible_notes)s, %(medicinal)s, %(medicinal_notes)s, %(toxicity)s, %(synonyms)s, %(native_status)s, %(conservation_status)s, %(timestamp)s) RETURNING plants.id]
[parameters: [{'propagation_tips': '', 'genus': '', 'common_name': 'Thorn-apple', 'conservation_status': '', 'scientific_name': 'Datura stramonium', 'year': '', 'ed ... (151 characters truncated) ... s': '', 'edible_part': '', 'medicinal': '', 'medicinal_notes': '', 'sunlight_care': 'None', 'edible_notes': '', 'native_status': '', 'water_care': ''}]]
