2023-04-27 15:52:53,573 - app - ERROR - Exception on /search_plant [POST]
Traceback (most recent call last):
  File "/Users/wbabich/Documents/plantApp/plant_app/venv/lib/python3.11/site-packages/flask/app.py", line 2528, in wsgi_app
    response = self.full_dispatch_request()
               ^^^^^^^^^^^^^^^^^^^^^^^^^^^^
  File "/Users/wbabich/Documents/plantApp/plant_app/venv/lib/python3.11/site-packages/flask/app.py", line 1825, in full_dispatch_request
    rv = self.handle_user_exception(e)
         ^^^^^^^^^^^^^^^^^^^^^^^^^^^^^
  File "/Users/wbabich/Documents/plantApp/plant_app/venv/lib/python3.11/site-packages/flask/app.py", line 1823, in full_dispatch_request
    rv = self.dispatch_request()
         ^^^^^^^^^^^^^^^^^^^^^^^
  File "/Users/wbabich/Documents/plantApp/plant_app/venv/lib/python3.11/site-packages/flask/app.py", line 1799, in dispatch_request
    return self.ensure_sync(self.view_functions[rule.endpoint])(**view_args)
           ^^^^^^^^^^^^^^^^^^^^^^^^^^^^^^^^^^^^^^^^^^^^^^^^^^^^^^^^^^^^^^^^^
  File "/Users/wbabich/Documents/plantApp/plant_app/app.py", line 87, in search_plant
    return jsonify(results)
           ^^^^^^^^^^^^^^^^
TypeError: 'module' object is not callable
