2023-04-27 15:52:53,573 - app - ERROR - Exception on /search_plant [POST]
Traceback (most recent call last):
  File "/Users/wbabich/Documents/plantApp/plant_app/venv/lib/python3.11/site-packages/flask/app.py", line 2528, in wsgi_app
    response = self.full_dispatch_request()
               ^^^^^^^^^^^^^^^^^^^^^^^^^^^^
  File "/Users/wbabich/Documents/plantApp/plant_app/venv/lib/python3.11/site-packages/flask/app.py", line 1825, in full_dispatch_request
    rv = self.handle_user_exception(e)
         ^^^^^^^^^^^^^^^^^^^^^^^^^^^^^
  File "/Users/wbabich/Documents/plantApp/plant_app/venv/lib/python3.11/site-packages/flask/app.py", line 1823, in full_dispatch_request
    rv = self.dispatch_request()
         ^^^^^^^^^^^^^^^^^^^^^^^
  File "/Users/wbabich/Documents/plantApp/plant_app/venv/lib/python3.11/site-packages/flask/app.py", line 1799, in dispatch_request
    return self.ensure_sync(self.view_functions[rule.endpoint])(**view_args)
           ^^^^^^^^^^^^^^^^^^^^^^^^^^^^^^^^^^^^^^^^^^^^^^^^^^^^^^^^^^^^^^^^^
  File "/Users/wbabich/Documents/plantApp/plant_app/app.py", line 87, in search_plant
    return jsonify(results)
           ^^^^^^^^^^^^^^^^
TypeError: 'module' object is not callable
2023-05-23 17:13:14,019 - app - ERROR - Exception on / [GET]
Traceback (most recent call last):
  File "/opt/homebrew/lib/python3.11/site-packages/sqlalchemy/engine/base.py", line 1964, in _exec_single_context
    self.dialect.do_execute(
  File "/opt/homebrew/lib/python3.11/site-packages/sqlalchemy/engine/default.py", line 748, in do_execute
    cursor.execute(statement, parameters)
psycopg2.errors.UndefinedColumn: column plants.sunlight_care does not exist
LINE 1: ...plants.scientific_name AS plants_scientific_name, plants.sun...
                                                             ^


The above exception was the direct cause of the following exception:

Traceback (most recent call last):
  File "/opt/homebrew/lib/python3.11/site-packages/flask/app.py", line 2528, in wsgi_app
    response = self.full_dispatch_request()
               ^^^^^^^^^^^^^^^^^^^^^^^^^^^^
  File "/opt/homebrew/lib/python3.11/site-packages/flask/app.py", line 1825, in full_dispatch_request
    rv = self.handle_user_exception(e)
         ^^^^^^^^^^^^^^^^^^^^^^^^^^^^^
  File "/opt/homebrew/lib/python3.11/site-packages/flask/app.py", line 1823, in full_dispatch_request
    rv = self.dispatch_request()
         ^^^^^^^^^^^^^^^^^^^^^^^
  File "/opt/homebrew/lib/python3.11/site-packages/flask/app.py", line 1799, in dispatch_request
    return self.ensure_sync(self.view_functions[rule.endpoint])(**view_args)
           ^^^^^^^^^^^^^^^^^^^^^^^^^^^^^^^^^^^^^^^^^^^^^^^^^^^^^^^^^^^^^^^^^
  File "/Users/wbabich/Documents/Python Flask Project/plant_app/app.py", line 49, in home
    plants = Plant.query.all()
             ^^^^^^^^^^^^^^^^^
  File "/opt/homebrew/lib/python3.11/site-packages/sqlalchemy/orm/query.py", line 2697, in all
    return self._iter().all()  # type: ignore
           ^^^^^^^^^^^^
  File "/opt/homebrew/lib/python3.11/site-packages/sqlalchemy/orm/query.py", line 2855, in _iter
    result: Union[ScalarResult[_T], Result[_T]] = self.session.execute(
                                                  ^^^^^^^^^^^^^^^^^^^^^
  File "/opt/homebrew/lib/python3.11/site-packages/sqlalchemy/orm/session.py", line 2229, in execute
    return self._execute_internal(
           ^^^^^^^^^^^^^^^^^^^^^^^
  File "/opt/homebrew/lib/python3.11/site-packages/sqlalchemy/orm/session.py", line 2124, in _execute_internal
    result: Result[Any] = compile_state_cls.orm_execute_statement(
                          ^^^^^^^^^^^^^^^^^^^^^^^^^^^^^^^^^^^^^^^^
  File "/opt/homebrew/lib/python3.11/site-packages/sqlalchemy/orm/context.py", line 253, in orm_execute_statement
    result = conn.execute(
             ^^^^^^^^^^^^^
  File "/opt/homebrew/lib/python3.11/site-packages/sqlalchemy/engine/base.py", line 1414, in execute
    return meth(
           ^^^^^
  File "/opt/homebrew/lib/python3.11/site-packages/sqlalchemy/sql/elements.py", line 486, in _execute_on_connection
    return connection._execute_clauseelement(
           ^^^^^^^^^^^^^^^^^^^^^^^^^^^^^^^^^^
  File "/opt/homebrew/lib/python3.11/site-packages/sqlalchemy/engine/base.py", line 1638, in _execute_clauseelement
    ret = self._execute_context(
          ^^^^^^^^^^^^^^^^^^^^^^
  File "/opt/homebrew/lib/python3.11/site-packages/sqlalchemy/engine/base.py", line 1842, in _execute_context
    return self._exec_single_context(
           ^^^^^^^^^^^^^^^^^^^^^^^^^^
  File "/opt/homebrew/lib/python3.11/site-packages/sqlalchemy/engine/base.py", line 1983, in _exec_single_context
    self._handle_dbapi_exception(
  File "/opt/homebrew/lib/python3.11/site-packages/sqlalchemy/engine/base.py", line 2326, in _handle_dbapi_exception
    raise sqlalchemy_exception.with_traceback(exc_info[2]) from e
  File "/opt/homebrew/lib/python3.11/site-packages/sqlalchemy/engine/base.py", line 1964, in _exec_single_context
    self.dialect.do_execute(
  File "/opt/homebrew/lib/python3.11/site-packages/sqlalchemy/engine/default.py", line 748, in do_execute
    cursor.execute(statement, parameters)
sqlalchemy.exc.ProgrammingError: (psycopg2.errors.UndefinedColumn) column plants.sunlight_care does not exist
LINE 1: ...plants.scientific_name AS plants_scientific_name, plants.sun...
                                                             ^

[SQL: SELECT plants.id AS plants_id, plants.common_name AS plants_common_name, plants.scientific_name AS plants_scientific_name, plants.sunlight_care AS plants_sunlight_care, plants.water_care AS plants_water_care, plants.temperature_care AS plants_temperature_care, plants.humidity_care AS plants_humidity_care, plants.growing_tips AS plants_growing_tips, plants.propagation_tips AS plants_propagation_tips, plants.common_pests AS plants_common_pests, plants.image_url AS plants_image_url, plants.family AS plants_family, plants.genus AS plants_genus, plants.year AS plants_year, plants.edible AS plants_edible, plants.edible_part AS plants_edible_part, plants.edible_notes AS plants_edible_notes, plants.medicinal AS plants_medicinal, plants.medicinal_notes AS plants_medicinal_notes, plants.toxicity AS plants_toxicity, plants.synonyms AS plants_synonyms, plants.native_status AS plants_native_status, plants.conservation_status AS plants_conservation_status, plants.timestamp AS plants_timestamp 
FROM plants]
(Background on this error at: https://sqlalche.me/e/20/f405)
2023-05-23 17:13:14,131 - app - ERROR - Exception on / [GET]
Traceback (most recent call last):
  File "/opt/homebrew/lib/python3.11/site-packages/sqlalchemy/engine/base.py", line 1964, in _exec_single_context
    self.dialect.do_execute(
  File "/opt/homebrew/lib/python3.11/site-packages/sqlalchemy/engine/default.py", line 748, in do_execute
    cursor.execute(statement, parameters)
psycopg2.errors.UndefinedColumn: column plants.sunlight_care does not exist
LINE 1: ...plants.scientific_name AS plants_scientific_name, plants.sun...
                                                             ^


The above exception was the direct cause of the following exception:

Traceback (most recent call last):
  File "/opt/homebrew/lib/python3.11/site-packages/flask/app.py", line 2528, in wsgi_app
    response = self.full_dispatch_request()
               ^^^^^^^^^^^^^^^^^^^^^^^^^^^^
  File "/opt/homebrew/lib/python3.11/site-packages/flask/app.py", line 1825, in full_dispatch_request
    rv = self.handle_user_exception(e)
         ^^^^^^^^^^^^^^^^^^^^^^^^^^^^^
  File "/opt/homebrew/lib/python3.11/site-packages/flask/app.py", line 1823, in full_dispatch_request
    rv = self.dispatch_request()
         ^^^^^^^^^^^^^^^^^^^^^^^
  File "/opt/homebrew/lib/python3.11/site-packages/flask/app.py", line 1799, in dispatch_request
    return self.ensure_sync(self.view_functions[rule.endpoint])(**view_args)
           ^^^^^^^^^^^^^^^^^^^^^^^^^^^^^^^^^^^^^^^^^^^^^^^^^^^^^^^^^^^^^^^^^
  File "/Users/wbabich/Documents/Python Flask Project/plant_app/app.py", line 49, in home
    plants = Plant.query.all()
             ^^^^^^^^^^^^^^^^^
  File "/opt/homebrew/lib/python3.11/site-packages/sqlalchemy/orm/query.py", line 2697, in all
    return self._iter().all()  # type: ignore
           ^^^^^^^^^^^^
  File "/opt/homebrew/lib/python3.11/site-packages/sqlalchemy/orm/query.py", line 2855, in _iter
    result: Union[ScalarResult[_T], Result[_T]] = self.session.execute(
                                                  ^^^^^^^^^^^^^^^^^^^^^
  File "/opt/homebrew/lib/python3.11/site-packages/sqlalchemy/orm/session.py", line 2229, in execute
    return self._execute_internal(
           ^^^^^^^^^^^^^^^^^^^^^^^
  File "/opt/homebrew/lib/python3.11/site-packages/sqlalchemy/orm/session.py", line 2124, in _execute_internal
    result: Result[Any] = compile_state_cls.orm_execute_statement(
                          ^^^^^^^^^^^^^^^^^^^^^^^^^^^^^^^^^^^^^^^^
  File "/opt/homebrew/lib/python3.11/site-packages/sqlalchemy/orm/context.py", line 253, in orm_execute_statement
    result = conn.execute(
             ^^^^^^^^^^^^^
  File "/opt/homebrew/lib/python3.11/site-packages/sqlalchemy/engine/base.py", line 1414, in execute
    return meth(
           ^^^^^
  File "/opt/homebrew/lib/python3.11/site-packages/sqlalchemy/sql/elements.py", line 486, in _execute_on_connection
    return connection._execute_clauseelement(
           ^^^^^^^^^^^^^^^^^^^^^^^^^^^^^^^^^^
  File "/opt/homebrew/lib/python3.11/site-packages/sqlalchemy/engine/base.py", line 1638, in _execute_clauseelement
    ret = self._execute_context(
          ^^^^^^^^^^^^^^^^^^^^^^
  File "/opt/homebrew/lib/python3.11/site-packages/sqlalchemy/engine/base.py", line 1842, in _execute_context
    return self._exec_single_context(
           ^^^^^^^^^^^^^^^^^^^^^^^^^^
  File "/opt/homebrew/lib/python3.11/site-packages/sqlalchemy/engine/base.py", line 1983, in _exec_single_context
    self._handle_dbapi_exception(
  File "/opt/homebrew/lib/python3.11/site-packages/sqlalchemy/engine/base.py", line 2326, in _handle_dbapi_exception
    raise sqlalchemy_exception.with_traceback(exc_info[2]) from e
  File "/opt/homebrew/lib/python3.11/site-packages/sqlalchemy/engine/base.py", line 1964, in _exec_single_context
    self.dialect.do_execute(
  File "/opt/homebrew/lib/python3.11/site-packages/sqlalchemy/engine/default.py", line 748, in do_execute
    cursor.execute(statement, parameters)
sqlalchemy.exc.ProgrammingError: (psycopg2.errors.UndefinedColumn) column plants.sunlight_care does not exist
LINE 1: ...plants.scientific_name AS plants_scientific_name, plants.sun...
                                                             ^

[SQL: SELECT plants.id AS plants_id, plants.common_name AS plants_common_name, plants.scientific_name AS plants_scientific_name, plants.sunlight_care AS plants_sunlight_care, plants.water_care AS plants_water_care, plants.temperature_care AS plants_temperature_care, plants.humidity_care AS plants_humidity_care, plants.growing_tips AS plants_growing_tips, plants.propagation_tips AS plants_propagation_tips, plants.common_pests AS plants_common_pests, plants.image_url AS plants_image_url, plants.family AS plants_family, plants.genus AS plants_genus, plants.year AS plants_year, plants.edible AS plants_edible, plants.edible_part AS plants_edible_part, plants.edible_notes AS plants_edible_notes, plants.medicinal AS plants_medicinal, plants.medicinal_notes AS plants_medicinal_notes, plants.toxicity AS plants_toxicity, plants.synonyms AS plants_synonyms, plants.native_status AS plants_native_status, plants.conservation_status AS plants_conservation_status, plants.timestamp AS plants_timestamp 
FROM plants]
(Background on this error at: https://sqlalche.me/e/20/f405)
2023-05-23 17:13:56,720 - app - ERROR - Exception on / [GET]
Traceback (most recent call last):
  File "/opt/homebrew/lib/python3.11/site-packages/sqlalchemy/engine/base.py", line 1964, in _exec_single_context
    self.dialect.do_execute(
  File "/opt/homebrew/lib/python3.11/site-packages/sqlalchemy/engine/default.py", line 748, in do_execute
    cursor.execute(statement, parameters)
psycopg2.errors.UndefinedColumn: column plants.sunlight_care does not exist
LINE 1: ...plants.scientific_name AS plants_scientific_name, plants.sun...
                                                             ^


The above exception was the direct cause of the following exception:

Traceback (most recent call last):
  File "/opt/homebrew/lib/python3.11/site-packages/flask/app.py", line 2528, in wsgi_app
    response = self.full_dispatch_request()
               ^^^^^^^^^^^^^^^^^^^^^^^^^^^^
  File "/opt/homebrew/lib/python3.11/site-packages/flask/app.py", line 1825, in full_dispatch_request
    rv = self.handle_user_exception(e)
         ^^^^^^^^^^^^^^^^^^^^^^^^^^^^^
  File "/opt/homebrew/lib/python3.11/site-packages/flask/app.py", line 1823, in full_dispatch_request
    rv = self.dispatch_request()
         ^^^^^^^^^^^^^^^^^^^^^^^
  File "/opt/homebrew/lib/python3.11/site-packages/flask/app.py", line 1799, in dispatch_request
    return self.ensure_sync(self.view_functions[rule.endpoint])(**view_args)
           ^^^^^^^^^^^^^^^^^^^^^^^^^^^^^^^^^^^^^^^^^^^^^^^^^^^^^^^^^^^^^^^^^
  File "/Users/wbabich/Documents/Python Flask Project/plant_app/app.py", line 49, in home
    plants = Plant.query.all()
             ^^^^^^^^^^^^^^^^^
  File "/opt/homebrew/lib/python3.11/site-packages/sqlalchemy/orm/query.py", line 2697, in all
    return self._iter().all()  # type: ignore
           ^^^^^^^^^^^^
  File "/opt/homebrew/lib/python3.11/site-packages/sqlalchemy/orm/query.py", line 2855, in _iter
    result: Union[ScalarResult[_T], Result[_T]] = self.session.execute(
                                                  ^^^^^^^^^^^^^^^^^^^^^
  File "/opt/homebrew/lib/python3.11/site-packages/sqlalchemy/orm/session.py", line 2229, in execute
    return self._execute_internal(
           ^^^^^^^^^^^^^^^^^^^^^^^
  File "/opt/homebrew/lib/python3.11/site-packages/sqlalchemy/orm/session.py", line 2124, in _execute_internal
    result: Result[Any] = compile_state_cls.orm_execute_statement(
                          ^^^^^^^^^^^^^^^^^^^^^^^^^^^^^^^^^^^^^^^^
  File "/opt/homebrew/lib/python3.11/site-packages/sqlalchemy/orm/context.py", line 253, in orm_execute_statement
    result = conn.execute(
             ^^^^^^^^^^^^^
  File "/opt/homebrew/lib/python3.11/site-packages/sqlalchemy/engine/base.py", line 1414, in execute
    return meth(
           ^^^^^
  File "/opt/homebrew/lib/python3.11/site-packages/sqlalchemy/sql/elements.py", line 486, in _execute_on_connection
    return connection._execute_clauseelement(
           ^^^^^^^^^^^^^^^^^^^^^^^^^^^^^^^^^^
  File "/opt/homebrew/lib/python3.11/site-packages/sqlalchemy/engine/base.py", line 1638, in _execute_clauseelement
    ret = self._execute_context(
          ^^^^^^^^^^^^^^^^^^^^^^
  File "/opt/homebrew/lib/python3.11/site-packages/sqlalchemy/engine/base.py", line 1842, in _execute_context
    return self._exec_single_context(
           ^^^^^^^^^^^^^^^^^^^^^^^^^^
  File "/opt/homebrew/lib/python3.11/site-packages/sqlalchemy/engine/base.py", line 1983, in _exec_single_context
    self._handle_dbapi_exception(
  File "/opt/homebrew/lib/python3.11/site-packages/sqlalchemy/engine/base.py", line 2326, in _handle_dbapi_exception
    raise sqlalchemy_exception.with_traceback(exc_info[2]) from e
  File "/opt/homebrew/lib/python3.11/site-packages/sqlalchemy/engine/base.py", line 1964, in _exec_single_context
    self.dialect.do_execute(
  File "/opt/homebrew/lib/python3.11/site-packages/sqlalchemy/engine/default.py", line 748, in do_execute
    cursor.execute(statement, parameters)
sqlalchemy.exc.ProgrammingError: (psycopg2.errors.UndefinedColumn) column plants.sunlight_care does not exist
LINE 1: ...plants.scientific_name AS plants_scientific_name, plants.sun...
                                                             ^

[SQL: SELECT plants.id AS plants_id, plants.common_name AS plants_common_name, plants.scientific_name AS plants_scientific_name, plants.sunlight_care AS plants_sunlight_care, plants.water_care AS plants_water_care, plants.temperature_care AS plants_temperature_care, plants.humidity_care AS plants_humidity_care, plants.growing_tips AS plants_growing_tips, plants.propagation_tips AS plants_propagation_tips, plants.common_pests AS plants_common_pests, plants.image_url AS plants_image_url, plants.family AS plants_family, plants.genus AS plants_genus, plants.year AS plants_year, plants.edible AS plants_edible, plants.edible_part AS plants_edible_part, plants.edible_notes AS plants_edible_notes, plants.medicinal AS plants_medicinal, plants.medicinal_notes AS plants_medicinal_notes, plants.toxicity AS plants_toxicity, plants.synonyms AS plants_synonyms, plants.native_status AS plants_native_status, plants.conservation_status AS plants_conservation_status, plants.timestamp AS plants_timestamp 
FROM plants]
(Background on this error at: https://sqlalche.me/e/20/f405)
2023-05-23 17:13:56,900 - app - ERROR - Exception on / [GET]
Traceback (most recent call last):
  File "/opt/homebrew/lib/python3.11/site-packages/sqlalchemy/engine/base.py", line 1964, in _exec_single_context
    self.dialect.do_execute(
  File "/opt/homebrew/lib/python3.11/site-packages/sqlalchemy/engine/default.py", line 748, in do_execute
    cursor.execute(statement, parameters)
psycopg2.errors.UndefinedColumn: column plants.sunlight_care does not exist
LINE 1: ...plants.scientific_name AS plants_scientific_name, plants.sun...
                                                             ^


The above exception was the direct cause of the following exception:

Traceback (most recent call last):
  File "/opt/homebrew/lib/python3.11/site-packages/flask/app.py", line 2528, in wsgi_app
    response = self.full_dispatch_request()
               ^^^^^^^^^^^^^^^^^^^^^^^^^^^^
  File "/opt/homebrew/lib/python3.11/site-packages/flask/app.py", line 1825, in full_dispatch_request
    rv = self.handle_user_exception(e)
         ^^^^^^^^^^^^^^^^^^^^^^^^^^^^^
  File "/opt/homebrew/lib/python3.11/site-packages/flask/app.py", line 1823, in full_dispatch_request
    rv = self.dispatch_request()
         ^^^^^^^^^^^^^^^^^^^^^^^
  File "/opt/homebrew/lib/python3.11/site-packages/flask/app.py", line 1799, in dispatch_request
    return self.ensure_sync(self.view_functions[rule.endpoint])(**view_args)
           ^^^^^^^^^^^^^^^^^^^^^^^^^^^^^^^^^^^^^^^^^^^^^^^^^^^^^^^^^^^^^^^^^
  File "/Users/wbabich/Documents/Python Flask Project/plant_app/app.py", line 49, in home
    plants = Plant.query.all()
             ^^^^^^^^^^^^^^^^^
  File "/opt/homebrew/lib/python3.11/site-packages/sqlalchemy/orm/query.py", line 2697, in all
    return self._iter().all()  # type: ignore
           ^^^^^^^^^^^^
  File "/opt/homebrew/lib/python3.11/site-packages/sqlalchemy/orm/query.py", line 2855, in _iter
    result: Union[ScalarResult[_T], Result[_T]] = self.session.execute(
                                                  ^^^^^^^^^^^^^^^^^^^^^
  File "/opt/homebrew/lib/python3.11/site-packages/sqlalchemy/orm/session.py", line 2229, in execute
    return self._execute_internal(
           ^^^^^^^^^^^^^^^^^^^^^^^
  File "/opt/homebrew/lib/python3.11/site-packages/sqlalchemy/orm/session.py", line 2124, in _execute_internal
    result: Result[Any] = compile_state_cls.orm_execute_statement(
                          ^^^^^^^^^^^^^^^^^^^^^^^^^^^^^^^^^^^^^^^^
  File "/opt/homebrew/lib/python3.11/site-packages/sqlalchemy/orm/context.py", line 253, in orm_execute_statement
    result = conn.execute(
             ^^^^^^^^^^^^^
  File "/opt/homebrew/lib/python3.11/site-packages/sqlalchemy/engine/base.py", line 1414, in execute
    return meth(
           ^^^^^
  File "/opt/homebrew/lib/python3.11/site-packages/sqlalchemy/sql/elements.py", line 486, in _execute_on_connection
    return connection._execute_clauseelement(
           ^^^^^^^^^^^^^^^^^^^^^^^^^^^^^^^^^^
  File "/opt/homebrew/lib/python3.11/site-packages/sqlalchemy/engine/base.py", line 1638, in _execute_clauseelement
    ret = self._execute_context(
          ^^^^^^^^^^^^^^^^^^^^^^
  File "/opt/homebrew/lib/python3.11/site-packages/sqlalchemy/engine/base.py", line 1842, in _execute_context
    return self._exec_single_context(
           ^^^^^^^^^^^^^^^^^^^^^^^^^^
  File "/opt/homebrew/lib/python3.11/site-packages/sqlalchemy/engine/base.py", line 1983, in _exec_single_context
    self._handle_dbapi_exception(
  File "/opt/homebrew/lib/python3.11/site-packages/sqlalchemy/engine/base.py", line 2326, in _handle_dbapi_exception
    raise sqlalchemy_exception.with_traceback(exc_info[2]) from e
  File "/opt/homebrew/lib/python3.11/site-packages/sqlalchemy/engine/base.py", line 1964, in _exec_single_context
    self.dialect.do_execute(
  File "/opt/homebrew/lib/python3.11/site-packages/sqlalchemy/engine/default.py", line 748, in do_execute
    cursor.execute(statement, parameters)
sqlalchemy.exc.ProgrammingError: (psycopg2.errors.UndefinedColumn) column plants.sunlight_care does not exist
LINE 1: ...plants.scientific_name AS plants_scientific_name, plants.sun...
                                                             ^

[SQL: SELECT plants.id AS plants_id, plants.common_name AS plants_common_name, plants.scientific_name AS plants_scientific_name, plants.sunlight_care AS plants_sunlight_care, plants.water_care AS plants_water_care, plants.temperature_care AS plants_temperature_care, plants.humidity_care AS plants_humidity_care, plants.growing_tips AS plants_growing_tips, plants.propagation_tips AS plants_propagation_tips, plants.common_pests AS plants_common_pests, plants.image_url AS plants_image_url, plants.family AS plants_family, plants.genus AS plants_genus, plants.year AS plants_year, plants.edible AS plants_edible, plants.edible_part AS plants_edible_part, plants.edible_notes AS plants_edible_notes, plants.medicinal AS plants_medicinal, plants.medicinal_notes AS plants_medicinal_notes, plants.toxicity AS plants_toxicity, plants.synonyms AS plants_synonyms, plants.native_status AS plants_native_status, plants.conservation_status AS plants_conservation_status, plants.timestamp AS plants_timestamp 
FROM plants]
(Background on this error at: https://sqlalche.me/e/20/f405)
